Workbook

Sheet README
A1: Structural element catalogue, detected without colour or CAD layer
A3: What this is
A4: Every element found on the plan by geometry and text alone: drawing structure (solid fill, cross-hatch, closed outline, parallel line pair, dash chain), size, relative position and the plan's label grammar. Colour and layer appear only in the two '(validation only)' columns, to grade the result against the verified, colour-based detections (out/detections.json from detect_structures.py).
A6: Sheets
A7: Summary by building - one row per building, element family and type: count, size range, totals, consistency. Formulas over 'Elements'.
A8: Elements - one row per detected element with its dimensions, colour-free marks and pixel box (150 dpi page render).
A9: Marks by family - share of each family carrying each colour-free mark, and the same share among all other families.
A10: P vs V - the EN 1992-1-1 column/wall test against the verified classes; threshold editable (yellow cell).
A11: LG junctions - what sits where two grade beams meet, per building.
A12: Validation - colour-free detections graded against the verified set, and how the band widths were chosen.
A14: Scale
A15: 1/200.0 (14.173 PDF points per metre), fitted from 222 of 266 dimension texts against their dimension lines, median error 0.24 cm.
... A29: Formulas were written with openpyxl and are set to recalculate when the file is opened. LibreOffice was not available to pre-compute them; they were evaluated with the Python 'formulas' engine instead (no errors) and spot-checked against pandas.

Sheet Summary by building
A1: Building | B1: Family | C1: Subclass | D1: Type key | E1: Count | F1: Length min (cm) | G1: Length max (cm) | H1: Width min (cm) | I1: Width max (cm) | J1: Same section throughout? | K1: Total span/run (m) | L1: Total area (m²) | M1: Colour-free identifying marks
A2: 120 | B2: column | C2: column | D2: P1/120 | E2: =COUNTIFS(Elements!$B$2:$B$862,$A2,Elements!$D$2:$D$862,$B2,Elements!$E$2:$E$862,$C2,Elements!$F$2:$F$862,$D2) | F2: =IFERROR(_xlfn.MINIFS(Elements!$I$2:$I$862,Elements!$B$2:$B$862,$A2,Elements!$D$2:$D$862,$B2,Elements!$E$2:$E$862,$C2,Elements!$F$2:$F$862,$D2),"") | G2: =IFERROR(_xlfn.MAXIFS(Elements!$I$2:$I$862,Elements!$B$2:$B$862,$A2,Elements!$D$2:$D$862,$B2,Elements!$E$2:$E$862,$C2,Elements!$F$2:$F$862,$D2),"") | H2: =IFERROR(_xlfn.MINIFS(Elements!$J$2:$J$862,Elements!$B$2:$B$862,$A2,Elements!$D$2:$D$862,$B2,Elements!$E$2:$E$862,$C2,Elements!$F$2:$F$862,$D2),"") | I2: =IFERROR(_xlfn.MAXIFS(Elements!$J$2:$J$862,Elements!$B$2:$B$862,$A2,Elements!$D$2:$D$862,$B2,Elements!$E$2:$E$862,$C2,Elements!$F$2:$F$862,$D2),"") | J2: =IF(OR(F2="",H2=""),"",IF(OR(B2="raft",B2="sump_pit",B2="crane_foundation",D2="(none)"),"n/a",IF(OR(B2="column",B2="footing",B2="mass_concrete_pad",AND(B2="wall",C2="shear_wall",D2<>"(none)")),IF(AND(G2-F2<=3,I2-H2<=3),"yes","no"),IF(I2-H2<=3,"yes (thickness)","no (thickness)")))) | K2: =SUMIFS(Elements!$M$2:$M$862,Elements!$B$2:$B$862,$A2,Elements!$D$2:$D$862,$B2,Elements!$E$2:$E$862,$C2,Elements!$F$2:$F$862,$D2) | L2: =SUMIFS(Elements!$L$2:$L$862,Elements!$B$2:$B$862,$A2,Elements!$D$2:$D$862,$B2,Elements!$E$2:$E$862,$C2,Elements!$F$2:$F$862,$D2) | M2: solid fill; 40-120 x 25-50 cm; L/W 1.60-4.00; inside a footing outline 37%; on a raft 63%; touching a hatched core wall 26%; in a strip-footing band 0%; at a grade-beam junction 26%
A3: 120 | B3: footing | C3: combined_footing | D3: SC3 | E3: =COUNTIFS(Elements!$B$2:$B$862,$A3,Elements!$D$2:$D$862,$B3,Elements!$E$2:$E$862,$C3,Elements!$F$2:$F$862,$D3) | F3: =IFERROR(_xlfn.MINIFS(Elements!$I$2:$I$862,Elements!$B$2:$B$862,$A3,Elements!$D$2:$D$862,$B3,Elements!$E$2:$E$862,$C3,Elements!$F$2:$F$862,$D3),"") | G3: =IFERROR(_xlfn.MAXIFS(Elements!$I$2:$I$862,Elements!$B$2:$B$862,$A3,Elements!$D$2:$D$862,$B3,Elements!$E$2:$E$862,$C3,Elements!$F$2:$F$862,$D3),"") | H3: =IFERROR(_xlfn.MINIFS(Elements!$J$2:$J$862,Elements!$B$2:$B$862,$A3,Elements!$D$2:$D$862,$B3,Elements!$E$2:$E$862,$C3,Elements!$F$2:$F$862,$D3),"") | I3: =IFERROR(_xlfn.MAXIFS(Elements!$J$2:$J$862,Elements!$B$2:$B$862,$A3,Elements!$D$2:$D$862,$B3,Elements!$E$2:$E$862,$C3,Elements!$F$2:$F$862,$D3),"") | J3: =IF(OR(F3="",H3=""),"",IF(OR(B3="raft",B3="sump_pit",B3="crane_foundation",D3="(none)"),"n/a",IF(OR(B3="column",B3="footing",B3="mass_concrete_pad",AND(B3="wall",C3="shear_wall",D3<>"(none)")),IF(AND(G3-F3<=3,I3-H3<=3),"yes","no"),IF(I3-H3<=3,"yes (thickness)","no (thickness)")))) | K3: =SUMIFS(Elements!$M$2:$M$862,Elements!$B$2:$B$862,$A3,Elements!$D$2:$D$862,$B3,Elements!$E$2:$E$862,$C3,Elements!$F$2:$F$862,$D3) | L3: =SUMIFS(Elements!$L$2:$L$862,Elements!$B$2:$B$862,$A3,Elements!$D$2:$D$862,$B3,Elements!$E$2:$E$862,$C3,Elements!$F$2:$F$862,$D3) | M3: closed outline; 350-600 x 200-450 cm; carries wall+wall (24), column+wall (3), wall+wall+wall+wall (1); grade beam crossing it 93%
A4: 120 | B4: footing | C4: isolated_footing | D4: S1 | E4: =COUNTIFS(Elements!$B$2:$B$862,$A4,Elements!$D$2:$D$862,$B4,Elements!$E$2:$E$862,$C4,Elements!$F$2:$F$862,$D4) | F4: =IFERROR(_xlfn.MINIFS(Elements!$I$2:$I$862,Elements!$B$2:$B$862,$A4,Elements!$D$2:$D$862,$B4,Elements!$E$2:$E$862,$C4,Elements!$F$2:$F$862,$D4),"") | G4: =IFERROR(_xlfn.MAXIFS(Elements!$I$2:$I$862,Elements!$B$2:$B$862,$A4,Elements!$D$2:$D$862,$B4,Elements!$E$2:$E$862,$C4,Elements!$F$2:$F$862,$D4),"") | H4: =IFERROR(_xlfn.MINIFS(Elements!$J$2:$J$862,Elements!$B$2:$B$862,$A4,Elements!$D$2:$D$862,$B4,Elements!$E$2:$E$862,$C4,Elements!$F$2:$F$862,$D4),"") | I4: =IFERROR(_xlfn.MAXIFS(Elements!$J$2:$J$862,Elements!$B$2:$B$862,$A4,Elements!$D$2:$D$862,$B4,Elements!$E$2:$E$862,$C4,Elements!$F$2:$F$862,$D4),"") | J4: =IF(OR(F4="",H4=""),"",IF(OR(B4="raft",B4="sump_pit",B4="crane_foundation",D4="(none)"),"n/a",IF(OR(B4="column",B4="footing",B4="mass_concrete_pad",AND(B4="wall",C4="shear_wall",D4<>"(none)")),IF(AND(G4-F4<=3,I4-H4<=3),"yes","no"),IF(I4-H4<=3,"yes (thickness)","no (thickness)")))) | K4: =SUMIFS(Elements!$M$2:$M$862,Elements!$B$2:$B$862,$A4,Elements!$D$2:$D$862,$B4,Elements!$E$2:$E$862,$C4,Elements!$F$2:$F$862,$D4) | L4: =SUMIFS(Elements!$L$2:$L$862,Elements!$B$2:$B$862,$A4,Elements!$D$2:$D$862,$B4,Elements!$E$2:$E$862,$C4,Elements!$F$2:$F$862,$D4) | M4: closed outline; 150-600 x 150-450 cm; carries wall (64), column (9), wall+wall (1); grade beam crossing it 95%
A5: 120 | B5: footing | C5: isolated_footing | D5: S2 | E5: =COUNTIFS(Elements!$B$2:$B$862,$A5,Elements!$D$2:$D$862,$B5,Elements!$E$2:$E$862,$C5,Elements!$F$2:$F$862,$D5) | F5: =IFERROR(_xlfn.MINIFS(Elements!$I$2:$I$862,Elements!$B$2:$B$862,$A5,Elements!$D$2:$D$862,$B5,Elements!$E$2:$E$862,$C5,Elements!$F$2:$F$862,$D5),"") | G5: =IFERROR(_xlfn.MAXIFS(Elements!$I$2:$I$862,Elements!$B$2:$B$862,$A5,Elements!$D$2:$D$862,$B5,Elements!$E$2:$E$862,$C5,Elements!$F$2:$F$862,$D5),"") | H5: =IFERROR(_xlfn.MINIFS(Elements!$J$2:$J$862,Elements!$B$2:$B$862,$A5,Elements!$D$2:$D$862,$B5,Elements!$E$2:$E$862,$C5,Elements!$F$2:$F$862,$D5),"") | I5: =IFERROR(_xlfn.MAXIFS(Elements!$J$2:$J$862,Elements!$B$2:$B$862,$A5,Elements!$D$2:$D$862,$B5,Elements!$E$2:$E$862,$C5,Elements!$F$2:$F$862,$D5),"") | J5: =IF(OR(F5="",H5=""),"",IF(OR(B5="raft",B5="sump_pit",B5="crane_foundation",D5="(none)"),"n/a",IF(OR(B5="column",B5="footing",B5="mass_concrete_pad",AND(B5="wall",C5="shear_wall",D5<>"(none)")),IF(AND(G5-F5<=3,I5-H5<=3),"yes","no"),IF(I5-H5<=3,"yes (thickness)","no (thickness)")))) | K5: =SUMIFS(Elements!$M$2:$M$862,Elements!$B$2:$B$862,$A5,Elements!$D$2:$D$862,$B5,Elements!$E$2:$E$862,$C5,Elements!$F$2:$F$862,$D5) | L5: =SUMIFS(Elements!$L$2:$L$862,Elements!$B$2:$B$862,$A5,Elements!$D$2:$D$862,$B5,Elements!$E$2:$E$862,$C5,Elements!$F$2:$F$862,$D5) | M5: closed outline; 150-600 x 150-450 cm; carries wall (64), column (9), wall+wall (1); grade beam crossing it 95%
A6: 120 | B6: footing | C6: isolated_footing | D6: S3 | E6: =COUNTIFS(Elements!$B$2:$B$862,$A6,Elements!$D$2:$D$862,$B6,Elements!$E$2:$E$862,$C6,Elements!$F$2:$F$862,$D6) | F6: =IFERROR(_xlfn.MINIFS(Elements!$I$2:$I$862,Elements!$B$2:$B$862,$A6,Elements!$D$2:$D$862,$B6,Elements!$E$2:$E$862,$C6,Elements!$F$2:$F$862,$D6),"") | G6: =IFERROR(_xlfn.MAXIFS(Elements!$I$2:$I$862,Elements!$B$2:$B$862,$A6,Elements!$D$2:$D$862,$B6,Elements!$E$2:$E$862,$C6,Elements!$F$2:$F$862,$D6),"") | H6: =IFERROR(_xlfn.MINIFS(Elements!$J$2:$J$862,Elements!$B$2:$B$862,$A6,Elements!$D$2:$D$862,$B6,Elements!$E$2:$E$862,$C6,Elements!$F$2:$F$862,$D6),"") | I6: =IFERROR(_xlfn.MAXIFS(Elements!$J$2:$J$862,Elements!$B$2:$B$862,$A6,Elements!$D$2:$D$862,$B6,Elements!$E$2:$E$862,$C6,Elements!$F$2:$F$862,$D6),"") | J6: =IF(OR(F6="",H6=""),"",IF(OR(B6="raft",B6="sump_pit",B6="crane_foundation",D6="(none)"),"n/a",IF(OR(B6="column",B6="footing",B6="mass_concrete_pad",AND(B6="wall",C6="shear_wall",D6<>"(none)")),IF(AND(G6-F6<=3,I6-H6<=3),"yes","no"),IF(I6-H6<=3,"yes (thickness)","no (thickness)")))) | K6: =SUMIFS(Elements!$M$2:$M$862,Elements!$B$2:$B$862,$A6,Elements!$D$2:$D$862,$B6,Elements!$E$2:$E$862,$C6,Elements!$F$2:$F$862,$D6) | L6: =SUMIFS(Elements!$L$2:$L$862,Elements!$B$2:$B$862,$A6,Elements!$D$2:$D$862,$B6,Elements!$E$2:$E$862,$C6,Elements!$F$2:$F$862,$D6) | M6: closed outline; 150-600 x 150-450 cm; carries wall (64), column (9), wall+wall (1); grade beam crossing it 95%
A7: 120 | B7: footing | C7: isolated_footing | D7: S5 | E7: =COUNTIFS(Elements!$B$2:$B$862,$A7,Elements!$D$2:$D$862,$B7,Elements!$E$2:$E$862,$C7,Elements!$F$2:$F$862,$D7) | F7: =IFERROR(_xlfn.MINIFS(Elements!$I$2:$I$862,Elements!$B$2:$B$862,$A7,Elements!$D$2:$D$862,$B7,Elements!$E$2:$E$862,$C7,Elements!$F$2:$F$862,$D7),"") | G7: =IFERROR(_xlfn.MAXIFS(Elements!$I$2:$I$862,Elements!$B$2:$B$862,$A7,Elements!$D$2:$D$862,$B7,Elements!$E$2:$E$862,$C7,Elements!$F$2:$F$862,$D7),"") | H7: =IFERROR(_xlfn.MINIFS(Elements!$J$2:$J$862,Elements!$B$2:$B$862,$A7,Elements!$D$2:$D$862,$B7,Elements!$E$2:$E$862,$C7,Elements!$F$2:$F$862,$D7),"") | I7: =IFERROR(_xlfn.MAXIFS(Elements!$J$2:$J$862,Elements!$B$2:$B$862,$A7,Elements!$D$2:$D$862,$B7,Elements!$E$2:$E$862,$C7,Elements!$F$2:$F$862,$D7),"") | J7: =IF(OR(F7="",H7=""),"",IF(OR(B7="raft",B7="sump_pit",B7="crane_foundation",D7="(none)"),"n/a",IF(OR(B7="column",B7="footing",B7="mass_concrete_pad",AND(B7="wall",C7="shear_wall",D7<>"(none)")),IF(AND(G7-F7<=3,I7-H7<=3),"yes","no"),IF(I7-H7<=3,"yes (thickness)","no (thickness)")))) | K7: =SUMIFS(Elements!$M$2:$M$862,Elements!$B$2:$B$862,$A7,Elements!$D$2:$D$862,$B7,Elements!$E$2:$E$862,$C7,Elements!$F$2:$F$862,$D7) | L7: =SUMIFS(Elements!$L$2:$L$862,Elements!$B$2:$B$862,$A7,Elements!$D$2:$D$862,$B7,Elements!$E$2:$E$862,$C7,Elements!$F$2:$F$862,$D7) | M7: closed outline; 150-600 x 150-450 cm; carries wall (64), column (9), wall+wall (1); grade beam crossing it 95%
A8: 120 | B8: footing | C8: isolated_footing | D8: S6 | E8: =COUNTIFS(Elements!$B$2:$B$862,$A8,Elements!$D$2:$D$862,$B8,Elements!$E$2:$E$862,$C8,Elements!$F$2:$F$862,$D8) | F8: =IFERROR(_xlfn.MINIFS(Elements!$I$2:$I$862,Elements!$B$2:$B$862,$A8,Elements!$D$2:$D$862,$B8,Elements!$E$2:$E$862,$C8,Elements!$F$2:$F$862,$D8),"") | G8: =IFERROR(_xlfn.MAXIFS(Elements!$I$2:$I$862,Elements!$B$2:$B$862,$A8,Elements!$D$2:$D$862,$B8,Elements!$E$2:$E$862,$C8,Elements!$F$2:$F$862,$D8),"") | H8: =IFERROR(_xlfn.MINIFS(Elements!$J$2:$J$862,Elements!$B$2:$B$862,$A8,Elements!$D$2:$D$862,$B8,Elements!$E$2:$E$862,$C8,Elements!$F$2:$F$862,$D8),"") | I8: =IFERROR(_xlfn.MAXIFS(Elements!$J$2:$J$862,Elements!$B$2:$B$862,$A8,Elements!$D$2:$D$862,$B8,Elements!$E$2:$E$862,$C8,Elements!$F$2:$F$862,$D8),"") | J8: =IF(OR(F8="",H8=""),"",IF(OR(B8="raft",B8="sump_pit",B8="crane_foundation",D8="(none)"),"n/a",IF(OR(B8="column",B8="footing",B8="mass_concrete_pad",AND(B8="wall",C8="shear_wall",D8<>"(none)")),IF(AND(G8-F8<=3,I8-H8<=3),"yes","no"),IF(I8-H8<=3,"yes (thickness)","no (thickness)")))) | K8: =SUMIFS(Elements!$M$2:$M$862,Elements!$B$2:$B$862,$A8,Elements!$D$2:$D$862,$B8,Elements!$E$2:$E$862,$C8,Elements!$F$2:$F$862,$D8) | L8: =SUMIFS(Elements!$L$2:$L$862,Elements!$B$2:$B$862,$A8,Elements!$D$2:$D$862,$B8,Elements!$E$2:$E$862,$C8,Elements!$F$2:$F$862,$D8) | M8: closed outline; 150-600 x 150-450 cm; carries wall (64), column (9), wall+wall (1); grade beam crossing it 95%
A9: 120 | B9: footing | C9: isolated_footing | D9: S7 | E9: =COUNTIFS(Elements!$B$2:$B$862,$A9,Elements!$D$2:$D$862,$B9,Elements!$E$2:$E$862,$C9,Elements!$F$2:$F$862,$D9) | F9: =IFERROR(_xlfn.MINIFS(Elements!$I$2:$I$862,Elements!$B$2:$B$862,$A9,Elements!$D$2:$D$862,$B9,Elements!$E$2:$E$862,$C9,Elements!$F$2:$F$862,$D9),"") | G9: =IFERROR(_xlfn.MAXIFS(Elements!$I$2:$I$862,Elements!$B$2:$B$862,$A9,Elements!$D$2:$D$862,$B9,Elements!$E$2:$E$862,$C9,Elements!$F$2:$F$862,$D9),"") | H9: =IFERROR(_xlfn.MINIFS(Elements!$J$2:$J$862,Elements!$B$2:$B$862,$A9,Elements!$D$2:$D$862,$B9,Elements!$E$2:$E$862,$C9,Elements!$F$2:$F$862,$D9),"") | I9: =IFERROR(_xlfn.MAXIFS(Elements!$J$2:$J$862,Elements!$B$2:$B$862,$A9,Elements!$D$2:$D$862,$B9,Elements!$E$2:$E$862,$C9,Elements!$F$2:$F$862,$D9),"") | J9: =IF(OR(F9="",H9=""),"",IF(OR(B9="raft",B9="sump_pit",B9="crane_foundation",D9="(none)"),"n/a",IF(OR(B9="column",B9="footing",B9="mass_concrete_pad",AND(B9="wall",C9="shear_wall",D9<>"(none)")),IF(AND(G9-F9<=3,I9-H9<=3),"yes","no"),IF(I9-H9<=3,"yes (thickness)","no (thickness)")))) | K9: =SUMIFS(Elements!$M$2:$M$862,Elements!$B$2:$B$862,$A9,Elements!$D$2:$D$862,$B9,Elements!$E$2:$E$862,$C9,Elements!$F$2:$F$862,$D9) | L9: =SUMIFS(Elements!$L$2:$L$862,Elements!$B$2:$B$862,$A9,Elements!$D$2:$D$862,$B9,Elements!$E$2:$E$862,$C9,Elements!$F$2:$F$862,$D9) | M9: closed outline; 150-600 x 150-450 cm; carries wall (64), column (9), wall+wall (1); grade beam crossing it 95%
A10: 120 | B10: grade_beam | C10: grade_beam | D10: LG40x15 | E10: =COUNTIFS(Elements!$B$2:$B$862,$A10,Elements!$D$2:$D$862,$B10,Elements!$E$2:$E$862,$C10,Elements!$F$2:$F$862,$D10) | F10: =IFERROR(_xlfn.MINIFS(Elements!$I$2:$I$862,Elements!$B$2:$B$862,$A10,Elements!$D$2:$D$862,$B10,Elements!$E$2:$E$862,$C10,Elements!$F$2:$F$862,$D10),"") | G10: =IFERROR(_xlfn.MAXIFS(Elements!$I$2:$I$862,Elements!$B$2:$B$862,$A10,Elements!$D$2:$D$862,$B10,Elements!$E$2:$E$862,$C10,Elements!$F$2:$F$862,$D10),"") | H10: =IFERROR(_xlfn.MINIFS(Elements!$J$2:$J$862,Elements!$B$2:$B$862,$A10,Elements!$D$2:$D$862,$B10,Elements!$E$2:$E$862,$C10,Elements!$F$2:$F$862,$D10),"") | I10: =IFERROR(_xlfn.MAXIFS(Elements!$J$2:$J$862,Elements!$B$2:$B$862,$A10,Elements!$D$2:$D$862,$B10,Elements!$E$2:$E$862,$C10,Elements!$F$2:$F$862,$D10),"") | J10: =IF(OR(F10="",H10=""),"",IF(OR(B10="raft",B10="sump_pit",B10="crane_foundation",D10="(none)"),"n/a",IF(OR(B10="column",B10="footing",B10="mass_concrete_pad",AND(B10="wall",C10="shear_wall",D10<>"(none)")),IF(AND(G10-F10<=3,I10-H10<=3),"yes","no"),IF(I10-H10<=3,"yes (thickness)","no (thickness)")))) | K10: =SUMIFS(Elements!$M$2:$M$862,Elements!$B$2:$B$862,$A10,Elements!$D$2:$D$862,$B10,Elements!$E$2:$E$862,$C10,Elements!$F$2:$F$862,$D10) | L10: =SUMIFS(Elements!$L$2:$L$862,Elements!$B$2:$B$862,$A10,Elements!$D$2:$D$862,$B10,Elements!$E$2:$E$862,$C10,Elements!$F$2:$F$862,$D10) | M10: parallel line pair; 30-2249 x 25-40 cm; width stated in its label
A11: 120 | B11: mass_concrete_pad | C11: mass_concrete_pad | D11: (none) | E11: =COUNTIFS(Elements!$B$2:$B$862,$A11,Elements!$D$2:$D$862,$B11,Elements!$E$2:$E$862,$C11,Elements!$F$2:$F$862,$D11) | F11: =IFERROR(_xlfn.MINIFS(Elements!$I$2:$I$862,Elements!$B$2:$B$862,$A11,Elements!$D$2:$D$862,$B11,Elements!$E$2:$E$862,$C11,Elements!$F$2:$F$862,$D11),"") | G11: =IFERROR(_xlfn.MAXIFS(Elements!$I$2:$I$862,Elements!$B$2:$B$862,$A11,Elements!$D$2:$D$862,$B11,Elements!$E$2:$E$862,$C11,Elements!$F$2:$F$862,$D11),"") | H11: =IFERROR(_xlfn.MINIFS(Elements!$J$2:$J$862,Elements!$B$2:$B$862,$A11,Elements!$D$2:$D$862,$B11,Elements!$E$2:$E$862,$C11,Elements!$F$2:$F$862,$D11),"") | I11: =IFERROR(_xlfn.MAXIFS(Elements!$J$2:$J$862,Elements!$B$2:$B$862,$A11,Elements!$D$2:$D$862,$B11,Elements!$E$2:$E$862,$C11,Elements!$F$2:$F$862,$D11),"") | J11: =IF(OR(F11="",H11=""),"",IF(OR(B11="raft",B11="sump_pit",B11="crane_foundation",D11="(none)"),"n/a",IF(OR(B11="column",B11="footing",B11="mass_concrete_pad",AND(B11="wall",C11="shear_wall",D11<>"(none)")),IF(AND(G11-F11<=3,I11-H11<=3),"yes","no"),IF(I11-H11<=3,"yes (thickness)","no (thickness)")))) | K11: =SUMIFS(Elements!$M$2:$M$862,Elements!$B$2:$B$862,$A11,Elements!$D$2:$D$862,$B11,Elements!$E$2:$E$862,$C11,Elements!$F$2:$F$862,$D11) | L11: =SUMIFS(Elements!$L$2:$L$862,Elements!$B$2:$B$862,$A11,Elements!$D$2:$D$862,$B11,Elements!$E$2:$E$862,$C11,Elements!$F$2:$F$862,$D11) | M11: closed outline + stipple; 60-60 x 60-60 cm; 47-91 stipple dots inside; on a grade beam 100%; at a grade-beam junction 62%
A12: 120 | B12: raft | C12: raft | D12: Radier 110 | E12: =COUNTIFS(Elements!$B$2:$B$862,$A12,Elements!$D$2:$D$862,$B12,Elements!$E$2:$E$862,$C12,Elements!$F$2:$F$862,$D12) | F12: =IFERROR(_xlfn.MINIFS(Elements!$I$2:$I$862,Elements!$B$2:$B$862,$A12,Elements!$D$2:$D$862,$B12,Elements!$E$2:$E$862,$C12,Elements!$F$2:$F$862,$D12),"") | G12: =IFERROR(_xlfn.MAXIFS(Elements!$I$2:$I$862,Elements!$B$2:$B$862,$A12,Elements!$D$2:$D$862,$B12,Elements!$E$2:$E$862,$C12,Elements!$F$2:$F$862,$D12),"") | H12: =IFERROR(_xlfn.MINIFS(Elements!$J$2:$J$862,Elements!$B$2:$B$862,$A12,Elements!$D$2:$D$862,$B12,Elements!$E$2:$E$862,$C12,Elements!$F$2:$F$862,$D12),"") | I12: =IFERROR(_xlfn.MAXIFS(Elements!$J$2:$J$862,Elements!$B$2:$B$862,$A12,Elements!$D$2:$D$862,$B12,Elements!$E$2:$E$862,$C12,Elements!$F$2:$F$862,$D12),"") | J12: =IF(OR(F12="",H12=""),"",IF(OR(B12="raft",B12="sump_pit",B12="crane_foundation",D12="(none)"),"n/a",IF(OR(B12="column",B12="footing",B12="mass_concrete_pad",AND(B12="wall",C12="shear_wall",D12<>"(none)")),IF(AND(G12-F12<=3,I12-H12<=3),"yes","no"),IF(I12-H12<=3,"yes (thickness)","no (thickness)")))) | K12: =SUMIFS(Elements!$M$2:$M$862,Elements!$B$2:$B$862,$A12,Elements!$D$2:$D$862,$B12,Elements!$E$2:$E$862,$C12,Elements!$F$2:$F$862,$D12) | L12: =SUMIFS(Elements!$L$2:$L$862,Elements!$B$2:$B$862,$A12,Elements!$D$2:$D$862,$B12,Elements!$E$2:$E$862,$C12,Elements!$F$2:$F$862,$D12) | M12: stamp + corner diagonals; 693-1971 x 450-1020 cm; circle stamp 'Radier' + thickness; diagonals from its corners to the stamp
A13: 120 | B13: raft | C13: raft | D13: Radier 90 | E13: =COUNTIFS(Elements!$B$2:$B$862,$A13,Elements!$D$2:$D$862,$B13,Elements!$E$2:$E$862,$C13,Elements!$F$2:$F$862,$D13) | F13: =IFERROR(_xlfn.MINIFS(Elements!$I$2:$I$862,Elements!$B$2:$B$862,$A13,Elements!$D$2:$D$862,$B13,Elements!$E$2:$E$862,$C13,Elements!$F$2:$F$862,$D13),"") | G13: =IFERROR(_xlfn.MAXIFS(Elements!$I$2:$I$862,Elements!$B$2:$B$862,$A13,Elements!$D$2:$D$862,$B13,Elements!$E$2:$E$862,$C13,Elements!$F$2:$F$862,$D13),"") | H13: =IFERROR(_xlfn.MINIFS(Elements!$J$2:$J$862,Elements!$B$2:$B$862,$A13,Elements!$D$2:$D$862,$B13,Elements!$E$2:$E$862,$C13,Elements!$F$2:$F$862,$D13),"") | I13: =IFERROR(_xlfn.MAXIFS(Elements!$J$2:$J$862,Elements!$B$2:$B$862,$A13,Elements!$D$2:$D$862,$B13,Elements!$E$2:$E$862,$C13,Elements!$F$2:$F$862,$D13),"") | J13: =IF(OR(F13="",H13=""),"",IF(OR(B13="raft",B13="sump_pit",B13="crane_foundation",D13="(none)"),"n/a",IF(OR(B13="column",B13="footing",B13="mass_concrete_pad",AND(B13="wall",C13="shear_wall",D13<>"(none)")),IF(AND(G13-F13<=3,I13-H13<=3),"yes","no"),IF(I13-H13<=3,"yes (thickness)","no (thickness)")))) | K13: =SUMIFS(Elements!$M$2:$M$862,Elements!$B$2:$B$862,$A13,Elements!$D$2:$D$862,$B13,Elements!$E$2:$E$862,$C13,Elements!$F$2:$F$862,$D13) | L13: =SUMIFS(Elements!$L$2:$L$862,Elements!$B$2:$B$862,$A13,Elements!$D$2:$D$862,$B13,Elements!$E$2:$E$862,$C13,Elements!$F$2:$F$862,$D13) | M13: stamp + corner diagonals; 693-1971 x 450-1020 cm; circle stamp 'Radier' + thickness; diagonals from its corners to the stamp
... A264: 130 | B264: wall | C264: shear_wall | D264: V6/130 | E264: =COUNTIFS(Elements!$B$2:$B$862,$A264,Elements!$D$2:$D$862,$B264,Elements!$E$2:$E$862,$C264,Elements!$F$2:$F$862,$D264) | F264: =IFERROR(_xlfn.MINIFS(Elements!$I$2:$I$862,Elements!$B$2:$B$862,$A264,Elements!$D$2:$D$862,$B264,Elements!$E$2:$E$862,$C264,Elements!$F$2:$F$862,$D264),"") | G264: =IFERROR(_xlfn.MAXIFS(Elements!$I$2:$I$862,Elements!$B$2:$B$862,$A264,Elements!$D$2:$D$862,$B264,Elements!$E$2:$E$862,$C264,Elements!$F$2:$F$862,$D264),"") | H264: =IFERROR(_xlfn.MINIFS(Elements!$J$2:$J$862,Elements!$B$2:$B$862,$A264,Elements!$D$2:$D$862,$B264,Elements!$E$2:$E$862,$C264,Elements!$F$2:$F$862,$D264),"") | I264: =IFERROR(_xlfn.MAXIFS(Elements!$J$2:$J$862,Elements!$B$2:$B$862,$A264,Elements!$D$2:$D$862,$B264,Elements!$E$2:$E$862,$C264,Elements!$F$2:$F$862,$D264),"") | J264: =IF(OR(F264="",H264=""),"",IF(OR(B264="raft",B264="sump_pit",B264="crane_foundation",D264="(none)"),"n/a",IF(OR(B264="column",B264="footing",B264="mass_concrete_pad",AND(B264="wall",C264="shear_wall",D264<>"(none)")),IF(AND(G264-F264<=3,I264-H264<=3),"yes","no"),IF(I264-H264<=3,"yes (thickness)","no (thickness)")))) | K264: =SUMIFS(Elements!$M$2:$M$862,Elements!$B$2:$B$862,$A264,Elements!$D$2:$D$862,$B264,Elements!$E$2:$E$862,$C264,Elements!$F$2:$F$862,$D264) | L264: =SUMIFS(Elements!$L$2:$L$862,Elements!$B$2:$B$862,$A264,Elements!$D$2:$D$862,$B264,Elements!$E$2:$E$862,$C264,Elements!$F$2:$F$862,$D264) | M264: solid fill; 87-1849 x 20-30 cm; L/W 4.17-92.45; inside a footing outline 72%; on a raft 10%; touching a hatched core wall 1%; in a strip-footing band 5%; at a grade-beam junction 51%
A266: All buildings | E266: =SUM(E2:E264) | K266: =SUM(K2:K264) | L266: =SUM(L2:L264)
A267: 'Same section throughout?' allows 3 cm between the smallest and largest element of the row. Columns, labelled shear walls, footings and pads are compared on length and width; walls and bands whose length varies by nature on thickness only; rafts, pits and crane groups, and rows of unlabelled elements (a mix of types), do not apply.

Sheet Elements
A1: ID | B1: Building | C1: Building source | D1: Family | E1: Subclass | F1: Type key | G1: Label text | H1: Label source | I1: Length (cm) | J1: Width (cm) | K1: L/W | L1: Area (m²) | M1: Span / run (m) | N1: Angle (°) | O1: Drawing type | P1: Colour-free rule | Q1: EC2 test | R1: Inside footing | S1: Supports inside | T1: Support offset (cm) | U1: On raft | V1: Touches hatched wall | W1: Touches solid element | X1: In strip band | Y1: On grade beam | Z1: At LG junction | AA1: Grid distance (m) | AB1: Hatch stroke (m) | AC1: Stipple dots | AD1: Raft thickness (cm) | AE1: bbox x0 (px) | AF1: bbox y0 (px) | AG1: bbox x1 (px) | AH1: bbox y1 (px) | AI1: Matches verified detection | AJ1: Verified subclass | AK1: Note | AL1: (validation only) colour | AM1: (validation only) layer
A2: 1 | B2: 120 | C2: own label | D2: column | E2: column | F2: P1/120 | G2: P1/120/120 | H2: printed | I2: 80 | J2: 25 | K2: =IF(AND(ISNUMBER(I2),ISNUMBER(J2),J2>0),I2/J2,"") | L2: 0.2 | N2: 0 | O2: solid fill | P2: solid fill, rectangle, L <= 4 W (EN 1992-1-1 5.3.1(7)) | Q2: =IF(OR(D2="column",D2="wall"),IF(I2<='P vs V'!$B$3*J2,"column","wall"),"") | U2: yes | V2: yes | W2: no | X2: no | Y2: no | Z2: no | AA2: 0.61 | AE2: 4596.9 | AF2: 792 | AG2: 4620.6 | AH2: 799.4 | AI2: yes | AJ2: column | AL2: (0.0, 0.0, 1.0) | AM2: DM-Poteaux
A3: 2 | B3: 120 | C3: own label | D3: column | E3: column | F3: P1/120 | G3: P1/120/120 | H3: printed | I3: 80 | J3: 25 | K3: =IF(AND(ISNUMBER(I3),ISNUMBER(J3),J3>0),I3/J3,"") | L3: 0.2 | N3: 0 | O3: solid fill | P3: solid fill, rectangle, L <= 4 W (EN 1992-1-1 5.3.1(7)) | Q3: =IF(OR(D3="column",D3="wall"),IF(I3<='P vs V'!$B$3*J3,"column","wall"),"") | U3: yes | V3: no | W3: no | X3: no | Y3: no | Z3: no | AA3: 1.17 | AE3: 4704.8 | AF3: 861.4 | AG3: 4728.4 | AH3: 868.8 | AI3: yes | AJ3: column | AL3: (0.0, 0.0, 1.0) | AM3: DM-Poteaux
A4: 3 | B4: 120 | C4: own label | D4: column | E4: column | F4: P1/120 | G4: P1/120/120 | H4: printed | I4: 80 | J4: 25 | K4: =IF(AND(ISNUMBER(I4),ISNUMBER(J4),J4>0),I4/J4,"") | L4: 0.2 | N4: 0 | O4: solid fill | P4: solid fill, rectangle, L <= 4 W (EN 1992-1-1 5.3.1(7)) | Q4: =IF(OR(D4="column",D4="wall"),IF(I4<='P vs V'!$B$3*J4,"column","wall"),"") | U4: yes | V4: no | W4: no | X4: no | Y4: no | Z4: no | AA4: 1.18 | AE4: 4596.9 | AF4: 861.4 | AG4: 4620.6 | AH4: 868.8 | AI4: yes | AJ4: column | AL4: (0.0, 0.0, 1.0) | AM4: DM-Poteaux
A5: 4 | B5: 120 | C5: own label | D5: column | E5: column | F5: P1/120 | G5: P1/120/120 | H5: printed | I5: 80 | J5: 25 | K5: =IF(AND(ISNUMBER(I5),ISNUMBER(J5),J5>0),I5/J5,"") | L5: 0.2 | N5: 0 | O5: solid fill | P5: solid fill, rectangle, L <= 4 W (EN 1992-1-1 5.3.1(7)) | Q5: =IF(OR(D5="column",D5="wall"),IF(I5<='P vs V'!$B$3*J5,"column","wall"),"") | U5: yes | V5: no | W5: no | X5: no | Y5: no | Z5: no | AA5: 0.61 | AE5: 4704.8 | AF5: 792 | AG5: 4728.4 | AH5: 799.4 | AI5: yes | AJ5: column | AL5: (0.0, 0.0, 1.0) | AM5: DM-Poteaux
A6: 5 | B6: 120 | C6: nearest labels (100% agree) | D6: wall | E6: core_wall_solid | F6: (none) | H6: none | I6: 424 | J6: 25 | K6: =IF(AND(ISNUMBER(I6),ISNUMBER(J6),J6>0),I6/J6,"") | L6: 1.062 | N6: 180 | O6: solid fill | P6: straight stretch of a thin filled outline with bends (pair of parallel faces) | Q6: =IF(OR(D6="column",D6="wall"),IF(I6<='P vs V'!$B$3*J6,"column","wall"),"") | U6: yes | V6: no | W6: yes | X6: no | Y6: no | Z6: no | AA6: 0.01 | AE6: 4878.4 | AF6: 774.2 | AG6: 5003.8 | AH6: 781.7 | AI6: new | AK6: piece of a wall network the colour pipeline left unsplit
A7: 6 | B7: 120 | C7: nearest labels (100% agree) | D7: wall | E7: core_wall_solid | F7: (none) | H7: none | I7: 175 | J7: 25 | K7: =IF(AND(ISNUMBER(I7),ISNUMBER(J7),J7>0),I7/J7,"") | L7: 0.441 | N7: 89.9 | O7: solid fill | P7: straight stretch of a thin filled outline with bends (pair of parallel faces) | Q7: =IF(OR(D7="column",D7="wall"),IF(I7<='P vs V'!$B$3*J7,"column","wall"),"") | U7: yes | V7: no | W7: yes | X7: no | Y7: no | Z7: no | AA7: 0.16 | AE7: 4763.8 | AF7: 756.6 | AG7: 4771.3 | AH7: 808.2 | AI7: new | AK7: piece of a wall network the colour pipeline left unsplit
A8: 7 | B8: 120 | C8: nearest labels (100% agree) | D8: wall | E8: core_wall_solid | F8: (none) | H8: none | I8: 158 | J8: 25 | K8: =IF(AND(ISNUMBER(I8),ISNUMBER(J8),J8>0),I8/J8,"") | L8: 0.402 | N8: 89.9 | O8: solid fill | P8: straight stretch of a thin filled outline with bends (pair of parallel faces) | Q8: =IF(OR(D8="column",D8="wall"),IF(I8<='P vs V'!$B$3*J8,"column","wall"),"") | U8: yes | V8: yes | W8: yes | X8: no | Y8: no | Z8: no | AA8: 0.87 | AE8: 4870.7 | AF8: 781.7 | AG8: 4878.3 | AH8: 828.2 | AI8: new | AK8: piece of a wall network the colour pipeline left unsplit
A9: 8 | B9: 120 | C9: nearest labels (100% agree) | D9: wall | E9: core_wall_solid | F9: (none) | H9: none | I9: 47 | J9: 26 | K9: =IF(AND(ISNUMBER(I9),ISNUMBER(J9),J9>0),I9/J9,"") | L9: 0.122 | N9: 89.9 | O9: solid fill | P9: straight stretch of a thin filled outline with bends (pair of parallel faces) | Q9: =IF(OR(D9="column",D9="wall"),IF(I9<='P vs V'!$B$3*J9,"column","wall"),"") | U9: yes | V9: no | W9: yes | X9: no | Y9: no | Z9: no | AA9: 0.35 | AE9: 4870.7 | AF9: 760.3 | AG9: 4878.3 | AH9: 774.3 | AI9: new | AK9: piece of a wall network the colour pipeline left unsplit
A10: 9 | B10: 120 | C10: nearest labels (100% agree) | D10: wall | E10: retaining_wall | F10: VP20 | H10: thickness matches a VP type | I10: 2869 | J10: 20 | K10: =IF(AND(ISNUMBER(I10),ISNUMBER(J10),J10>0),I10/J10,"") | L10: 5.7 | N10: 90 | O10: solid fill | P10: solid fill, rectangle, L > 4 W (EN 1992-1-1 5.3.1(7)) | Q10: =IF(OR(D10="column",D10="wall"),IF(I10<='P vs V'!$B$3*J10,"column","wall"),"") | U10: no | V10: no | W10: yes | X10: yes | Y10: yes | Z10: no | AA10: 2.28 | AE10: 4159.1 | AF10: 483.6 | AG10: 4165.5 | AH10: 1330.7 | AI10: new | AK10: piece of a wall network the colour pipeline left unsplit | AL10: (0.87, 0.0, 0.87) | AM10: DM-VOILE
A11: 10 | B11: 120 | C11: nearest labels (100% agree) | D11: wall | E11: retaining_wall | F11: VP20 | H11: thickness matches a VP type | I11: 2055 | J11: 20 | K11: =IF(AND(ISNUMBER(I11),ISNUMBER(J11),J11>0),I11/J11,"") | L11: 4.06 | N11: 172.6 | O11: solid fill | P11: solid fill, rectangle, L > 4 W (EN 1992-1-1 5.3.1(7)) | Q11: =IF(OR(D11="column",D11="wall"),IF(I11<='P vs V'!$B$3*J11,"column","wall"),"") | U11: no | V11: no | W11: yes | X11: yes | Y11: no | Z11: no | AA11: 1.26 | AE11: 4159.6 | AF11: 404.5 | AG11: 4761.8 | AH11: 486.5 | AI11: new | AK11: piece of a wall network the colour pipeline left unsplit | AL11: (0.87, 0.0, 0.87) | AM11: DM-VOILE
A12: 11 | B12: 120 | C12: nearest labels (100% agree) | D12: wall | E12: retaining_wall | F12: VP20 | H12: thickness matches a VP type | I12: 110 | J12: 20 | K12: =IF(AND(ISNUMBER(I12),ISNUMBER(J12),J12>0),I12/J12,"") | L12: 0.209 | N12: 90 | O12: solid fill | P12: solid fill, rectangle, L > 4 W (EN 1992-1-1 5.3.1(7)) | Q12: =IF(OR(D12="column",D12="wall"),IF(I12<='P vs V'!$B$3*J12,"column","wall"),"") | U12: yes | V12: yes | W12: yes | X12: yes | Y12: no | Z12: no | AA12: 1.82 | AE12: 4818.4 | AF12: 868.7 | AG12: 4824.2 | AH12: 901.3 | AI12: new | AK12: piece of a wall network the colour pipeline left unsplit | AL12: (0.87, 0.0, 0.87) | AM12: DM-VOILE
A13: 12 | B13: 120 | C13: nearest labels (100% agree) | D13: wall | E13: retaining_wall | F13: VP20 | H13: thickness matches a VP type | I13: 245 | J13: 20 | K13: =IF(AND(ISNUMBER(I13),ISNUMBER(J13),J13>0),I13/J13,"") | L13: 0.489 | N13: 90 | O13: solid fill | P13: straight stretch of a thin filled outline with bends (pair of parallel faces) | Q13: =IF(OR(D13="column",D13="wall"),IF(I13<='P vs V'!$B$3*J13,"column","wall"),"") | U13: no | V13: yes | W13: yes | X13: yes | Y13: no | Z13: no | AA13: 3.09 | AE13: 4818.3 | AF13: 901.3 | AG13: 4824.3 | AH13: 973.5 | AI13: new | AK13: piece of a wall network the colour pipeline left unsplit
A14: 13 | B14: 120 | C14: nearest labels (100% agree) | D14: wall | E14: retaining_wall | F14: VP25 | H14: thickness matches a VP type | I14: 474 | J14: 25 | K14: =IF(AND(ISNUMBER(I14),ISNUMBER(J14),J14>0),I14/J14,"") | L14: 1.188 | N14: 180 | O14: solid fill | P14: straight stretch of a thin filled outline with bends (pair of parallel faces) | Q14: =IF(OR(D14="column",D14="wall"),IF(I14<='P vs V'!$B$3*J14,"column","wall"),"") | U14: yes | V14: yes | W14: yes | X14: yes | Y14: no | Z14: no | AA14: 1.16 | AE14: 4870.8 | AF14: 861.3 | AG14: 5010.9 | AH14: 868.7 | AI14: new | AK14: piece of a wall network the colour pipeline left unsplit
A15: 14 | B15: 120 | C15: nearest labels (100% agree) | D15: wall | E15: retaining_wall | F15: VP25 | H15: thickness matches a VP type | I15: 270 | J15: 25 | K15: =IF(AND(ISNUMBER(I15),ISNUMBER(J15),J15>0),I15/J15,"") | L15: 0.684 | N15: 90 | O15: solid fill | P15: straight stretch of a thin filled outline with bends (pair of parallel faces) | Q15: =IF(OR(D15="column",D15="wall"),IF(I15<='P vs V'!$B$3*J15,"column","wall"),"") | U15: yes | V15: no | W15: yes | X15: yes | Y15: no | Z15: no | AA15: 0.32 | AE15: 5011 | AF15: 781.6 | AG15: 5018.5 | AH15: 861.3 | AI15: new | AK15: piece of a wall network the colour pipeline left unsplit
A16: 15 | B16: 120 | C16: nearest labels (100% agree) | D16: wall | E16: retaining_wall | F16: VP25 | H16: thickness matches a VP type | I16: 287 | J16: 25 | K16: =IF(AND(ISNUMBER(I16),ISNUMBER(J16),J16>0),I16/J16,"") | L16: 0.722 | N16: 180 | O16: solid fill | P16: straight stretch of a thin filled outline with bends (pair of parallel faces) | Q16: =IF(OR(D16="column",D16="wall"),IF(I16<='P vs V'!$B$3*J16,"column","wall"),"") | U16: yes | V16: no | W16: yes | X16: yes | Y16: no | Z16: no | AA16: 0.84 | AE16: 4771.3 | AF16: 749.2 | AG16: 4856.1 | AH16: 756.6 | AI16: new | AK16: piece of a wall network the colour pipeline left unsplit
A17: 16 | B17: 120 | C17: own label | D17: wall | E17: shear_wall | F17: V1/120 | G17: V1/120/120 | H17: printed | I17: 200 | J17: 25 | K17: =IF(AND(ISNUMBER(I17),ISNUMBER(J17),J17>0),I17/J17,"") | L17: 0.502 | N17: 0 | O17: solid fill | P17: solid fill, rectangle, L > 4 W (EN 1992-1-1 5.3.1(7)) | Q17: =IF(OR(D17="column",D17="wall"),IF(I17<='P vs V'!$B$3*J17,"column","wall"),"") | U17: yes | V17: no | W17: no | X17: no | Y17: yes | Z17: yes | AA17: 2.6 | AE17: 4521.3 | AF17: 517.4 | AG17: 4580.3 | AH17: 524.9 | AI17: yes | AJ17: shear_wall | AL17: (0.87, 0.0, 0.87) | AM17: DM-VOILE
A18: 17 | B18: 120 | C18: own label | D18: wall | E18: shear_wall | F18: V1/120 | G18: V1/120/120 | H18: printed | I18: 200 | J18: 25 | K18: =IF(AND(ISNUMBER(I18),ISNUMBER(J18),J18>0),I18/J18,"") | L18: 0.5 | N18: 0 | O18: solid fill | P18: solid fill, rectangle, L > 4 W (EN 1992-1-1 5.3.1(7)) | Q18: =IF(OR(D18="column",D18="wall"),IF(I18<='P vs V'!$B$3*J18,"column","wall"),"") | U18: yes | V18: no | W18: no | X18: no | Y18: yes | Z18: yes | AA18: 1.7 | AE18: 4516.5 | AF18: 826.7 | AG18: 4575.6 | AH18: 834.2 | AI18: yes | AJ18: shear_wall | AL18: (0.87, 0.0, 0.87) | AM18: DM-VOILE
A19: 18 | B19: 120 | C19: own label | D19: wall | E19: shear_wall | F19: V1/120 | H19: inferred from building + size | I19: 200 | J19: 25 | K19: =IF(AND(ISNUMBER(I19),ISNUMBER(J19),J19>0),I19/J19,"") | L19: 0.5 | N19: 90.1 | O19: solid fill | P19: solid fill, rectangle, L > 4 W (EN 1992-1-1 5.3.1(7)) | Q19: =IF(OR(D19="column",D19="wall"),IF(I19<='P vs V'!$B$3*J19,"column","wall"),"") | R19: S1 | U19: no | V19: no | W19: yes | X19: no | Y19: no | Z19: no | AA19: 1.29 | AE19: 4763.6 | AF19: 416.7 | AG19: 4771.1 | AH19: 475.8 | AI19: new | AK19: piece of a wall network the colour pipeline left unsplit | AL19: (0.87, 0.0, 0.87) | AM19: DM-VOILE
A20: 19 | B20: 120 | C20: own label | D20: wall | E20: shear_wall | F20: V1/120 | H20: inferred from building + size | I20: 200 | J20: 25 | K20: =IF(AND(ISNUMBER(I20),ISNUMBER(J20),J20>0),I20/J20,"") | L20: 0.5 | N20: 90 | O20: solid fill | P20: solid fill, rectangle, L > 4 W (EN 1992-1-1 5.3.1(7)) | Q20: =IF(OR(D20="column",D20="wall"),IF(I20<='P vs V'!$B$3*J20,"column","wall"),"") | U20: yes | V20: no | W20: no | X20: no | Y20: no | Z20: no | AA20: 1.59 | AE20: 4644.1 | AF20: 425.8 | AG20: 4651.4 | AH20: 484.9 | AI20: yes | AJ20: shear_wall | AL20: (0.87, 0.0, 0.87) | AM20: DM-VOILE
A21: 20 | B21: 120 | C21: own label | D21: wall | E21: shear_wall | F21: V1/120 | G21: V1/120/120 | H21: printed | I21: 200 | J21: 25 | K21: =IF(AND(ISNUMBER(I21),ISNUMBER(J21),J21>0),I21/J21,"") | L21: 0.5 | N21: 0 | O21: solid fill | P21: solid fill, rectangle, L > 4 W (EN 1992-1-1 5.3.1(7)) | Q21: =IF(OR(D21="column",D21="wall"),IF(I21<='P vs V'!$B$3*J21,"column","wall"),"") | R21: S7 | U21: no | V21: no | W21: no | X21: no | Y21: yes | Z21: yes | AA21: 2.3 | AE21: 4519.4 | AF21: 681.4 | AG21: 4578.4 | AH21: 688.7 | AI21: yes | AJ21: shear_wall | AL21: (0.87, 0.0, 0.87) | AM21: DM-VOILE
A22: 21 | B22: 120 | C22: own label | D22: wall | E22: shear_wall | F22: V1/120 | G22: V1/120/120 | H22: printed | I22: 200 | J22: 25 | K22: =IF(AND(ISNUMBER(I22),ISNUMBER(J22),J22>0),I22/J22,"") | L22: 0.499 | N22: 0 | O22: solid fill | P22: solid fill, rectangle, L > 4 W (EN 1992-1-1 5.3.1(7)) | Q22: =IF(OR(D22="column",D22="wall"),IF(I22<='P vs V'!$B$3*J22,"column","wall"),"") | R22: S7 | U22: no | V22: no | W22: no | X22: no | Y22: yes | Z22: yes | AA22: 0.02 | AE22: 4519.5 | AF22: 972.2 | AG22: 4578.5 | AH22: 979.5 | AI22: yes | AJ22: shear_wall | AL22: (0.87, 0.0, 0.87) | AM22: DM-VOILE
A23: 22 | B23: 120 | C23: own label | D23: wall | E23: shear_wall | F23: V2/120 | G23: V2/120/120 | H23: printed | I23: 125 | J23: 25 | K23: =IF(AND(ISNUMBER(I23),ISNUMBER(J23),J23>0),I23/J23,"") | L23: 0.313 | N23: 179.7 | O23: solid fill | P23: solid fill, rectangle, L > 4 W (EN 1992-1-1 5.3.1(7)) | Q23: =IF(OR(D23="column",D23="wall"),IF(I23<='P vs V'!$B$3*J23,"column","wall"),"") | R23: SC3 | U23: no | V23: no | W23: no | X23: no | Y23: yes | Z23: yes | AA23: 6.21 | AE23: 4516.6 | AF23: 1323 | AG23: 4553.6 | AH23: 1330.6 | AI23: yes | AJ23: shear_wall | AL23: (0.87, 0.0, 0.87) | AM23: DM-VOILE
A24: 23 | B24: 120 | C24: own label | D24: wall | E24: shear_wall | F24: V2/120 | G24: V2/120/120 | H24: printed | I24: 125 | J24: 25 | K24: =IF(AND(ISNUMBER(I24),ISNUMBER(J24),J24>0),I24/J24,"") | L24: 0.312 | N24: 0 | O24: solid fill | P24: solid fill, rectangle, L > 4 W (EN 1992-1-1 5.3.1(7)) | Q24: =IF(OR(D24="column",D24="wall"),IF(I24<='P vs V'!$B$3*J24,"column","wall"),"") | R24: SC1 | U24: no | V24: no | W24: yes | X24: no | Y24: yes | Z24: no | AA24: 6.81 | AE24: 4749.1 | AF24: 1323.2 | AG24: 4786.1 | AH24: 1330.5 | AI24: new | AK24: piece of a wall network the colour pipeline left unsplit | AL24: (0.87, 0.0, 0.87) | AM24: DM-VOILE
A25: 24 | B25: 120 | C25: own label | D25: wall | E25: shear_wall | F25: V3/120 | G25: V3/120/120 | H25: printed | I25: 125 | J25: 25 | K25: =IF(AND(ISNUMBER(I25),ISNUMBER(J25),J25>0),I25/J25,"") | L25: 0.314 | N25: 0 | O25: solid fill | P25: solid fill, rectangle, L > 4 W (EN 1992-1-1 5.3.1(7)) | Q25: =IF(OR(D25="column",D25="wall"),IF(I25<='P vs V'!$B$3*J25,"column","wall"),"") | R25: S2 | U25: no | V25: no | W25: no | X25: no | Y25: yes | Z25: yes | AA25: 3.07 | AE25: 4285 | AF25: 864.7 | AG25: 4321.9 | AH25: 872.1 | AI25: yes | AJ25: shear_wall | AL25: (0.87, 0.0, 0.87) | AM25: DM-VOILE
A26: 25 | B26: 120 | C26: own label | D26: wall | E26: shear_wall | F26: V3/120 | G26: V3/120/120 | H26: printed | I26: 125 | J26: 25 | K26: =IF(AND(ISNUMBER(I26),ISNUMBER(J26),J26>0),I26/J26,"") | L26: 0.313 | N26: 0.1 | O26: solid fill | P26: solid fill, rectangle, L > 4 W (EN 1992-1-1 5.3.1(7)) | Q26: =IF(OR(D26="column",D26="wall"),IF(I26<='P vs V'!$B$3*J26,"column","wall"),"") | U26: yes | V26: no | W26: no | X26: no | Y26: yes | Z26: no | AA26: 6.21 | AE26: 4253.5 | AF26: 1323.1 | AG26: 4290.5 | AH26: 1330.5 | AI26: yes | AJ26: shear_wall | AL26: (0.87, 0.0, 0.87) | AM26: DM-VOILE
A27: 26 | B27: 120 | C27: own label | D27: wall | E27: shear_wall | F27: V3/120 | G27: V3/120/120 | H27: printed | I27: 125 | J27: 25 | K27: =IF(AND(ISNUMBER(I27),ISNUMBER(J27),J27>0),I27/J27,"") | L27: 0.313 | N27: 0.1 | O27: solid fill | P27: solid fill, rectangle, L > 4 W (EN 1992-1-1 5.3.1(7)) | Q27: =IF(OR(D27="column",D27="wall"),IF(I27<='P vs V'!$B$3*J27,"column","wall"),"") | R27: S2 | U27: no | V27: no | W27: no | X27: no | Y27: yes | Z27: yes | AA27: 1.55 | AE27: 4284.8 | AF27: 1094.2 | AG27: 4321.7 | AH27: 1101.6 | AI27: yes | AJ27: shear_wall | AL27: (0.87, 0.0, 0.87) | AM27: DM-VOIL
A28: 27 | B28: 120 | C28: own label | D28: wall | E28: shear_wall | F28: V3/120 | G28: V3/120120 | H28: printed | I28: 125 | J28: 25 | K28: =IF(AND(ISNUMBER(I28),ISNUMBER(J28),J28>0),I28/J28,"") | L28: 0.313 | N28: 0.1 | O28: solid fill | P28: solid fill, rectangle, L > 4 W (EN 1992-1-1 5.3.1(7)) | Q28: =IF(OR(D28="column",D28="wall"),IF(I28<='P vs V'!$B$3*J28,"column","wall"),"") | R28: S2 | U28: no | V28: no | W28: no | X28: no | Y28: yes | Z28: yes | AA28: 1.4 | AE28: 4285.2 | AF28: 635.6 | AG28: 4322.1 | AH28: 643 | AI28: yes | AJ28: shear_wall | AL28: (0.87, 0.0, 0.87) | AM28: DM-VOILE
A29: 28 | B29: 120 | C29: own label | D29: wall | E29: shear_wall | F29: V5/120 | G29: V5/120/120 | H29: printed | I29: 300 | J29: 25 | K29: =IF(AND(ISNUMBER(I29),ISNUMBER(J29),J29>0),I29/J29,"") | L29: 0.752 | N29: 90 | O29: solid fill | P29: solid fill, rectangle, L > 4 W (EN 1992-1-1 5.3.1(7)) | Q29: =IF(OR(D29="column",D29="wall"),IF(I29<='P vs V'!$B$3*J29,"column","wall"),"") | R29: S6 | U29: no | V29: no | W29: yes | X29: no | Y29: no | Z29: no | AA29: 3.31 | AE29: 4763.8 | AF29: 1046.6 | AG29: 4771.2 | AH29: 1135.2 | AI29: new | AK29: piece of a wall network the colour pipeline left unsplit | AL29: (0.87, 0.0, 0.87) | AM29: DM-VOIL
A30: 29 | B30: 120 | C30: own label | D30: wall | E30: shear_wall | F30: V8/120 | G30: V8/120/120 | H30: printed | I30: 250 | J30: 25 | K30: =IF(AND(ISNUMBER(I30),ISNUMBER(J30),J30>0),I30/J30,"") | L30: 0.625 | N30: 90.1 | O30: solid fill | P30: solid fill, rectangle, L > 4 W (EN 1992-1-1 5.3.1(7)) | Q30: =IF(OR(D30="column",D30="wall"),IF(I30<='P vs V'!$B$3*J30,"column","wall"),"") | R30: S3 | U30: no | V30: no | W30: yes | X30: no | Y30: no | Z30: no | AA30: 2.8 | AE30: 4763.7 | AF30: 561.5 | AG30: 4771.2 | AH30: 635.3 | AI30: new | AK30: piece of a wall network the colour pipeline left unsplit | AL30: (0.87, 0.0, 0.87) | AM30: DM-VOILE
A31: 30 | B31: 120 | C31: own label | D31: wall | E31: shear_wall | F31: V9/120 | G31: V9/120/120 | H31: printed | I31: 200 | J31: 30 | K31: =IF(AND(ISNUMBER(I31),ISNUMBER(J31),J31>0),I31/J31,"") | L31: 0.601 | N31: 0 | O31: solid fill | P31: solid fill, rectangle, L > 4 W (EN 1992-1-1 5.3.1(7)) | Q31: =IF(OR(D31="column",D31="wall"),IF(I31<='P vs V'!$B$3*J31,"column","wall"),"") | R31: S5 | U31: no | V31: no | W31: no | X31: no | Y31: yes | Z31: yes | AA31: 0.02 | AE31: 4516.6 | AF31: 1139.7 | AG31: 4575.6 | AH31: 1148.6 | AI31: yes | AJ31: shear_wall | AL31: (0.87, 0.0, 0.87) | AM31: DM-VOILE
A32: 31 | B32: 120 | C32: nearest labels (100% agree) | D32: wall | E32: shear_wall | F32: (none) | H32: none | I32: 1129 | J32: 20 | K32: =IF(AND(ISNUMBER(I32),ISNUMBER(J32),J32>0),I32/J32,"") | L32: 2.246 | N32: 90 | O32: solid fill | P32: straight stretch of a thin filled outline with bends (pair of parallel faces) | Q32: =IF(OR(D32="column",D32="wall"),IF(I32<='P vs V'!$B$3*J32,"column","wall"),"") | U32: no | V32: no | W32: yes | X32: no | Y32: yes | Z32: no | AA32: 2.87 | AE32: 4765.2 | AF32: 415.9 | AG32: 4771.1 | AH32: 749.2 | AI32: new | AK32: piece of a wall network the colour pipeline left unsplit
A33: 32 | B33: 120 | C33: nearest labels (80% agree) | D33: wall | E33: shear_wall | F33: (none) | H33: none | I33: 1849 | J33: 20 | K33: =IF(AND(ISNUMBER(I33),ISNUMBER(J33),J33>0),I33/J33,"") | L33: 3.705 | N33: 90 | O33: solid fill | P33: straight stretch of a thin filled outline with bends (pair of parallel faces) | Q33: =IF(OR(D33="column",D33="wall"),IF(I33<='P vs V'!$B$3*J33,"column","wall"),"") | U33: no | V33: no | W33: yes | X33: no | Y33: yes | Z33: no | AA33: 4.57 | AE33: 4765.5 | AF33: 976.5 | AG33: 4771.5 | AH33: 1522.5 | AI33: new | AK33: piece of a wall network the colour pipeline left unsplit
A34: 33 | B34: 120 | C34: nearest labels (100% agree) | D34: wall | E34: core_wall_hatched | F34: (none) | H34: none | I34: 272 | J34: 20 | K34: =IF(AND(ISNUMBER(I34),ISNUMBER(J34),J34>0),I34/J34,"") | L34: 0.54 | M34: 2.72 | N34: 0 | O34: cross-hatch | P34: cross-hatch of short strokes in two perpendicular families | Q34: =IF(OR(D34="column",D34="wall"),IF(I34<='P vs V'!$B$3*J34,"column","wall"),"") | U34: yes | V34: no | W34: no | X34: yes | Y34: no | Z34: no | AA34: 0.59 | AB34: 0.28 | AE34: 4645.5 | AF34: 790.3 | AG34: 4702.8 | AH34: 799.7 | AI34: n/a
A35: 34 | B35: 120 | C35: nearest labels (100% agree) | D35: wall | E35: core_wall_hatched | F35: (none) | H35: none | I35: 114 | J35: 20 | K35: =IF(AND(ISNUMBER(I35),ISNUMBER(J35),J35>0),I35/J35,"") | L35: 0.229 | M35: 1.14 | N35: 90 | O35: cross-hatch | P35: cross-hatch of short strokes in two perpendicular families | Q35: =IF(OR(D35="column",D35="wall"),IF(I35<='P vs V'!$B$3*J35,"column","wall"),"") | U35: yes | V35: no | W35: yes | X35: no | Y35: no | Z35: no | AA35: 0.18 | AB35: 0.28 | AE35: 4596.9 | AF35: 799.5 | AG35: 4602.9 | AH35: 850.7 | AI35: n/a
A36: 35 | B36: 120 | C36: nearest labels (100% agree) | D36: wall | E36: core_wall_hatched | F36: (none) | H36: none | I36: 241 | J36: 20 | K36: =IF(AND(ISNUMBER(I36),ISNUMBER(J36),J36>0),I36/J36,"") | L36: 0.48 | M36: 2.41 | N36: 0 | O36: cross-hatch | P36: cross-hatch of short strokes in two perpendicular families | Q36: =IF(OR(D36="column",D36="wall"),IF(I36<='P vs V'!$B$3*J36,"column","wall"),"") | U36: yes | V36: no | W36: no | X36: no | Y36: no | Z36: no | AA36: 1.2 | AB36: 0.28 | AE36: 4648 | AF36: 861.1 | AG36: 4698.9 | AH36: 870.6 | AI36: n/a
A37: 36 | B37: 120 | C37: nearest labels (100% agree) | D37: wall | E37: core_wall_hatched | F37: (none) | H37: none | I37: 408 | J37: 20 | K37: =IF(AND(ISNUMBER(I37),ISNUMBER(J37),J37>0),I37/J37,"") | L37: 0.821 | M37: 4.08 | N37: 180 | O37: cross-hatch | P37: cross-hatch of short strokes in two perpendicular families | Q37: =IF(OR(D37="column",D37="wall"),IF(I37<='P vs V'!$B$3*J37,"column","wall"),"") | U37: yes | V37: no | W37: yes | X37: yes | Y37: no | Z37: no | AA37: 1.35 | AB37: 0.28 | AE37: 4745.3 | AF37: 862.9 | AG37: 4870.3 | AH37: 901.3 | AI37: n/a
A38: 37 | B38: 120 | C38: nearest labels (100% agree) | D38: wall | E38: core_wall_hatched | F38: (none) | H38: none | I38: 163 | J38: 20 | K38: =IF(AND(ISNUMBER(I38),ISNUMBER(J38),J38>0),I38/J38,"") | L38: 0.324 | M38: 1.63 | N38: 0 | O38: cross-hatch | P38: cross-hatch of short strokes in two perpendicular families | Q38: =IF(OR(D38="column",D38="wall"),IF(I38<='P vs V'!$B$3*J38,"column","wall"),"") | U38: yes | V38: no | W38: no | X38: no | Y38: no | Z38: no | AA38: 0.86 | AB38: 0.28 | AE38: 4800 | AF38: 802.4 | AG38: 4869.3 | AH38: 808.2 | AI38: n/a
A39: 38 | B39: 120 | C39: nearest labels (60% agree) | D39: footing | E39: combined_footing | F39: SC3 | G39: SC3- | H39: printed | I39: 500 | J39: 450 | K39: =IF(AND(ISNUMBER(I39),ISNUMBER(J39),J39>0),I39/J39,"") | L39: 22.501 | N39: 179.9 | O39: closed outline | P39: closed rectangular outline around a column/wall or next to an S/SC label | Q39: =IF(OR(D39="column",D39="wall"),IF(I39<='P vs V'!$B$3*J39,"column","wall"),"") | S39: wall+wall | T39: 23 | U39: no | V39: no | W39: yes | X39: no | Y39: yes | Z39: yes | AA39: 6.34 | AE39: 4463.4 | AF39: 1264 | AG39: 4611.3 | AH39: 1397.2 | AI39: yes | AJ39: combined_footing | AL39: (0.72, 0.72, 0.0) | AM39: DM-SEMELLES
A40: 39 | B40: 120 | C40: own label | D40: footing | E40: isolated_footing | F40: S1 | G40: S1-120120 | H40: printed | I40: 280 | J40: 280 | K40: =IF(AND(ISNUMBER(I40),ISNUMBER(J40),J40>0),I40/J40,"") | L40: 7.843 | N40: 90 | O40: closed outline | P40: closed rectangular outline around a column/wall or next to an S/SC label | Q40: =IF(OR(D40="column",D40="wall"),IF(I40<='P vs V'!$B$3*J40,"column","wall"),"") | S40: wall | T40: 0 | U40: no | V40: no | W40: yes | X40: no | Y40: no | Z40: no | AA40: 1.29 | AE40: 4726 | AF40: 404.9 | AG40: 4808.7 | AH40: 487.6 | AI40: yes | AJ40: isolated_footing | AL40: (0.72, 0.72, 0.0) | AM40: DM-SEMELLES
...

Sheet Marks by family
A1: Family | B1: Subclass | C1: Count | D1: On raft (share) | E1: Touches hatched wall (share) | F1: Touches solid element (share) | G1: In strip band (share) | H1: On grade beam (share) | I1: At LG junction (share) | J1: On raft (share in other families) | K1: Touches hatched wall (share in other families) | L1: Touches solid element (share in other families) | M1: In strip band (share in other families) | N1: On grade beam (share in other families) | O1: At LG junction (share in other families) | P1: Signature (colour-free)
A2: column | B2: column | C2: =COUNTIFS(Elements!$D$2:$D$862,$A2,Elements!$E$2:$E$862,$B2) | D2: =IFERROR(COUNTIFS(Elements!$D$2:$D$862,$A2,Elements!$E$2:$E$862,$B2,Elements!$U$2:$U$862,"yes")/$C2,0) | E2: =IFERROR(COUNTIFS(Elements!$D$2:$D$862,$A2,Elements!$E$2:$E$862,$B2,Elements!$V$2:$V$862,"yes")/$C2,0) | F2: =IFERROR(COUNTIFS(Elements!$D$2:$D$862,$A2,Elements!$E$2:$E$862,$B2,Elements!$W$2:$W$862,"yes")/$C2,0) | G2: =IFERROR(COUNTIFS(Elements!$D$2:$D$862,$A2,Elements!$E$2:$E$862,$B2,Elements!$X$2:$X$862,"yes")/$C2,0) | H2: =IFERROR(COUNTIFS(Elements!$D$2:$D$862,$A2,Elements!$E$2:$E$862,$B2,Elements!$Y$2:$Y$862,"yes")/$C2,0) | I2: =IFERROR(COUNTIFS(Elements!$D$2:$D$862,$A2,Elements!$E$2:$E$862,$B2,Elements!$Z$2:$Z$862,"yes")/$C2,0) | J2: =IFERROR((COUNTIFS(Elements!$U$2:$U$862,"yes")-COUNTIFS(Elements!$D$2:$D$862,$A2,Elements!$E$2:$E$862,$B2,Elements!$U$2:$U$862,"yes"))/(COUNTA(Elements!$A$2:$A$862)-$C2),0) | K2: =IFERROR((COUNTIFS(Elements!$V$2:$V$862,"yes")-COUNTIFS(Elements!$D$2:$D$862,$A2,Elements!$E$2:$E$862,$B2,Elements!$V$2:$V$862,"yes"))/(COUNTA(Elements!$A$2:$A$862)-$C2),0) | L2: =IFERROR((COUNTIFS(Elements!$W$2:$W$862,"yes")-COUNTIFS(Elements!$D$2:$D$862,$A2,Elements!$E$2:$E$862,$B2,Elements!$W$2:$W$862,"yes"))/(COUNTA(Elements!$A$2:$A$862)-$C2),0) | M2: =IFERROR((COUNTIFS(Elements!$X$2:$X$862,"yes")-COUNTIFS(Elements!$D$2:$D$862,$A2,Elements!$E$2:$E$862,$B2,Elements!$X$2:$X$862,"yes"))/(COUNTA(Elements!$A$2:$A$862)-$C2),0) | N2: =IFERROR((COUNTIFS(Elements!$Y$2:$Y$862,"yes")-COUNTIFS(Elements!$D$2:$D$862,$A2,Elements!$E$2:$E$862,$B2,Elements!$Y$2:$Y$862,"yes"))/(COUNTA(Elements!$A$2:$A$862)-$C2),0) | O2: =IFERROR((COUNTIFS(Elements!$Z$2:$Z$862,"yes")-COUNTIFS(Elements!$D$2:$D$862,$A2,Elements!$E$2:$E$862,$B2,Elements!$Z$2:$Z$862,"yes"))/(COUNTA(Elements!$A$2:$A$862)-$C2),0) | P2: solid fill; 40-120 x 25-50 cm; L/W 1.60-4.00; inside a footing outline 37%; on a raft 63%; touching a hatched core wall 26%; in a strip-footing band 0%; at a grade-beam junction 26%
A3: crane_foundation | B3: crane_foundation | C3: =COUNTIFS(Elements!$D$2:$D$862,$A3,Elements!$E$2:$E$862,$B3) | D3: =IFERROR(COUNTIFS(Elements!$D$2:$D$862,$A3,Elements!$E$2:$E$862,$B3,Elements!$U$2:$U$862,"yes")/$C3,0) | E3: =IFERROR(COUNTIFS(Elements!$D$2:$D$862,$A3,Elements!$E$2:$E$862,$B3,Elements!$V$2:$V$862,"yes")/$C3,0) | F3: =IFERROR(COUNTIFS(Elements!$D$2:$D$862,$A3,Elements!$E$2:$E$862,$B3,Elements!$W$2:$W$862,"yes")/$C3,0) | G3: =IFERROR(COUNTIFS(Elements!$D$2:$D$862,$A3,Elements!$E$2:$E$862,$B3,Elements!$X$2:$X$862,"yes")/$C3,0) | H3: =IFERROR(COUNTIFS(Elements!$D$2:$D$862,$A3,Elements!$E$2:$E$862,$B3,Elements!$Y$2:$Y$862,"yes")/$C3,0) | I3: =IFERROR(COUNTIFS(Elements!$D$2:$D$862,$A3,Elements!$E$2:$E$862,$B3,Elements!$Z$2:$Z$862,"yes")/$C3,0) | J3: =IFERROR((COUNTIFS(Elements!$U$2:$U$862,"yes")-COUNTIFS(Elements!$D$2:$D$862,$A3,Elements!$E$2:$E$862,$B3,Elements!$U$2:$U$862,"yes"))/(COUNTA(Elements!$A$2:$A$862)-$C3),0) | K3: =IFERROR((COUNTIFS(Elements!$V$2:$V$862,"yes")-COUNTIFS(Elements!$D$2:$D$862,$A3,Elements!$E$2:$E$862,$B3,Elements!$V$2:$V$862,"yes"))/(COUNTA(Elements!$A$2:$A$862)-$C3),0) | L3: =IFERROR((COUNTIFS(Elements!$W$2:$W$862,"yes")-COUNTIFS(Elements!$D$2:$D$862,$A3,Elements!$E$2:$E$862,$B3,Elements!$W$2:$W$862,"yes"))/(COUNTA(Elements!$A$2:$A$862)-$C3),0) | M3: =IFERROR((COUNTIFS(Elements!$X$2:$X$862,"yes")-COUNTIFS(Elements!$D$2:$D$862,$A3,Elements!$E$2:$E$862,$B3,Elements!$X$2:$X$862,"yes"))/(COUNTA(Elements!$A$2:$A$862)-$C3),0) | N3: =IFERROR((COUNTIFS(Elements!$Y$2:$Y$862,"yes")-COUNTIFS(Elements!$D$2:$D$862,$A3,Elements!$E$2:$E$862,$B3,Elements!$Y$2:$Y$862,"yes"))/(COUNTA(Elements!$A$2:$A$862)-$C3),0) | O3: =IFERROR((COUNTIFS(Elements!$Z$2:$Z$862,"yes")-COUNTIFS(Elements!$D$2:$D$862,$A3,Elements!$E$2:$E$862,$B3,Elements!$Z$2:$Z$862,"yes"))/(COUNTA(Elements!$A$2:$A$862)-$C3),0) | P3: group of footings; 840-840 x 840-840 cm
A4: footing | B4: combined_footing | C4: =COUNTIFS(Elements!$D$2:$D$862,$A4,Elements!$E$2:$E$862,$B4) | D4: =IFERROR(COUNTIFS(Elements!$D$2:$D$862,$A4,Elements!$E$2:$E$862,$B4,Elements!$U$2:$U$862,"yes")/$C4,0) | E4: =IFERROR(COUNTIFS(Elements!$D$2:$D$862,$A4,Elements!$E$2:$E$862,$B4,Elements!$V$2:$V$862,"yes")/$C4,0) | F4: =IFERROR(COUNTIFS(Elements!$D$2:$D$862,$A4,Elements!$E$2:$E$862,$B4,Elements!$W$2:$W$862,"yes")/$C4,0) | G4: =IFERROR(COUNTIFS(Elements!$D$2:$D$862,$A4,Elements!$E$2:$E$862,$B4,Elements!$X$2:$X$862,"yes")/$C4,0) | H4: =IFERROR(COUNTIFS(Elements!$D$2:$D$862,$A4,Elements!$E$2:$E$862,$B4,Elements!$Y$2:$Y$862,"yes")/$C4,0) | I4: =IFERROR(COUNTIFS(Elements!$D$2:$D$862,$A4,Elements!$E$2:$E$862,$B4,Elements!$Z$2:$Z$862,"yes")/$C4,0) | J4: =IFERROR((COUNTIFS(Elements!$U$2:$U$862,"yes")-COUNTIFS(Elements!$D$2:$D$862,$A4,Elements!$E$2:$E$862,$B4,Elements!$U$2:$U$862,"yes"))/(COUNTA(Elements!$A$2:$A$862)-$C4),0) | K4: =IFERROR((COUNTIFS(Elements!$V$2:$V$862,"yes")-COUNTIFS(Elements!$D$2:$D$862,$A4,Elements!$E$2:$E$862,$B4,Elements!$V$2:$V$862,"yes"))/(COUNTA(Elements!$A$2:$A$862)-$C4),0) | L4: =IFERROR((COUNTIFS(Elements!$W$2:$W$862,"yes")-COUNTIFS(Elements!$D$2:$D$862,$A4,Elements!$E$2:$E$862,$B4,Elements!$W$2:$W$862,"yes"))/(COUNTA(Elements!$A$2:$A$862)-$C4),0) | M4: =IFERROR((COUNTIFS(Elements!$X$2:$X$862,"yes")-COUNTIFS(Elements!$D$2:$D$862,$A4,Elements!$E$2:$E$862,$B4,Elements!$X$2:$X$862,"yes"))/(COUNTA(Elements!$A$2:$A$862)-$C4),0) | N4: =IFERROR((COUNTIFS(Elements!$Y$2:$Y$862,"yes")-COUNTIFS(Elements!$D$2:$D$862,$A4,Elements!$E$2:$E$862,$B4,Elements!$Y$2:$Y$862,"yes"))/(COUNTA(Elements!$A$2:$A$862)-$C4),0) | O4: =IFERROR((COUNTIFS(Elements!$Z$2:$Z$862,"yes")-COUNTIFS(Elements!$D$2:$D$862,$A4,Elements!$E$2:$E$862,$B4,Elements!$Z$2:$Z$862,"yes"))/(COUNTA(Elements!$A$2:$A$862)-$C4),0) | P4: closed outline; 350-600 x 200-450 cm; carries wall+wall (24), column+wall (3), wall+wall+wall+wall (1); grade beam crossing it 93%
A5: footing | B5: crane_footing | C5: =COUNTIFS(Elements!$D$2:$D$862,$A5,Elements!$E$2:$E$862,$B5) | D5: =IFERROR(COUNTIFS(Elements!$D$2:$D$862,$A5,Elements!$E$2:$E$862,$B5,Elements!$U$2:$U$862,"yes")/$C5,0) | E5: =IFERROR(COUNTIFS(Elements!$D$2:$D$862,$A5,Elements!$E$2:$E$862,$B5,Elements!$V$2:$V$862,"yes")/$C5,0) | F5: =IFERROR(COUNTIFS(Elements!$D$2:$D$862,$A5,Elements!$E$2:$E$862,$B5,Elements!$W$2:$W$862,"yes")/$C5,0) | G5: =IFERROR(COUNTIFS(Elements!$D$2:$D$862,$A5,Elements!$E$2:$E$862,$B5,Elements!$X$2:$X$862,"yes")/$C5,0) | H5: =IFERROR(COUNTIFS(Elements!$D$2:$D$862,$A5,Elements!$E$2:$E$862,$B5,Elements!$Y$2:$Y$862,"yes")/$C5,0) | I5: =IFERROR(COUNTIFS(Elements!$D$2:$D$862,$A5,Elements!$E$2:$E$862,$B5,Elements!$Z$2:$Z$862,"yes")/$C5,0) | J5: =IFERROR((COUNTIFS(Elements!$U$2:$U$862,"yes")-COUNTIFS(Elements!$D$2:$D$862,$A5,Elements!$E$2:$E$862,$B5,Elements!$U$2:$U$862,"yes"))/(COUNTA(Elements!$A$2:$A$862)-$C5),0) | K5: =IFERROR((COUNTIFS(Elements!$V$2:$V$862,"yes")-COUNTIFS(Elements!$D$2:$D$862,$A5,Elements!$E$2:$E$862,$B5,Elements!$V$2:$V$862,"yes"))/(COUNTA(Elements!$A$2:$A$862)-$C5),0) | L5: =IFERROR((COUNTIFS(Elements!$W$2:$W$862,"yes")-COUNTIFS(Elements!$D$2:$D$862,$A5,Elements!$E$2:$E$862,$B5,Elements!$W$2:$W$862,"yes"))/(COUNTA(Elements!$A$2:$A$862)-$C5),0) | M5: =IFERROR((COUNTIFS(Elements!$X$2:$X$862,"yes")-COUNTIFS(Elements!$D$2:$D$862,$A5,Elements!$E$2:$E$862,$B5,Elements!$X$2:$X$862,"yes"))/(COUNTA(Elements!$A$2:$A$862)-$C5),0) | N5: =IFERROR((COUNTIFS(Elements!$Y$2:$Y$862,"yes")-COUNTIFS(Elements!$D$2:$D$862,$A5,Elements!$E$2:$E$862,$B5,Elements!$Y$2:$Y$862,"yes"))/(COUNTA(Elements!$A$2:$A$862)-$C5),0) | O5: =IFERROR((COUNTIFS(Elements!$Z$2:$Z$862,"yes")-COUNTIFS(Elements!$D$2:$D$862,$A5,Elements!$E$2:$E$862,$B5,Elements!$Z$2:$Z$862,"yes"))/(COUNTA(Elements!$A$2:$A$862)-$C5),0) | P5: closed outline; 240-240 x 240-240 cm; carries none (4); grade beam crossing it 100%
A6: footing | B6: isolated_footing | C6: =COUNTIFS(Elements!$D$2:$D$862,$A6,Elements!$E$2:$E$862,$B6) | D6: =IFERROR(COUNTIFS(Elements!$D$2:$D$862,$A6,Elements!$E$2:$E$862,$B6,Elements!$U$2:$U$862,"yes")/$C6,0) | E6: =IFERROR(COUNTIFS(Elements!$D$2:$D$862,$A6,Elements!$E$2:$E$862,$B6,Elements!$V$2:$V$862,"yes")/$C6,0) | F6: =IFERROR(COUNTIFS(Elements!$D$2:$D$862,$A6,Elements!$E$2:$E$862,$B6,Elements!$W$2:$W$862,"yes")/$C6,0) | G6: =IFERROR(COUNTIFS(Elements!$D$2:$D$862,$A6,Elements!$E$2:$E$862,$B6,Elements!$X$2:$X$862,"yes")/$C6,0) | H6: =IFERROR(COUNTIFS(Elements!$D$2:$D$862,$A6,Elements!$E$2:$E$862,$B6,Elements!$Y$2:$Y$862,"yes")/$C6,0) | I6: =IFERROR(COUNTIFS(Elements!$D$2:$D$862,$A6,Elements!$E$2:$E$862,$B6,Elements!$Z$2:$Z$862,"yes")/$C6,0) | J6: =IFERROR((COUNTIFS(Elements!$U$2:$U$862,"yes")-COUNTIFS(Elements!$D$2:$D$862,$A6,Elements!$E$2:$E$862,$B6,Elements!$U$2:$U$862,"yes"))/(COUNTA(Elements!$A$2:$A$862)-$C6),0) | K6: =IFERROR((COUNTIFS(Elements!$V$2:$V$862,"yes")-COUNTIFS(Elements!$D$2:$D$862,$A6,Elements!$E$2:$E$862,$B6,Elements!$V$2:$V$862,"yes"))/(COUNTA(Elements!$A$2:$A$862)-$C6),0) | L6: =IFERROR((COUNTIFS(Elements!$W$2:$W$862,"yes")-COUNTIFS(Elements!$D$2:$D$862,$A6,Elements!$E$2:$E$862,$B6,Elements!$W$2:$W$862,"yes"))/(COUNTA(Elements!$A$2:$A$862)-$C6),0) | M6: =IFERROR((COUNTIFS(Elements!$X$2:$X$862,"yes")-COUNTIFS(Elements!$D$2:$D$862,$A6,Elements!$E$2:$E$862,$B6,Elements!$X$2:$X$862,"yes"))/(COUNTA(Elements!$A$2:$A$862)-$C6),0) | N6: =IFERROR((COUNTIFS(Elements!$Y$2:$Y$862,"yes")-COUNTIFS(Elements!$D$2:$D$862,$A6,Elements!$E$2:$E$862,$B6,Elements!$Y$2:$Y$862,"yes"))/(COUNTA(Elements!$A$2:$A$862)-$C6),0) | O6: =IFERROR((COUNTIFS(Elements!$Z$2:$Z$862,"yes")-COUNTIFS(Elements!$D$2:$D$862,$A6,Elements!$E$2:$E$862,$B6,Elements!$Z$2:$Z$862,"yes"))/(COUNTA(Elements!$A$2:$A$862)-$C6),0) | P6: closed outline; 150-600 x 150-450 cm; carries wall (64), column (9), wall+wall (1); grade beam crossing it 95%
A7: grade_beam | B7: grade_beam | C7: =COUNTIFS(Elements!$D$2:$D$862,$A7,Elements!$E$2:$E$862,$B7) | D7: =IFERROR(COUNTIFS(Elements!$D$2:$D$862,$A7,Elements!$E$2:$E$862,$B7,Elements!$U$2:$U$862,"yes")/$C7,0) | E7: =IFERROR(COUNTIFS(Elements!$D$2:$D$862,$A7,Elements!$E$2:$E$862,$B7,Elements!$V$2:$V$862,"yes")/$C7,0) | F7: =IFERROR(COUNTIFS(Elements!$D$2:$D$862,$A7,Elements!$E$2:$E$862,$B7,Elements!$W$2:$W$862,"yes")/$C7,0) | G7: =IFERROR(COUNTIFS(Elements!$D$2:$D$862,$A7,Elements!$E$2:$E$862,$B7,Elements!$X$2:$X$862,"yes")/$C7,0) | H7: =IFERROR(COUNTIFS(Elements!$D$2:$D$862,$A7,Elements!$E$2:$E$862,$B7,Elements!$Y$2:$Y$862,"yes")/$C7,0) | I7: =IFERROR(COUNTIFS(Elements!$D$2:$D$862,$A7,Elements!$E$2:$E$862,$B7,Elements!$Z$2:$Z$862,"yes")/$C7,0) | J7: =IFERROR((COUNTIFS(Elements!$U$2:$U$862,"yes")-COUNTIFS(Elements!$D$2:$D$862,$A7,Elements!$E$2:$E$862,$B7,Elements!$U$2:$U$862,"yes"))/(COUNTA(Elements!$A$2:$A$862)-$C7),0) | K7: =IFERROR((COUNTIFS(Elements!$V$2:$V$862,"yes")-COUNTIFS(Elements!$D$2:$D$862,$A7,Elements!$E$2:$E$862,$B7,Elements!$V$2:$V$862,"yes"))/(COUNTA(Elements!$A$2:$A$862)-$C7),0) | L7: =IFERROR((COUNTIFS(Elements!$W$2:$W$862,"yes")-COUNTIFS(Elements!$D$2:$D$862,$A7,Elements!$E$2:$E$862,$B7,Elements!$W$2:$W$862,"yes"))/(COUNTA(Elements!$A$2:$A$862)-$C7),0) | M7: =IFERROR((COUNTIFS(Elements!$X$2:$X$862,"yes")-COUNTIFS(Elements!$D$2:$D$862,$A7,Elements!$E$2:$E$862,$B7,Elements!$X$2:$X$862,"yes"))/(COUNTA(Elements!$A$2:$A$862)-$C7),0) | N7: =IFERROR((COUNTIFS(Elements!$Y$2:$Y$862,"yes")-COUNTIFS(Elements!$D$2:$D$862,$A7,Elements!$E$2:$E$862,$B7,Elements!$Y$2:$Y$862,"yes"))/(COUNTA(Elements!$A$2:$A$862)-$C7),0) | O7: =IFERROR((COUNTIFS(Elements!$Z$2:$Z$862,"yes")-COUNTIFS(Elements!$D$2:$D$862,$A7,Elements!$E$2:$E$862,$B7,Elements!$Z$2:$Z$862,"yes"))/(COUNTA(Elements!$A$2:$A$862)-$C7),0) | P7: parallel line pair; 30-2249 x 25-40 cm; width stated in its label
