Workbook

Sheet README
A1: Geometry-first classification
A3: How each element got its class
A4: 1. Objects were found from geometry only: solid fills (pieces grouped by the order they are drawn in), cross-hatched regions, closed outlines, bands (pairs of parallel lines; the widths come from the drawing itself) and circle stamps with corner rays. No colour, no layer, no text.
A5: 2. Objects of the same drawing kind were clustered on geometric features only: size, shape (including the EN 1992-1-1 5.3.1(7) section test, long side <= 4 x short side), and what they touch, contain or stand in. Deliberately more clusters than classes.
A6: 3. Every label was matched to one object by distance and text alignment, in one global assignment that ignores what the label says; a label may stay unmatched.
A7: 4. A cluster takes the class that most of its matched labels name (>= 5 votes for it, at least 1.5 x the runner-up, with labels on >= 10% of its members, or a small clear vote of 2 or more with labels on 30% of its members). A cluster without enough labels takes the name of the most similar named cluster of the same drawing kind (feature distance <= 1.6), else stays unnamed. Unlabelled members inherit their cluster's class - that is how unlabelled walls became walls.
A8: 5. Labels were matched again, now only to objects of the class they name (or unnamed ones, at a cost), penalising an object whose size differs from the size its type has where a label sits right on its element, or that lies between expansion joints of another building. That gives the type keys (P1/124, V3/120, S7...).
A9: 6. An unlabelled member of a class takes the type of its class (and building, where sizes vary per building) that has its size: '~P1/124' when one type fits, '~V2/123|V4/123' when several share the size (nearest first). When none fits, the type source says so: for a 'column' that is a sign it is not a column.
A10: 7. Buildings: the footprint is cut along the expansion joints (pairs of long lines a few cm apart); a region whose labels agree is one building. Elsewhere the nearest building-numbered labels within the region decide.
A12: What labels do and do not decide
A13: A single label never decides an object's class: it votes for its cluster, and its object keeps the cluster's class even if the label disagrees. Disagreeing labels are listed on 'Conflicts' - each is a wrong label, a wrongly placed label, or a geometry mistake worth a look.
A14: Clusters no label votes for (cross-hatched walls, small stippled squares, several band widths) keep a descriptive geometric name; naming them is an interpretation, not something the plan states.
... A24: Scale 1/200.0, from 222 dimension texts (median error 0.24 cm). Formulas recalculate on opening; they were checked with the Python 'formulas' engine.

Sheet Summary by building
A1: Building | B1: Class | C1: Type key | D1: Count | E1: Length min (cm) | F1: Length max (cm) | G1: Width min (cm) | H1: Width max (cm) | I1: Same section? | J1: Total length (m) | K1: Of which typed by inference
A2: 120 | B2: column | C2: (none) | D2: =COUNTIFS(Objects!$B$2:$B$1089,$A2,Objects!$F$2:$F$1089,$B2,Objects!$H$2:$H$1089,$C2) | E2: =_xlfn.MINIFS(Objects!$K$2:$K$1089,Objects!$B$2:$B$1089,$A2,Objects!$F$2:$F$1089,$B2,Objects!$H$2:$H$1089,$C2) | F2: =_xlfn.MAXIFS(Objects!$K$2:$K$1089,Objects!$B$2:$B$1089,$A2,Objects!$F$2:$F$1089,$B2,Objects!$H$2:$H$1089,$C2) | G2: =_xlfn.MINIFS(Objects!$L$2:$L$1089,Objects!$B$2:$B$1089,$A2,Objects!$F$2:$F$1089,$B2,Objects!$H$2:$H$1089,$C2) | H2: =_xlfn.MAXIFS(Objects!$L$2:$L$1089,Objects!$B$2:$B$1089,$A2,Objects!$F$2:$F$1089,$B2,Objects!$H$2:$H$1089,$C2) | I2: =IF(OR(C2="(none)",B2="raft",B2="sump_pit"),"n/a",IF(OR(B2="column",B2="shear_wall",B2="isolated_footing",B2="combined_footing"),IF(AND(F2-E2<=3,H2-G2<=3),"yes","no"),IF(H2-G2<=3,"yes (thickness)","no (thickness)"))) | J2: =SUMIFS(Objects!$K$2:$K$1089,Objects!$B$2:$B$1089,$A2,Objects!$F$2:$F$1089,$B2,Objects!$H$2:$H$1089,$C2)/100 | K2: =COUNTIFS(Objects!$B$2:$B$1089,$A2,Objects!$F$2:$F$1089,$B2,Objects!$H$2:$H$1089,$C2,Objects!$I$2:$I$1089,"inferred*")
A3: 120 | B3: column | C3: P1/120 | D3: =COUNTIFS(Objects!$B$2:$B$1089,$A3,Objects!$F$2:$F$1089,$B3,Objects!$H$2:$H$1089,$C3) | E3: =_xlfn.MINIFS(Objects!$K$2:$K$1089,Objects!$B$2:$B$1089,$A3,Objects!$F$2:$F$1089,$B3,Objects!$H$2:$H$1089,$C3) | F3: =_xlfn.MAXIFS(Objects!$K$2:$K$1089,Objects!$B$2:$B$1089,$A3,Objects!$F$2:$F$1089,$B3,Objects!$H$2:$H$1089,$C3) | G3: =_xlfn.MINIFS(Objects!$L$2:$L$1089,Objects!$B$2:$B$1089,$A3,Objects!$F$2:$F$1089,$B3,Objects!$H$2:$H$1089,$C3) | H3: =_xlfn.MAXIFS(Objects!$L$2:$L$1089,Objects!$B$2:$B$1089,$A3,Objects!$F$2:$F$1089,$B3,Objects!$H$2:$H$1089,$C3) | I3: =IF(OR(C3="(none)",B3="raft",B3="sump_pit"),"n/a",IF(OR(B3="column",B3="shear_wall",B3="isolated_footing",B3="combined_footing"),IF(AND(F3-E3<=3,H3-G3<=3),"yes","no"),IF(H3-G3<=3,"yes (thickness)","no (thickness)"))) | J3: =SUMIFS(Objects!$K$2:$K$1089,Objects!$B$2:$B$1089,$A3,Objects!$F$2:$F$1089,$B3,Objects!$H$2:$H$1089,$C3)/100 | K3: =COUNTIFS(Objects!$B$2:$B$1089,$A3,Objects!$F$2:$F$1089,$B3,Objects!$H$2:$H$1089,$C3,Objects!$I$2:$I$1089,"inferred*")
A4: 120 | B4: shear_wall | C4: (none) | D4: =COUNTIFS(Objects!$B$2:$B$1089,$A4,Objects!$F$2:$F$1089,$B4,Objects!$H$2:$H$1089,$C4) | E4: =_xlfn.MINIFS(Objects!$K$2:$K$1089,Objects!$B$2:$B$1089,$A4,Objects!$F$2:$F$1089,$B4,Objects!$H$2:$H$1089,$C4) | F4: =_xlfn.MAXIFS(Objects!$K$2:$K$1089,Objects!$B$2:$B$1089,$A4,Objects!$F$2:$F$1089,$B4,Objects!$H$2:$H$1089,$C4) | G4: =_xlfn.MINIFS(Objects!$L$2:$L$1089,Objects!$B$2:$B$1089,$A4,Objects!$F$2:$F$1089,$B4,Objects!$H$2:$H$1089,$C4) | H4: =_xlfn.MAXIFS(Objects!$L$2:$L$1089,Objects!$B$2:$B$1089,$A4,Objects!$F$2:$F$1089,$B4,Objects!$H$2:$H$1089,$C4) | I4: =IF(OR(C4="(none)",B4="raft",B4="sump_pit"),"n/a",IF(OR(B4="column",B4="shear_wall",B4="isolated_footing",B4="combined_footing"),IF(AND(F4-E4<=3,H4-G4<=3),"yes","no"),IF(H4-G4<=3,"yes (thickness)","no (thickness)"))) | J4: =SUMIFS(Objects!$K$2:$K$1089,Objects!$B$2:$B$1089,$A4,Objects!$F$2:$F$1089,$B4,Objects!$H$2:$H$1089,$C4)/100 | K4: =COUNTIFS(Objects!$B$2:$B$1089,$A4,Objects!$F$2:$F$1089,$B4,Objects!$H$2:$H$1089,$C4,Objects!$I$2:$I$1089,"inferred*")
A5: 120 | B5: shear_wall | C5: V1/120 | D5: =COUNTIFS(Objects!$B$2:$B$1089,$A5,Objects!$F$2:$F$1089,$B5,Objects!$H$2:$H$1089,$C5) | E5: =_xlfn.MINIFS(Objects!$K$2:$K$1089,Objects!$B$2:$B$1089,$A5,Objects!$F$2:$F$1089,$B5,Objects!$H$2:$H$1089,$C5) | F5: =_xlfn.MAXIFS(Objects!$K$2:$K$1089,Objects!$B$2:$B$1089,$A5,Objects!$F$2:$F$1089,$B5,Objects!$H$2:$H$1089,$C5) | G5: =_xlfn.MINIFS(Objects!$L$2:$L$1089,Objects!$B$2:$B$1089,$A5,Objects!$F$2:$F$1089,$B5,Objects!$H$2:$H$1089,$C5) | H5: =_xlfn.MAXIFS(Objects!$L$2:$L$1089,Objects!$B$2:$B$1089,$A5,Objects!$F$2:$F$1089,$B5,Objects!$H$2:$H$1089,$C5) | I5: =IF(OR(C5="(none)",B5="raft",B5="sump_pit"),"n/a",IF(OR(B5="column",B5="shear_wall",B5="isolated_footing",B5="combined_footing"),IF(AND(F5-E5<=3,H5-G5<=3),"yes","no"),IF(H5-G5<=3,"yes (thickness)","no (thickness)"))) | J5: =SUMIFS(Objects!$K$2:$K$1089,Objects!$B$2:$B$1089,$A5,Objects!$F$2:$F$1089,$B5,Objects!$H$2:$H$1089,$C5)/100 | K5: =COUNTIFS(Objects!$B$2:$B$1089,$A5,Objects!$F$2:$F$1089,$B5,Objects!$H$2:$H$1089,$C5,Objects!$I$2:$I$1089,"inferred*")
A6: 120 | B6: shear_wall | C6: V2/120 | D6: =COUNTIFS(Objects!$B$2:$B$1089,$A6,Objects!$F$2:$F$1089,$B6,Objects!$H$2:$H$1089,$C6) | E6: =_xlfn.MINIFS(Objects!$K$2:$K$1089,Objects!$B$2:$B$1089,$A6,Objects!$F$2:$F$1089,$B6,Objects!$H$2:$H$1089,$C6) | F6: =_xlfn.MAXIFS(Objects!$K$2:$K$1089,Objects!$B$2:$B$1089,$A6,Objects!$F$2:$F$1089,$B6,Objects!$H$2:$H$1089,$C6) | G6: =_xlfn.MINIFS(Objects!$L$2:$L$1089,Objects!$B$2:$B$1089,$A6,Objects!$F$2:$F$1089,$B6,Objects!$H$2:$H$1089,$C6) | H6: =_xlfn.MAXIFS(Objects!$L$2:$L$1089,Objects!$B$2:$B$1089,$A6,Objects!$F$2:$F$1089,$B6,Objects!$H$2:$H$1089,$C6) | I6: =IF(OR(C6="(none)",B6="raft",B6="sump_pit"),"n/a",IF(OR(B6="column",B6="shear_wall",B6="isolated_footing",B6="combined_footing"),IF(AND(F6-E6<=3,H6-G6<=3),"yes","no"),IF(H6-G6<=3,"yes (thickness)","no (thickness)"))) | J6: =SUMIFS(Objects!$K$2:$K$1089,Objects!$B$2:$B$1089,$A6,Objects!$F$2:$F$1089,$B6,Objects!$H$2:$H$1089,$C6)/100 | K6: =COUNTIFS(Objects!$B$2:$B$1089,$A6,Objects!$F$2:$F$1089,$B6,Objects!$H$2:$H$1089,$C6,Objects!$I$2:$I$1089,"inferred*")
A7: 120 | B7: shear_wall | C7: V3/120 | D7: =COUNTIFS(Objects!$B$2:$B$1089,$A7,Objects!$F$2:$F$1089,$B7,Objects!$H$2:$H$1089,$C7) | E7: =_xlfn.MINIFS(Objects!$K$2:$K$1089,Objects!$B$2:$B$1089,$A7,Objects!$F$2:$F$1089,$B7,Objects!$H$2:$H$1089,$C7) | F7: =_xlfn.MAXIFS(Objects!$K$2:$K$1089,Objects!$B$2:$B$1089,$A7,Objects!$F$2:$F$1089,$B7,Objects!$H$2:$H$1089,$C7) | G7: =_xlfn.MINIFS(Objects!$L$2:$L$1089,Objects!$B$2:$B$1089,$A7,Objects!$F$2:$F$1089,$B7,Objects!$H$2:$H$1089,$C7) | H7: =_xlfn.MAXIFS(Objects!$L$2:$L$1089,Objects!$B$2:$B$1089,$A7,Objects!$F$2:$F$1089,$B7,Objects!$H$2:$H$1089,$C7) | I7: =IF(OR(C7="(none)",B7="raft",B7="sump_pit"),"n/a",IF(OR(B7="column",B7="shear_wall",B7="isolated_footing",B7="combined_footing"),IF(AND(F7-E7<=3,H7-G7<=3),"yes","no"),IF(H7-G7<=3,"yes (thickness)","no (thickness)"))) | J7: =SUMIFS(Objects!$K$2:$K$1089,Objects!$B$2:$B$1089,$A7,Objects!$F$2:$F$1089,$B7,Objects!$H$2:$H$1089,$C7)/100 | K7: =COUNTIFS(Objects!$B$2:$B$1089,$A7,Objects!$F$2:$F$1089,$B7,Objects!$H$2:$H$1089,$C7,Objects!$I$2:$I$1089,"inferred*")
A8: 120 | B8: shear_wall | C8: V4/120 | D8: =COUNTIFS(Objects!$B$2:$B$1089,$A8,Objects!$F$2:$F$1089,$B8,Objects!$H$2:$H$1089,$C8) | E8: =_xlfn.MINIFS(Objects!$K$2:$K$1089,Objects!$B$2:$B$1089,$A8,Objects!$F$2:$F$1089,$B8,Objects!$H$2:$H$1089,$C8) | F8: =_xlfn.MAXIFS(Objects!$K$2:$K$1089,Objects!$B$2:$B$1089,$A8,Objects!$F$2:$F$1089,$B8,Objects!$H$2:$H$1089,$C8) | G8: =_xlfn.MINIFS(Objects!$L$2:$L$1089,Objects!$B$2:$B$1089,$A8,Objects!$F$2:$F$1089,$B8,Objects!$H$2:$H$1089,$C8) | H8: =_xlfn.MAXIFS(Objects!$L$2:$L$1089,Objects!$B$2:$B$1089,$A8,Objects!$F$2:$F$1089,$B8,Objects!$H$2:$H$1089,$C8) | I8: =IF(OR(C8="(none)",B8="raft",B8="sump_pit"),"n/a",IF(OR(B8="column",B8="shear_wall",B8="isolated_footing",B8="combined_footing"),IF(AND(F8-E8<=3,H8-G8<=3),"yes","no"),IF(H8-G8<=3,"yes (thickness)","no (thickness)"))) | J8: =SUMIFS(Objects!$K$2:$K$1089,Objects!$B$2:$B$1089,$A8,Objects!$F$2:$F$1089,$B8,Objects!$H$2:$H$1089,$C8)/100 | K8: =COUNTIFS(Objects!$B$2:$B$1089,$A8,Objects!$F$2:$F$1089,$B8,Objects!$H$2:$H$1089,$C8,Objects!$I$2:$I$1089,"inferred*")
A9: 120 | B9: shear_wall | C9: V5/120 | D9: =COUNTIFS(Objects!$B$2:$B$1089,$A9,Objects!$F$2:$F$1089,$B9,Objects!$H$2:$H$1089,$C9) | E9: =_xlfn.MINIFS(Objects!$K$2:$K$1089,Objects!$B$2:$B$1089,$A9,Objects!$F$2:$F$1089,$B9,Objects!$H$2:$H$1089,$C9) | F9: =_xlfn.MAXIFS(Objects!$K$2:$K$1089,Objects!$B$2:$B$1089,$A9,Objects!$F$2:$F$1089,$B9,Objects!$H$2:$H$1089,$C9) | G9: =_xlfn.MINIFS(Objects!$L$2:$L$1089,Objects!$B$2:$B$1089,$A9,Objects!$F$2:$F$1089,$B9,Objects!$H$2:$H$1089,$C9) | H9: =_xlfn.MAXIFS(Objects!$L$2:$L$1089,Objects!$B$2:$B$1089,$A9,Objects!$F$2:$F$1089,$B9,Objects!$H$2:$H$1089,$C9) | I9: =IF(OR(C9="(none)",B9="raft",B9="sump_pit"),"n/a",IF(OR(B9="column",B9="shear_wall",B9="isolated_footing",B9="combined_footing"),IF(AND(F9-E9<=3,H9-G9<=3),"yes","no"),IF(H9-G9<=3,"yes (thickness)","no (thickness)"))) | J9: =SUMIFS(Objects!$K$2:$K$1089,Objects!$B$2:$B$1089,$A9,Objects!$F$2:$F$1089,$B9,Objects!$H$2:$H$1089,$C9)/100 | K9: =COUNTIFS(Objects!$B$2:$B$1089,$A9,Objects!$F$2:$F$1089,$B9,Objects!$H$2:$H$1089,$C9,Objects!$I$2:$I$1089,"inferred*")
A10: 120 | B10: shear_wall | C10: V8/120 | D10: =COUNTIFS(Objects!$B$2:$B$1089,$A10,Objects!$F$2:$F$1089,$B10,Objects!$H$2:$H$1089,$C10) | E10: =_xlfn.MINIFS(Objects!$K$2:$K$1089,Objects!$B$2:$B$1089,$A10,Objects!$F$2:$F$1089,$B10,Objects!$H$2:$H$1089,$C10) | F10: =_xlfn.MAXIFS(Objects!$K$2:$K$1089,Objects!$B$2:$B$1089,$A10,Objects!$F$2:$F$1089,$B10,Objects!$H$2:$H$1089,$C10) | G10: =_xlfn.MINIFS(Objects!$L$2:$L$1089,Objects!$B$2:$B$1089,$A10,Objects!$F$2:$F$1089,$B10,Objects!$H$2:$H$1089,$C10) | H10: =_xlfn.MAXIFS(Objects!$L$2:$L$1089,Objects!$B$2:$B$1089,$A10,Objects!$F$2:$F$1089,$B10,Objects!$H$2:$H$1089,$C10) | I10: =IF(OR(C10="(none)",B10="raft",B10="sump_pit"),"n/a",IF(OR(B10="column",B10="shear_wall",B10="isolated_footing",B10="combined_footing"),IF(AND(F10-E10<=3,H10-G10<=3),"yes","no"),IF(H10-G10<=3,"yes (thickness)","no (thickness)"))) | J10: =SUMIFS(Objects!$K$2:$K$1089,Objects!$B$2:$B$1089,$A10,Objects!$F$2:$F$1089,$B10,Objects!$H$2:$H$1089,$C10)/100 | K10: =COUNTIFS(Objects!$B$2:$B$1089,$A10,Objects!$F$2:$F$1089,$B10,Objects!$H$2:$H$1089,$C10,Objects!$I$2:$I$1089,"inferred*")
A11: 120 | B11: shear_wall | C11: V9/120 | D11: =COUNTIFS(Objects!$B$2:$B$1089,$A11,Objects!$F$2:$F$1089,$B11,Objects!$H$2:$H$1089,$C11) | E11: =_xlfn.MINIFS(Objects!$K$2:$K$1089,Objects!$B$2:$B$1089,$A11,Objects!$F$2:$F$1089,$B11,Objects!$H$2:$H$1089,$C11) | F11: =_xlfn.MAXIFS(Objects!$K$2:$K$1089,Objects!$B$2:$B$1089,$A11,Objects!$F$2:$F$1089,$B11,Objects!$H$2:$H$1089,$C11) | G11: =_xlfn.MINIFS(Objects!$L$2:$L$1089,Objects!$B$2:$B$1089,$A11,Objects!$F$2:$F$1089,$B11,Objects!$H$2:$H$1089,$C11) | H11: =_xlfn.MAXIFS(Objects!$L$2:$L$1089,Objects!$B$2:$B$1089,$A11,Objects!$F$2:$F$1089,$B11,Objects!$H$2:$H$1089,$C11) | I11: =IF(OR(C11="(none)",B11="raft",B11="sump_pit"),"n/a",IF(OR(B11="column",B11="shear_wall",B11="isolated_footing",B11="combined_footing"),IF(AND(F11-E11<=3,H11-G11<=3),"yes","no"),IF(H11-G11<=3,"yes (thickness)","no (thickness)"))) | J11: =SUMIFS(Objects!$K$2:$K$1089,Objects!$B$2:$B$1089,$A11,Objects!$F$2:$F$1089,$B11,Objects!$H$2:$H$1089,$C11)/100 | K11: =COUNTIFS(Objects!$B$2:$B$1089,$A11,Objects!$F$2:$F$1089,$B11,Objects!$H$2:$H$1089,$C11,Objects!$I$2:$I$1089,"inferred*")
A12: 120 | B12: retaining_wall | C12: VP20 | D12: =COUNTIFS(Objects!$B$2:$B$1089,$A12,Objects!$F$2:$F$1089,$B12,Objects!$H$2:$H$1089,$C12) | E12: =_xlfn.MINIFS(Objects!$K$2:$K$1089,Objects!$B$2:$B$1089,$A12,Objects!$F$2:$F$1089,$B12,Objects!$H$2:$H$1089,$C12) | F12: =_xlfn.MAXIFS(Objects!$K$2:$K$1089,Objects!$B$2:$B$1089,$A12,Objects!$F$2:$F$1089,$B12,Objects!$H$2:$H$1089,$C12) | G12: =_xlfn.MINIFS(Objects!$L$2:$L$1089,Objects!$B$2:$B$1089,$A12,Objects!$F$2:$F$1089,$B12,Objects!$H$2:$H$1089,$C12) | H12: =_xlfn.MAXIFS(Objects!$L$2:$L$1089,Objects!$B$2:$B$1089,$A12,Objects!$F$2:$F$1089,$B12,Objects!$H$2:$H$1089,$C12) | I12: =IF(OR(C12="(none)",B12="raft",B12="sump_pit"),"n/a",IF(OR(B12="column",B12="shear_wall",B12="isolated_footing",B12="combined_footing"),IF(AND(F12-E12<=3,H12-G12<=3),"yes","no"),IF(H12-G12<=3,"yes (thickness)","no (thickness)"))) | J12: =SUMIFS(Objects!$K$2:$K$1089,Objects!$B$2:$B$1089,$A12,Objects!$F$2:$F$1089,$B12,Objects!$H$2:$H$1089,$C12)/100 | K12: =COUNTIFS(Objects!$B$2:$B$1089,$A12,Objects!$F$2:$F$1089,$B12,Objects!$H$2:$H$1089,$C12,Objects!$I$2:$I$1089,"inferred*")
A13: 120 | B13: isolated_footing | C13: S1 | D13: =COUNTIFS(Objects!$B$2:$B$1089,$A13,Objects!$F$2:$F$1089,$B13,Objects!$H$2:$H$1089,$C13) | E13: =_xlfn.MINIFS(Objects!$K$2:$K$1089,Objects!$B$2:$B$1089,$A13,Objects!$F$2:$F$1089,$B13,Objects!$H$2:$H$1089,$C13) | F13: =_xlfn.MAXIFS(Objects!$K$2:$K$1089,Objects!$B$2:$B$1089,$A13,Objects!$F$2:$F$1089,$B13,Objects!$H$2:$H$1089,$C13) | G13: =_xlfn.MINIFS(Objects!$L$2:$L$1089,Objects!$B$2:$B$1089,$A13,Objects!$F$2:$F$1089,$B13,Objects!$H$2:$H$1089,$C13) | H13: =_xlfn.MAXIFS(Objects!$L$2:$L$1089,Objects!$B$2:$B$1089,$A13,Objects!$F$2:$F$1089,$B13,Objects!$H$2:$H$1089,$C13) | I13: =IF(OR(C13="(none)",B13="raft",B13="sump_pit"),"n/a",IF(OR(B13="column",B13="shear_wall",B13="isolated_footing",B13="combined_footing"),IF(AND(F13-E13<=3,H13-G13<=3),"yes","no"),IF(H13-G13<=3,"yes (thickness)","no (thickness)"))) | J13: =SUMIFS(Objects!$K$2:$K$1089,Objects!$B$2:$B$1089,$A13,Objects!$F$2:$F$1089,$B13,Objects!$H$2:$H$1089,$C13)/100 | K13: =COUNTIFS(Objects!$B$2:$B$1089,$A13,Objects!$F$2:$F$1089,$B13,Objects!$H$2:$H$1089,$C13,Objects!$I$2:$I$1089,"inferred*")
... A244: 130 | B244: sump_pit | C244: Fosse | D244: =COUNTIFS(Objects!$B$2:$B$1089,$A244,Objects!$F$2:$F$1089,$B244,Objects!$H$2:$H$1089,$C244) | E244: =_xlfn.MINIFS(Objects!$K$2:$K$1089,Objects!$B$2:$B$1089,$A244,Objects!$F$2:$F$1089,$B244,Objects!$H$2:$H$1089,$C244) | F244: =_xlfn.MAXIFS(Objects!$K$2:$K$1089,Objects!$B$2:$B$1089,$A244,Objects!$F$2:$F$1089,$B244,Objects!$H$2:$H$1089,$C244) | G244: =_xlfn.MINIFS(Objects!$L$2:$L$1089,Objects!$B$2:$B$1089,$A244,Objects!$F$2:$F$1089,$B244,Objects!$H$2:$H$1089,$C244) | H244: =_xlfn.MAXIFS(Objects!$L$2:$L$1089,Objects!$B$2:$B$1089,$A244,Objects!$F$2:$F$1089,$B244,Objects!$H$2:$H$1089,$C244) | I244: =IF(OR(C244="(none)",B244="raft",B244="sump_pit"),"n/a",IF(OR(B244="column",B244="shear_wall",B244="isolated_footing",B244="combined_footing"),IF(AND(F244-E244<=3,H244-G244<=3),"yes","no"),IF(H244-G244<=3,"yes (thickness)","no (thickness)"))) | J244: =SUMIFS(Objects!$K$2:$K$1089,Objects!$B$2:$B$1089,$A244,Objects!$F$2:$F$1089,$B244,Objects!$H$2:$H$1089,$C244)/100 | K244: =COUNTIFS(Objects!$B$2:$B$1089,$A244,Objects!$F$2:$F$1089,$B244,Objects!$H$2:$H$1089,$C244,Objects!$I$2:$I$1089,"inferred*")
A246: All | D246: =SUM(D2:D244)
A247: Unnamed clusters are not listed here (see 'Clusters'). 'Same section?' allows 3 cm; columns, shear walls and footings compare length and width, walls and bands of varying length compare thickness only.

Sheet Clusters
A1: Cluster | B1: Drawing kind | C1: Members | D1: Length min (cm) | E1: Length max (cm) | F1: Width min (cm) | G1: Width max (cm) | H1: Touch solids | I1: Inside an outline | J1: In a strip band | K1: On a stamped region | L1: Votes: column | M1: Votes: footing:S | N1: Votes: footing:SC | O1: Votes: grade_beam | P1: Votes: pit | Q1: Votes: raft | R1: Votes: retaining_wall+strip_footing | S1: Votes: strip_footing | T1: Votes: wall | U1: Votes total | V1: Top share | W1: Class | X1: Named by | Y1: Silhouette
A2: 0 | B2: band 0.11 m | C2: =COUNTIFS(Objects!$E$2:$E$1089,$A2) | D2: =_xlfn.MINIFS(Objects!$K$2:$K$1089,Objects!$E$2:$E$1089,$A2) | E2: =_xlfn.MAXIFS(Objects!$K$2:$K$1089,Objects!$E$2:$E$1089,$A2) | F2: =_xlfn.MINIFS(Objects!$L$2:$L$1089,Objects!$E$2:$E$1089,$A2) | G2: =_xlfn.MAXIFS(Objects!$L$2:$L$1089,Objects!$E$2:$E$1089,$A2) | H2: =IFERROR(COUNTIFS(Objects!$E$2:$E$1089,$A2,Objects!$P$2:$P$1089,">0")/$C2,0) | I2: =IFERROR(COUNTIFS(Objects!$E$2:$E$1089,$A2,Objects!$Q$2:$Q$1089,1)/$C2,0) | J2: =IFERROR(COUNTIFS(Objects!$E$2:$E$1089,$A2,Objects!$R$2:$R$1089,1)/$C2,0) | K2: =IFERROR(COUNTIFS(Objects!$E$2:$E$1089,$A2,Objects!$S$2:$S$1089,1)/$C2,0) | L2: 0 | M2: 0 | N2: 0 | O2: 0 | P2: 0 | Q2: 0 | R2: 0 | S2: 0 | T2: 0 | U2: =SUM(L2:T2) | V2: =IFERROR(MAX(L2:T2)/U2,0) | W2: unnamed | X2: no label votes
A3: 1 | B3: band 0.20 m | C3: =COUNTIFS(Objects!$E$2:$E$1089,$A3) | D3: =_xlfn.MINIFS(Objects!$K$2:$K$1089,Objects!$E$2:$E$1089,$A3) | E3: =_xlfn.MAXIFS(Objects!$K$2:$K$1089,Objects!$E$2:$E$1089,$A3) | F3: =_xlfn.MINIFS(Objects!$L$2:$L$1089,Objects!$E$2:$E$1089,$A3) | G3: =_xlfn.MAXIFS(Objects!$L$2:$L$1089,Objects!$E$2:$E$1089,$A3) | H3: =IFERROR(COUNTIFS(Objects!$E$2:$E$1089,$A3,Objects!$P$2:$P$1089,">0")/$C3,0) | I3: =IFERROR(COUNTIFS(Objects!$E$2:$E$1089,$A3,Objects!$Q$2:$Q$1089,1)/$C3,0) | J3: =IFERROR(COUNTIFS(Objects!$E$2:$E$1089,$A3,Objects!$R$2:$R$1089,1)/$C3,0) | K3: =IFERROR(COUNTIFS(Objects!$E$2:$E$1089,$A3,Objects!$S$2:$S$1089,1)/$C3,0) | L3: 0 | M3: 0 | N3: 0 | O3: 0 | P3: 0 | Q3: 0 | R3: 0 | S3: 0 | T3: 0 | U3: =SUM(L3:T3) | V3: =IFERROR(MAX(L3:T3)/U3,0) | W3: unnamed | X3: no label votes
A4: 2 | B4: band 0.26 m | C4: =COUNTIFS(Objects!$E$2:$E$1089,$A4) | D4: =_xlfn.MINIFS(Objects!$K$2:$K$1089,Objects!$E$2:$E$1089,$A4) | E4: =_xlfn.MAXIFS(Objects!$K$2:$K$1089,Objects!$E$2:$E$1089,$A4) | F4: =_xlfn.MINIFS(Objects!$L$2:$L$1089,Objects!$E$2:$E$1089,$A4) | G4: =_xlfn.MAXIFS(Objects!$L$2:$L$1089,Objects!$E$2:$E$1089,$A4) | H4: =IFERROR(COUNTIFS(Objects!$E$2:$E$1089,$A4,Objects!$P$2:$P$1089,">0")/$C4,0) | I4: =IFERROR(COUNTIFS(Objects!$E$2:$E$1089,$A4,Objects!$Q$2:$Q$1089,1)/$C4,0) | J4: =IFERROR(COUNTIFS(Objects!$E$2:$E$1089,$A4,Objects!$R$2:$R$1089,1)/$C4,0) | K4: =IFERROR(COUNTIFS(Objects!$E$2:$E$1089,$A4,Objects!$S$2:$S$1089,1)/$C4,0) | L4: 0 | M4: 0 | N4: 0 | O4: 7 | P4: 0 | Q4: 0 | R4: 0 | S4: 0 | T4: 1 | U4: =SUM(L4:T4) | V4: =IFERROR(MAX(L4:T4)/U4,0) | W4: grade_beam | X4: label vote
A5: 3 | B5: band 0.31 m | C5: =COUNTIFS(Objects!$E$2:$E$1089,$A5) | D5: =_xlfn.MINIFS(Objects!$K$2:$K$1089,Objects!$E$2:$E$1089,$A5) | E5: =_xlfn.MAXIFS(Objects!$K$2:$K$1089,Objects!$E$2:$E$1089,$A5) | F5: =_xlfn.MINIFS(Objects!$L$2:$L$1089,Objects!$E$2:$E$1089,$A5) | G5: =_xlfn.MAXIFS(Objects!$L$2:$L$1089,Objects!$E$2:$E$1089,$A5) | H5: =IFERROR(COUNTIFS(Objects!$E$2:$E$1089,$A5,Objects!$P$2:$P$1089,">0")/$C5,0) | I5: =IFERROR(COUNTIFS(Objects!$E$2:$E$1089,$A5,Objects!$Q$2:$Q$1089,1)/$C5,0) | J5: =IFERROR(COUNTIFS(Objects!$E$2:$E$1089,$A5,Objects!$R$2:$R$1089,1)/$C5,0) | K5: =IFERROR(COUNTIFS(Objects!$E$2:$E$1089,$A5,Objects!$S$2:$S$1089,1)/$C5,0) | L5: 0 | M5: 0 | N5: 0 | O5: 0 | P5: 0 | Q5: 0 | R5: 0 | S5: 0 | T5: 4 | U5: =SUM(L5:T5) | V5: =IFERROR(MAX(L5:T5)/U5,0) | W5: unnamed | X5: no label votes
A6: 4 | B6: band 0.41 m | C6: =COUNTIFS(Objects!$E$2:$E$1089,$A6) | D6: =_xlfn.MINIFS(Objects!$K$2:$K$1089,Objects!$E$2:$E$1089,$A6) | E6: =_xlfn.MAXIFS(Objects!$K$2:$K$1089,Objects!$E$2:$E$1089,$A6) | F6: =_xlfn.MINIFS(Objects!$L$2:$L$1089,Objects!$E$2:$E$1089,$A6) | G6: =_xlfn.MAXIFS(Objects!$L$2:$L$1089,Objects!$E$2:$E$1089,$A6) | H6: =IFERROR(COUNTIFS(Objects!$E$2:$E$1089,$A6,Objects!$P$2:$P$1089,">0")/$C6,0) | I6: =IFERROR(COUNTIFS(Objects!$E$2:$E$1089,$A6,Objects!$Q$2:$Q$1089,1)/$C6,0) | J6: =IFERROR(COUNTIFS(Objects!$E$2:$E$1089,$A6,Objects!$R$2:$R$1089,1)/$C6,0) | K6: =IFERROR(COUNTIFS(Objects!$E$2:$E$1089,$A6,Objects!$S$2:$S$1089,1)/$C6,0) | L6: 4 | M6: 5 | N6: 2 | O6: 184 | P6: 0 | Q6: 0 | R6: 0 | S6: 0 | T6: 45 | U6: =SUM(L6:T6) | V6: =IFERROR(MAX(L6:T6)/U6,0) | W6: grade_beam | X6: label vote
A7: 5 | B7: band 0.49 m | C7: =COUNTIFS(Objects!$E$2:$E$1089,$A7) | D7: =_xlfn.MINIFS(Objects!$K$2:$K$1089,Objects!$E$2:$E$1089,$A7) | E7: =_xlfn.MAXIFS(Objects!$K$2:$K$1089,Objects!$E$2:$E$1089,$A7) | F7: =_xlfn.MINIFS(Objects!$L$2:$L$1089,Objects!$E$2:$E$1089,$A7) | G7: =_xlfn.MAXIFS(Objects!$L$2:$L$1089,Objects!$E$2:$E$1089,$A7) | H7: =IFERROR(COUNTIFS(Objects!$E$2:$E$1089,$A7,Objects!$P$2:$P$1089,">0")/$C7,0) | I7: =IFERROR(COUNTIFS(Objects!$E$2:$E$1089,$A7,Objects!$Q$2:$Q$1089,1)/$C7,0) | J7: =IFERROR(COUNTIFS(Objects!$E$2:$E$1089,$A7,Objects!$R$2:$R$1089,1)/$C7,0) | K7: =IFERROR(COUNTIFS(Objects!$E$2:$E$1089,$A7,Objects!$S$2:$S$1089,1)/$C7,0) | L7: 0 | M7: 0 | N7: 1 | O7: 0 | P7: 0 | Q7: 0 | R7: 0 | S7: 0 | T7: 1 | U7: =SUM(L7:T7) | V7: =IFERROR(MAX(L7:T7)/U7,0) | W7: unnamed | X7: no label votes
A8: 6 | B8: band 0.80 m | C8: =COUNTIFS(Objects!$E$2:$E$1089,$A8) | D8: =_xlfn.MINIFS(Objects!$K$2:$K$1089,Objects!$E$2:$E$1089,$A8) | E8: =_xlfn.MAXIFS(Objects!$K$2:$K$1089,Objects!$E$2:$E$1089,$A8) | F8: =_xlfn.MINIFS(Objects!$L$2:$L$1089,Objects!$E$2:$E$1089,$A8) | G8: =_xlfn.MAXIFS(Objects!$L$2:$L$1089,Objects!$E$2:$E$1089,$A8) | H8: =IFERROR(COUNTIFS(Objects!$E$2:$E$1089,$A8,Objects!$P$2:$P$1089,">0")/$C8,0) | I8: =IFERROR(COUNTIFS(Objects!$E$2:$E$1089,$A8,Objects!$Q$2:$Q$1089,1)/$C8,0) | J8: =IFERROR(COUNTIFS(Objects!$E$2:$E$1089,$A8,Objects!$R$2:$R$1089,1)/$C8,0) | K8: =IFERROR(COUNTIFS(Objects!$E$2:$E$1089,$A8,Objects!$S$2:$S$1089,1)/$C8,0) | L8: 1 | M8: 1 | N8: 0 | O8: 0 | P8: 0 | Q8: 0 | R8: 0 | S8: 60 | T8: 2 | U8: =SUM(L8:T8) | V8: =IFERROR(MAX(L8:T8)/U8,0) | W8: strip_footing | X8: label vote
A9: 7 | B9: band 0.84 m | C9: =COUNTIFS(Objects!$E$2:$E$1089,$A9) | D9: =_xlfn.MINIFS(Objects!$K$2:$K$1089,Objects!$E$2:$E$1089,$A9) | E9: =_xlfn.MAXIFS(Objects!$K$2:$K$1089,Objects!$E$2:$E$1089,$A9) | F9: =_xlfn.MINIFS(Objects!$L$2:$L$1089,Objects!$E$2:$E$1089,$A9) | G9: =_xlfn.MAXIFS(Objects!$L$2:$L$1089,Objects!$E$2:$E$1089,$A9) | H9: =IFERROR(COUNTIFS(Objects!$E$2:$E$1089,$A9,Objects!$P$2:$P$1089,">0")/$C9,0) | I9: =IFERROR(COUNTIFS(Objects!$E$2:$E$1089,$A9,Objects!$Q$2:$Q$1089,1)/$C9,0) | J9: =IFERROR(COUNTIFS(Objects!$E$2:$E$1089,$A9,Objects!$R$2:$R$1089,1)/$C9,0) | K9: =IFERROR(COUNTIFS(Objects!$E$2:$E$1089,$A9,Objects!$S$2:$S$1089,1)/$C9,0) | L9: 0 | M9: 1 | N9: 0 | O9: 0 | P9: 0 | Q9: 0 | R9: 0 | S9: 0 | T9: 1 | U9: =SUM(L9:T9) | V9: =IFERROR(MAX(L9:T9)/U9,0) | W9: unnamed | X9: no label votes
A10: 8 | B10: band 0.94 m | C10: =COUNTIFS(Objects!$E$2:$E$1089,$A10) | D10: =_xlfn.MINIFS(Objects!$K$2:$K$1089,Objects!$E$2:$E$1089,$A10) | E10: =_xlfn.MAXIFS(Objects!$K$2:$K$1089,Objects!$E$2:$E$1089,$A10) | F10: =_xlfn.MINIFS(Objects!$L$2:$L$1089,Objects!$E$2:$E$1089,$A10) | G10: =_xlfn.MAXIFS(Objects!$L$2:$L$1089,Objects!$E$2:$E$1089,$A10) | H10: =IFERROR(COUNTIFS(Objects!$E$2:$E$1089,$A10,Objects!$P$2:$P$1089,">0")/$C10,0) | I10: =IFERROR(COUNTIFS(Objects!$E$2:$E$1089,$A10,Objects!$Q$2:$Q$1089,1)/$C10,0) | J10: =IFERROR(COUNTIFS(Objects!$E$2:$E$1089,$A10,Objects!$R$2:$R$1089,1)/$C10,0) | K10: =IFERROR(COUNTIFS(Objects!$E$2:$E$1089,$A10,Objects!$S$2:$S$1089,1)/$C10,0) | L10: 0 | M10: 1 | N10: 0 | O10: 0 | P10: 0 | Q10: 1 | R10: 0 | S10: 0 | T10: 2 | U10: =SUM(L10:T10) | V10: =IFERROR(MAX(L10:T10)/U10,0) | W10: unnamed | X10: no label votes
A11: 9 | B11: band 0.99 m | C11: =COUNTIFS(Objects!$E$2:$E$1089,$A11) | D11: =_xlfn.MINIFS(Objects!$K$2:$K$1089,Objects!$E$2:$E$1089,$A11) | E11: =_xlfn.MAXIFS(Objects!$K$2:$K$1089,Objects!$E$2:$E$1089,$A11) | F11: =_xlfn.MINIFS(Objects!$L$2:$L$1089,Objects!$E$2:$E$1089,$A11) | G11: =_xlfn.MAXIFS(Objects!$L$2:$L$1089,Objects!$E$2:$E$1089,$A11) | H11: =IFERROR(COUNTIFS(Objects!$E$2:$E$1089,$A11,Objects!$P$2:$P$1089,">0")/$C11,0) | I11: =IFERROR(COUNTIFS(Objects!$E$2:$E$1089,$A11,Objects!$Q$2:$Q$1089,1)/$C11,0) | J11: =IFERROR(COUNTIFS(Objects!$E$2:$E$1089,$A11,Objects!$R$2:$R$1089,1)/$C11,0) | K11: =IFERROR(COUNTIFS(Objects!$E$2:$E$1089,$A11,Objects!$S$2:$S$1089,1)/$C11,0) | L11: 0 | M11: 0 | N11: 0 | O11: 0 | P11: 0 | Q11: 1 | R11: 0 | S11: 0 | T11: 0 | U11: =SUM(L11:T11) | V11: =IFERROR(MAX(L11:T11)/U11,0) | W11: unnamed | X11: no label votes
A12: 10 | B12: band 1.21 m | C12: =COUNTIFS(Objects!$E$2:$E$1089,$A12) | D12: =_xlfn.MINIFS(Objects!$K$2:$K$1089,Objects!$E$2:$E$1089,$A12) | E12: =_xlfn.MAXIFS(Objects!$K$2:$K$1089,Objects!$E$2:$E$1089,$A12) | F12: =_xlfn.MINIFS(Objects!$L$2:$L$1089,Objects!$E$2:$E$1089,$A12) | G12: =_xlfn.MAXIFS(Objects!$L$2:$L$1089,Objects!$E$2:$E$1089,$A12) | H12: =IFERROR(COUNTIFS(Objects!$E$2:$E$1089,$A12,Objects!$P$2:$P$1089,">0")/$C12,0) | I12: =IFERROR(COUNTIFS(Objects!$E$2:$E$1089,$A12,Objects!$Q$2:$Q$1089,1)/$C12,0) | J12: =IFERROR(COUNTIFS(Objects!$E$2:$E$1089,$A12,Objects!$R$2:$R$1089,1)/$C12,0) | K12: =IFERROR(COUNTIFS(Objects!$E$2:$E$1089,$A12,Objects!$S$2:$S$1089,1)/$C12,0) | L12: 0 | M12: 0 | N12: 0 | O12: 0 | P12: 0 | Q12: 0 | R12: 0 | S12: 1 | T12: 1 | U12: =SUM(L12:T12) | V12: =IFERROR(MAX(L12:T12)/U12,0) | W12: unnamed | X12: no label votes
A13: 11 | B13: band 1.34 m | C13: =COUNTIFS(Objects!$E$2:$E$1089,$A13) | D13: =_xlfn.MINIFS(Objects!$K$2:$K$1089,Objects!$E$2:$E$1089,$A13) | E13: =_xlfn.MAXIFS(Objects!$K$2:$K$1089,Objects!$E$2:$E$1089,$A13) | F13: =_xlfn.MINIFS(Objects!$L$2:$L$1089,Objects!$E$2:$E$1089,$A13) | G13: =_xlfn.MAXIFS(Objects!$L$2:$L$1089,Objects!$E$2:$E$1089,$A13) | H13: =IFERROR(COUNTIFS(Objects!$E$2:$E$1089,$A13,Objects!$P$2:$P$1089,">0")/$C13,0) | I13: =IFERROR(COUNTIFS(Objects!$E$2:$E$1089,$A13,Objects!$Q$2:$Q$1089,1)/$C13,0) | J13: =IFERROR(COUNTIFS(Objects!$E$2:$E$1089,$A13,Objects!$R$2:$R$1089,1)/$C13,0) | K13: =IFERROR(COUNTIFS(Objects!$E$2:$E$1089,$A13,Objects!$S$2:$S$1089,1)/$C13,0) | L13: 1 | M13: 0 | N13: 0 | O13: 0 | P13: 0 | Q13: 0 | R13: 0 | S13: 0 | T13: 1 | U13: =SUM(L13:T13) | V13: =IFERROR(MAX(L13:T13)/U13,0) | W13: unnamed | X13: no label votes
... A16: 14 | B16: cross_hatch | C16: =COUNTIFS(Objects!$E$2:$E$1089,$A16) | D16: =_xlfn.MINIFS(Objects!$K$2:$K$1089,Objects!$E$2:$E$1089,$A16) | E16: =_xlfn.MAXIFS(Objects!$K$2:$K$1089,Objects!$E$2:$E$1089,$A16) | F16: =_xlfn.MINIFS(Objects!$L$2:$L$1089,Objects!$E$2:$E$1089,$A16) | G16: =_xlfn.MAXIFS(Objects!$L$2:$L$1089,Objects!$E$2:$E$1089,$A16) | H16: =IFERROR(COUNTIFS(Objects!$E$2:$E$1089,$A16,Objects!$P$2:$P$1089,">0")/$C16,0) | I16: =IFERROR(COUNTIFS(Objects!$E$2:$E$1089,$A16,Objects!$Q$2:$Q$1089,1)/$C16,0) | J16: =IFERROR(COUNTIFS(Objects!$E$2:$E$1089,$A16,Objects!$R$2:$R$1089,1)/$C16,0) | K16: =IFERROR(COUNTIFS(Objects!$E$2:$E$1089,$A16,Objects!$S$2:$S$1089,1)/$C16,0) | L16: 1 | M16: 0 | N16: 0 | O16: 0 | P16: 0 | Q16: 0 | R16: 0 | S16: 0 | T16: 0 | U16: =SUM(L16:T16) | V16: =IFERROR(MAX(L16:T16)/U16,0) | W16: unnamed | X16: no label votes
A17: 15 | B17: outline | C17: =COUNTIFS(Objects!$E$2:$E$1089,$A17) | D17: =_xlfn.MINIFS(Objects!$K$2:$K$1089,Objects!$E$2:$E$1089,$A17) | E17: =_xlfn.MAXIFS(Objects!$K$2:$K$1089,Objects!$E$2:$E$1089,$A17) | F17: =_xlfn.MINIFS(Objects!$L$2:$L$1089,Objects!$E$2:$E$1089,$A17) | G17: =_xlfn.MAXIFS(Objects!$L$2:$L$1089,Objects!$E$2:$E$1089,$A17) | H17: =IFERROR(COUNTIFS(Objects!$E$2:$E$1089,$A17,Objects!$P$2:$P$1089,">0")/$C17,0) | I17: =IFERROR(COUNTIFS(Objects!$E$2:$E$1089,$A17,Objects!$Q$2:$Q$1089,1)/$C17,0) | J17: =IFERROR(COUNTIFS(Objects!$E$2:$E$1089,$A17,Objects!$R$2:$R$1089,1)/$C17,0) | K17: =IFERROR(COUNTIFS(Objects!$E$2:$E$1089,$A17,Objects!$S$2:$S$1089,1)/$C17,0) | L17: 0 | M17: 1 | N17: 22 | O17: 1 | P17: 0 | Q17: 0 | R17: 0 | S17: 0 | T17: 0 | U17: =SUM(L17:T17) | V17: =IFERROR(MAX(L17:T17)/U17,0) | W17: combined_footing | X17: label vote | Y17: 0.634
A18: 16 | B18: outline | C18: =COUNTIFS(Objects!$E$2:$E$1089,$A18) | D18: =_xlfn.MINIFS(Objects!$K$2:$K$1089,Objects!$E$2:$E$1089,$A18) | E18: =_xlfn.MAXIFS(Objects!$K$2:$K$1089,Objects!$E$2:$E$1089,$A18) | F18: =_xlfn.MINIFS(Objects!$L$2:$L$1089,Objects!$E$2:$E$1089,$A18) | G18: =_xlfn.MAXIFS(Objects!$L$2:$L$1089,Objects!$E$2:$E$1089,$A18) | H18: =IFERROR(COUNTIFS(Objects!$E$2:$E$1089,$A18,Objects!$P$2:$P$1089,">0")/$C18,0) | I18: =IFERROR(COUNTIFS(Objects!$E$2:$E$1089,$A18,Objects!$Q$2:$Q$1089,1)/$C18,0) | J18: =IFERROR(COUNTIFS(Objects!$E$2:$E$1089,$A18,Objects!$R$2:$R$1089,1)/$C18,0) | K18: =IFERROR(COUNTIFS(Objects!$E$2:$E$1089,$A18,Objects!$S$2:$S$1089,1)/$C18,0) | L18: 0 | M18: 40 | N18: 0 | O18: 1 | P18: 0 | Q18: 0 | R18: 0 | S18: 0 | T18: 2 | U18: =SUM(L18:T18) | V18: =IFERROR(MAX(L18:T18)/U18,0) | W18: isolated_footing | X18: label vote | Y18: 0.634
A19: 17 | B19: outline | C19: =COUNTIFS(Objects!$E$2:$E$1089,$A19) | D19: =_xlfn.MINIFS(Objects!$K$2:$K$1089,Objects!$E$2:$E$1089,$A19) | E19: =_xlfn.MAXIFS(Objects!$K$2:$K$1089,Objects!$E$2:$E$1089,$A19) | F19: =_xlfn.MINIFS(Objects!$L$2:$L$1089,Objects!$E$2:$E$1089,$A19) | G19: =_xlfn.MAXIFS(Objects!$L$2:$L$1089,Objects!$E$2:$E$1089,$A19) | H19: =IFERROR(COUNTIFS(Objects!$E$2:$E$1089,$A19,Objects!$P$2:$P$1089,">0")/$C19,0) | I19: =IFERROR(COUNTIFS(Objects!$E$2:$E$1089,$A19,Objects!$Q$2:$Q$1089,1)/$C19,0) | J19: =IFERROR(COUNTIFS(Objects!$E$2:$E$1089,$A19,Objects!$R$2:$R$1089,1)/$C19,0) | K19: =IFERROR(COUNTIFS(Objects!$E$2:$E$1089,$A19,Objects!$S$2:$S$1089,1)/$C19,0) | L19: 1 | M19: 22 | N19: 0 | O19: 0 | P19: 0 | Q19: 0 | R19: 0 | S19: 0 | T19: 6 | U19: =SUM(L19:T19) | V19: =IFERROR(MAX(L19:T19)/U19,0) | W19: isolated_footing | X19: label vote | Y19: 0.634
A20: 18 | B20: outline | C20: =COUNTIFS(Objects!$E$2:$E$1089,$A20) | D20: =_xlfn.MINIFS(Objects!$K$2:$K$1089,Objects!$E$2:$E$1089,$A20) | E20: =_xlfn.MAXIFS(Objects!$K$2:$K$1089,Objects!$E$2:$E$1089,$A20) | F20: =_xlfn.MINIFS(Objects!$L$2:$L$1089,Objects!$E$2:$E$1089,$A20) | G20: =_xlfn.MAXIFS(Objects!$L$2:$L$1089,Objects!$E$2:$E$1089,$A20) | H20: =IFERROR(COUNTIFS(Objects!$E$2:$E$1089,$A20,Objects!$P$2:$P$1089,">0")/$C20,0) | I20: =IFERROR(COUNTIFS(Objects!$E$2:$E$1089,$A20,Objects!$Q$2:$Q$1089,1)/$C20,0) | J20: =IFERROR(COUNTIFS(Objects!$E$2:$E$1089,$A20,Objects!$R$2:$R$1089,1)/$C20,0) | K20: =IFERROR(COUNTIFS(Objects!$E$2:$E$1089,$A20,Objects!$S$2:$S$1089,1)/$C20,0) | L20: 0 | M20: 4 | N20: 0 | O20: 0 | P20: 2 | Q20: 2 | R20: 0 | S20: 0 | T20: 0 | U20: =SUM(L20:T20) | V20: =IFERROR(MAX(L20:T20)/U20,0) | W20: isolated_footing | X20: label vote | Y20: 0.634
A21: 19 | B21: outline | C21: =COUNTIFS(Objects!$E$2:$E$1089,$A21) | D21: =_xlfn.MINIFS(Objects!$K$2:$K$1089,Objects!$E$2:$E$1089,$A21) | E21: =_xlfn.MAXIFS(Objects!$K$2:$K$1089,Objects!$E$2:$E$1089,$A21) | F21: =_xlfn.MINIFS(Objects!$L$2:$L$1089,Objects!$E$2:$E$1089,$A21) | G21: =_xlfn.MAXIFS(Objects!$L$2:$L$1089,Objects!$E$2:$E$1089,$A21) | H21: =IFERROR(COUNTIFS(Objects!$E$2:$E$1089,$A21,Objects!$P$2:$P$1089,">0")/$C21,0) | I21: =IFERROR(COUNTIFS(Objects!$E$2:$E$1089,$A21,Objects!$Q$2:$Q$1089,1)/$C21,0) | J21: =IFERROR(COUNTIFS(Objects!$E$2:$E$1089,$A21,Objects!$R$2:$R$1089,1)/$C21,0) | K21: =IFERROR(COUNTIFS(Objects!$E$2:$E$1089,$A21,Objects!$S$2:$S$1089,1)/$C21,0) | L21: 0 | M21: 0 | N21: 0 | O21: 0 | P21: 0 | Q21: 0 | R21: 0 | S21: 0 | T21: 0 | U21: =SUM(L21:T21) | V21: =IFERROR(MAX(L21:T21)/U21,0) | W21: unnamed | X21: no label votes | Y21: 0.634
A22: 20 | B22: outline | C22: =COUNTIFS(Objects!$E$2:$E$1089,$A22) | D22: =_xlfn.MINIFS(Objects!$K$2:$K$1089,Objects!$E$2:$E$1089,$A22) | E22: =_xlfn.MAXIFS(Objects!$K$2:$K$1089,Objects!$E$2:$E$1089,$A22) | F22: =_xlfn.MINIFS(Objects!$L$2:$L$1089,Objects!$E$2:$E$1089,$A22) | G22: =_xlfn.MAXIFS(Objects!$L$2:$L$1089,Objects!$E$2:$E$1089,$A22) | H22: =IFERROR(COUNTIFS(Objects!$E$2:$E$1089,$A22,Objects!$P$2:$P$1089,">0")/$C22,0) | I22: =IFERROR(COUNTIFS(Objects!$E$2:$E$1089,$A22,Objects!$Q$2:$Q$1089,1)/$C22,0) | J22: =IFERROR(COUNTIFS(Objects!$E$2:$E$1089,$A22,Objects!$R$2:$R$1089,1)/$C22,0) | K22: =IFERROR(COUNTIFS(Objects!$E$2:$E$1089,$A22,Objects!$S$2:$S$1089,1)/$C22,0) | L22: 0 | M22: 0 | N22: 0 | O22: 0 | P22: 2 | Q22: 0 | R22: 0 | S22: 1 | T22: 0 | U22: =SUM(L22:T22) | V22: =IFERROR(MAX(L22:T22)/U22,0) | W22: sump_pit | X22: label vote | Y22: 0.634
A23: 21 | B23: outline | C23: =COUNTIFS(Objects!$E$2:$E$1089,$A23) | D23: =_xlfn.MINIFS(Objects!$K$2:$K$1089,Objects!$E$2:$E$1089,$A23) | E23: =_xlfn.MAXIFS(Objects!$K$2:$K$1089,Objects!$E$2:$E$1089,$A23) | F23: =_xlfn.MINIFS(Objects!$L$2:$L$1089,Objects!$E$2:$E$1089,$A23) | G23: =_xlfn.MAXIFS(Objects!$L$2:$L$1089,Objects!$E$2:$E$1089,$A23) | H23: =IFERROR(COUNTIFS(Objects!$E$2:$E$1089,$A23,Objects!$P$2:$P$1089,">0")/$C23,0) | I23: =IFERROR(COUNTIFS(Objects!$E$2:$E$1089,$A23,Objects!$Q$2:$Q$1089,1)/$C23,0) | J23: =IFERROR(COUNTIFS(Objects!$E$2:$E$1089,$A23,Objects!$R$2:$R$1089,1)/$C23,0) | K23: =IFERROR(COUNTIFS(Objects!$E$2:$E$1089,$A23,Objects!$S$2:$S$1089,1)/$C23,0) | L23: 0 | M23: 0 | N23: 0 | O23: 0 | P23: 0 | Q23: 0 | R23: 0 | S23: 0 | T23: 0 | U23: =SUM(L23:T23) | V23: =IFERROR(MAX(L23:T23)/U23,0) | W23: unnamed | X23: no label votes | Y23: 0.634
A24: 22 | B24: outline | C24: =COUNTIFS(Objects!$E$2:$E$1089,$A24) | D24: =_xlfn.MINIFS(Objects!$K$2:$K$1089,Objects!$E$2:$E$1089,$A24) | E24: =_xlfn.MAXIFS(Objects!$K$2:$K$1089,Objects!$E$2:$E$1089,$A24) | F24: =_xlfn.MINIFS(Objects!$L$2:$L$1089,Objects!$E$2:$E$1089,$A24) | G24: =_xlfn.MAXIFS(Objects!$L$2:$L$1089,Objects!$E$2:$E$1089,$A24) | H24: =IFERROR(COUNTIFS(Objects!$E$2:$E$1089,$A24,Objects!$P$2:$P$1089,">0")/$C24,0) | I24: =IFERROR(COUNTIFS(Objects!$E$2:$E$1089,$A24,Objects!$Q$2:$Q$1089,1)/$C24,0) | J24: =IFERROR(COUNTIFS(Objects!$E$2:$E$1089,$A24,Objects!$R$2:$R$1089,1)/$C24,0) | K24: =IFERROR(COUNTIFS(Objects!$E$2:$E$1089,$A24,Objects!$S$2:$S$1089,1)/$C24,0) | L24: 0 | M24: 0 | N24: 0 | O24: 0 | P24: 0 | Q24: 0 | R24: 0 | S24: 0 | T24: 0 | U24: =SUM(L24:T24) | V24: =IFERROR(MAX(L24:T24)/U24,0) | W24: unnamed | X24: no label votes | Y24: 0.634
A25: 23 | B25: outline | C25: =COUNTIFS(Objects!$E$2:$E$1089,$A25) | D25: =_xlfn.MINIFS(Objects!$K$2:$K$1089,Objects!$E$2:$E$1089,$A25) | E25: =_xlfn.MAXIFS(Objects!$K$2:$K$1089,Objects!$E$2:$E$1089,$A25) | F25: =_xlfn.MINIFS(Objects!$L$2:$L$1089,Objects!$E$2:$E$1089,$A25) | G25: =_xlfn.MAXIFS(Objects!$L$2:$L$1089,Objects!$E$2:$E$1089,$A25) | H25: =IFERROR(COUNTIFS(Objects!$E$2:$E$1089,$A25,Objects!$P$2:$P$1089,">0")/$C25,0) | I25: =IFERROR(COUNTIFS(Objects!$E$2:$E$1089,$A25,Objects!$Q$2:$Q$1089,1)/$C25,0) | J25: =IFERROR(COUNTIFS(Objects!$E$2:$E$1089,$A25,Objects!$R$2:$R$1089,1)/$C25,0) | K25: =IFERROR(COUNTIFS(Objects!$E$2:$E$1089,$A25,Objects!$S$2:$S$1089,1)/$C25,0) | L25: 0 | M25: 0 | N25: 3 | O25: 0 | P25: 0 | Q25: 0 | R25: 0 | S25: 0 | T25: 3 | U25: =SUM(L25:T25) | V25: =IFERROR(MAX(L25:T25)/U25,0) | W25: combined_footing | X25: similar to cluster 15 (distance 0.87) | Y25: 0.634
A26: 24 | B26: outline | C26: =COUNTIFS(Objects!$E$2:$E$1089,$A26) | D26: =_xlfn.MINIFS(Objects!$K$2:$K$1089,Objects!$E$2:$E$1089,$A26) | E26: =_xlfn.MAXIFS(Objects!$K$2:$K$1089,Objects!$E$2:$E$1089,$A26) | F26: =_xlfn.MINIFS(Objects!$L$2:$L$1089,Objects!$E$2:$E$1089,$A26) | G26: =_xlfn.MAXIFS(Objects!$L$2:$L$1089,Objects!$E$2:$E$1089,$A26) | H26: =IFERROR(COUNTIFS(Objects!$E$2:$E$1089,$A26,Objects!$P$2:$P$1089,">0")/$C26,0) | I26: =IFERROR(COUNTIFS(Objects!$E$2:$E$1089,$A26,Objects!$Q$2:$Q$1089,1)/$C26,0) | J26: =IFERROR(COUNTIFS(Objects!$E$2:$E$1089,$A26,Objects!$R$2:$R$1089,1)/$C26,0) | K26: =IFERROR(COUNTIFS(Objects!$E$2:$E$1089,$A26,Objects!$S$2:$S$1089,1)/$C26,0) | L26: 0 | M26: 0 | N26: 0 | O26: 1 | P26: 0 | Q26: 0 | R26: 0 | S26: 0 | T26: 0 | U26: =SUM(L26:T26) | V26: =IFERROR(MAX(L26:T26)/U26,0) | W26: unnamed | X26: no label votes | Y26: 0.634
A27: 25 | B27: outline | C27: =COUNTIFS(Objects!$E$2:$E$1089,$A27) | D27: =_xlfn.MINIFS(Objects!$K$2:$K$1089,Objects!$E$2:$E$1089,$A27) | E27: =_xlfn.MAXIFS(Objects!$K$2:$K$1089,Objects!$E$2:$E$1089,$A27) | F27: =_xlfn.MINIFS(Objects!$L$2:$L$1089,Objects!$E$2:$E$1089,$A27) | G27: =_xlfn.MAXIFS(Objects!$L$2:$L$1089,Objects!$E$2:$E$1089,$A27) | H27: =IFERROR(COUNTIFS(Objects!$E$2:$E$1089,$A27,Objects!$P$2:$P$1089,">0")/$C27,0) | I27: =IFERROR(COUNTIFS(Objects!$E$2:$E$1089,$A27,Objects!$Q$2:$Q$1089,1)/$C27,0) | J27: =IFERROR(COUNTIFS(Objects!$E$2:$E$1089,$A27,Objects!$R$2:$R$1089,1)/$C27,0) | K27: =IFERROR(COUNTIFS(Objects!$E$2:$E$1089,$A27,Objects!$S$2:$S$1089,1)/$C27,0) | L27: 0 | M27: 0 | N27: 0 | O27: 1 | P27: 0 | Q27: 0 | R27: 0 | S27: 0 | T27: 0 | U27: =SUM(L27:T27) | V27: =IFERROR(MAX(L27:T27)/U27,0) | W27: isolated_footing | X27: similar to cluster 16 (distance 1.19) | Y27: 0.634
A28: 26 | B28: outline | C28: =COUNTIFS(Objects!$E$2:$E$1089,$A28) | D28: =_xlfn.MINIFS(Objects!$K$2:$K$1089,Objects!$E$2:$E$1089,$A28) | E28: =_xlfn.MAXIFS(Objects!$K$2:$K$1089,Objects!$E$2:$E$1089,$A28) | F28: =_xlfn.MINIFS(Objects!$L$2:$L$1089,Objects!$E$2:$E$1089,$A28) | G28: =_xlfn.MAXIFS(Objects!$L$2:$L$1089,Objects!$E$2:$E$1089,$A28) | H28: =IFERROR(COUNTIFS(Objects!$E$2:$E$1089,$A28,Objects!$P$2:$P$1089,">0")/$C28,0) | I28: =IFERROR(COUNTIFS(Objects!$E$2:$E$1089,$A28,Objects!$Q$2:$Q$1089,1)/$C28,0) | J28: =IFERROR(COUNTIFS(Objects!$E$2:$E$1089,$A28,Objects!$R$2:$R$1089,1)/$C28,0) | K28: =IFERROR(COUNTIFS(Objects!$E$2:$E$1089,$A28,Objects!$S$2:$S$1089,1)/$C28,0) | L28: 0 | M28: 1 | N28: 0 | O28: 1 | P28: 0 | Q28: 0 | R28: 0 | S28: 0 | T28: 0 | U28: =SUM(L28:T28) | V28: =IFERROR(MAX(L28:T28)/U28,0) | W28: isolated_footing | X28: similar to cluster 18 (distance 1.25) | Y28: 0.634
A29: 27 | B29: single_hatch | C29: =COUNTIFS(Objects!$E$2:$E$1089,$A29) | D29: =_xlfn.MINIFS(Objects!$K$2:$K$1089,Objects!$E$2:$E$1089,$A29) | E29: =_xlfn.MAXIFS(Objects!$K$2:$K$1089,Objects!$E$2:$E$1089,$A29) | F29: =_xlfn.MINIFS(Objects!$L$2:$L$1089,Objects!$E$2:$E$1089,$A29) | G29: =_xlfn.MAXIFS(Objects!$L$2:$L$1089,Objects!$E$2:$E$1089,$A29) | H29: =IFERROR(COUNTIFS(Objects!$E$2:$E$1089,$A29,Objects!$P$2:$P$1089,">0")/$C29,0) | I29: =IFERROR(COUNTIFS(Objects!$E$2:$E$1089,$A29,Objects!$Q$2:$Q$1089,1)/$C29,0) | J29: =IFERROR(COUNTIFS(Objects!$E$2:$E$1089,$A29,Objects!$R$2:$R$1089,1)/$C29,0) | K29: =IFERROR(COUNTIFS(Objects!$E$2:$E$1089,$A29,Objects!$S$2:$S$1089,1)/$C29,0) | L29: 0 | M29: 0 | N29: 0 | O29: 0 | P29: 0 | Q29: 0 | R29: 0 | S29: 0 | T29: 0 | U29: =SUM(L29:T29) | V29: =IFERROR(MAX(L29:T29)/U29,0) | W29: unnamed | X29: no label votes
A30: 28 | B30: solid | C30: =COUNTIFS(Objects!$E$2:$E$1089,$A30) | D30: =_xlfn.MINIFS(Objects!$K$2:$K$1089,Objects!$E$2:$E$1089,$A30) | E30: =_xlfn.MAXIFS(Objects!$K$2:$K$1089,Objects!$E$2:$E$1089,$A30) | F30: =_xlfn.MINIFS(Objects!$L$2:$L$1089,Objects!$E$2:$E$1089,$A30) | G30: =_xlfn.MAXIFS(Objects!$L$2:$L$1089,Objects!$E$2:$E$1089,$A30) | H30: =IFERROR(COUNTIFS(Objects!$E$2:$E$1089,$A30,Objects!$P$2:$P$1089,">0")/$C30,0) | I30: =IFERROR(COUNTIFS(Objects!$E$2:$E$1089,$A30,Objects!$Q$2:$Q$1089,1)/$C30,0) | J30: =IFERROR(COUNTIFS(Objects!$E$2:$E$1089,$A30,Objects!$R$2:$R$1089,1)/$C30,0) | K30: =IFERROR(COUNTIFS(Objects!$E$2:$E$1089,$A30,Objects!$S$2:$S$1089,1)/$C30,0) | L30: 1 | M30: 0 | N30: 0 | O30: 0 | P30: 0 | Q30: 1 | R30: 0 | S30: 1 | T30: 4 | U30: =SUM(L30:T30) | V30: =IFERROR(MAX(L30:T30)/U30,0) | W30: retaining_wall | X30: label vote | Y30: 0.433
A31: 29 | B31: solid | C31: =COUNTIFS(Objects!$E$2:$E$1089,$A31) | D31: =_xlfn.MINIFS(Objects!$K$2:$K$1089,Objects!$E$2:$E$1089,$A31) | E31: =_xlfn.MAXIFS(Objects!$K$2:$K$1089,Objects!$E$2:$E$1089,$A31) | F31: =_xlfn.MINIFS(Objects!$L$2:$L$1089,Objects!$E$2:$E$1089,$A31) | G31: =_xlfn.MAXIFS(Objects!$L$2:$L$1089,Objects!$E$2:$E$1089,$A31) | H31: =IFERROR(COUNTIFS(Objects!$E$2:$E$1089,$A31,Objects!$P$2:$P$1089,">0")/$C31,0) | I31: =IFERROR(COUNTIFS(Objects!$E$2:$E$1089,$A31,Objects!$Q$2:$Q$1089,1)/$C31,0) | J31: =IFERROR(COUNTIFS(Objects!$E$2:$E$1089,$A31,Objects!$R$2:$R$1089,1)/$C31,0) | K31: =IFERROR(COUNTIFS(Objects!$E$2:$E$1089,$A31,Objects!$S$2:$S$1089,1)/$C31,0) | L31: 10 | M31: 0 | N31: 0 | O31: 1 | P31: 0 | Q31: 0 | R31: 0 | S31: 0 | T31: 1 | U31: =SUM(L31:T31) | V31: =IFERROR(MAX(L31:T31)/U31,0) | W31: column | X31: label vote | Y31: 0.433
A32: 30 | B32: solid | C32: =COUNTIFS(Objects!$E$2:$E$1089,$A32) | D32: =_xlfn.MINIFS(Objects!$K$2:$K$1089,Objects!$E$2:$E$1089,$A32) | E32: =_xlfn.MAXIFS(Objects!$K$2:$K$1089,Objects!$E$2:$E$1089,$A32) | F32: =_xlfn.MINIFS(Objects!$L$2:$L$1089,Objects!$E$2:$E$1089,$A32) | G32: =_xlfn.MAXIFS(Objects!$L$2:$L$1089,Objects!$E$2:$E$1089,$A32) | H32: =IFERROR(COUNTIFS(Objects!$E$2:$E$1089,$A32,Objects!$P$2:$P$1089,">0")/$C32,0) | I32: =IFERROR(COUNTIFS(Objects!$E$2:$E$1089,$A32,Objects!$Q$2:$Q$1089,1)/$C32,0) | J32: =IFERROR(COUNTIFS(Objects!$E$2:$E$1089,$A32,Objects!$R$2:$R$1089,1)/$C32,0) | K32: =IFERROR(COUNTIFS(Objects!$E$2:$E$1089,$A32,Objects!$S$2:$S$1089,1)/$C32,0) | L32: 0 | M32: 0 | N32: 0 | O32: 0 | P32: 0 | Q32: 0 | R32: 0 | S32: 0 | T32: 5 | U32: =SUM(L32:T32) | V32: =IFERROR(MAX(L32:T32)/U32,0) | W32: shear_wall | X32: label vote | Y32: 0.433
A33: 31 | B33: solid | C33: =COUNTIFS(Objects!$E$2:$E$1089,$A33) | D33: =_xlfn.MINIFS(Objects!$K$2:$K$1089,Objects!$E$2:$E$1089,$A33) | E33: =_xlfn.MAXIFS(Objects!$K$2:$K$1089,Objects!$E$2:$E$1089,$A33) | F33: =_xlfn.MINIFS(Objects!$L$2:$L$1089,Objects!$E$2:$E$1089,$A33) | G33: =_xlfn.MAXIFS(Objects!$L$2:$L$1089,Objects!$E$2:$E$1089,$A33) | H33: =IFERROR(COUNTIFS(Objects!$E$2:$E$1089,$A33,Objects!$P$2:$P$1089,">0")/$C33,0) | I33: =IFERROR(COUNTIFS(Objects!$E$2:$E$1089,$A33,Objects!$Q$2:$Q$1089,1)/$C33,0) | J33: =IFERROR(COUNTIFS(Objects!$E$2:$E$1089,$A33,Objects!$R$2:$R$1089,1)/$C33,0) | K33: =IFERROR(COUNTIFS(Objects!$E$2:$E$1089,$A33,Objects!$S$2:$S$1089,1)/$C33,0) | L33: 14 | M33: 1 | N33: 0 | O33: 0 | P33: 0 | Q33: 0 | R33: 0 | S33: 0 | T33: 0 | U33: =SUM(L33:T33) | V33: =IFERROR(MAX(L33:T33)/U33,0) | W33: column | X33: label vote | Y33: 0.433
A34: 32 | B34: solid | C34: =COUNTIFS(Objects!$E$2:$E$1089,$A34) | D34: =_xlfn.MINIFS(Objects!$K$2:$K$1089,Objects!$E$2:$E$1089,$A34) | E34: =_xlfn.MAXIFS(Objects!$K$2:$K$1089,Objects!$E$2:$E$1089,$A34) | F34: =_xlfn.MINIFS(Objects!$L$2:$L$1089,Objects!$E$2:$E$1089,$A34) | G34: =_xlfn.MAXIFS(Objects!$L$2:$L$1089,Objects!$E$2:$E$1089,$A34) | H34: =IFERROR(COUNTIFS(Objects!$E$2:$E$1089,$A34,Objects!$P$2:$P$1089,">0")/$C34,0) | I34: =IFERROR(COUNTIFS(Objects!$E$2:$E$1089,$A34,Objects!$Q$2:$Q$1089,1)/$C34,0) | J34: =IFERROR(COUNTIFS(Objects!$E$2:$E$1089,$A34,Objects!$R$2:$R$1089,1)/$C34,0) | K34: =IFERROR(COUNTIFS(Objects!$E$2:$E$1089,$A34,Objects!$S$2:$S$1089,1)/$C34,0) | L34: 0 | M34: 1 | N34: 0 | O34: 0 | P34: 0 | Q34: 0 | R34: 0 | S34: 0 | T34: 11 | U34: =SUM(L34:T34) | V34: =IFERROR(MAX(L34:T34)/U34,0) | W34: shear_wall | X34: label vote | Y34: 0.433
A35: 33 | B35: solid | C35: =COUNTIFS(Objects!$E$2:$E$1089,$A35) | D35: =_xlfn.MINIFS(Objects!$K$2:$K$1089,Objects!$E$2:$E$1089,$A35) | E35: =_xlfn.MAXIFS(Objects!$K$2:$K$1089,Objects!$E$2:$E$1089,$A35) | F35: =_xlfn.MINIFS(Objects!$L$2:$L$1089,Objects!$E$2:$E$1089,$A35) | G35: =_xlfn.MAXIFS(Objects!$L$2:$L$1089,Objects!$E$2:$E$1089,$A35) | H35: =IFERROR(COUNTIFS(Objects!$E$2:$E$1089,$A35,Objects!$P$2:$P$1089,">0")/$C35,0) | I35: =IFERROR(COUNTIFS(Objects!$E$2:$E$1089,$A35,Objects!$Q$2:$Q$1089,1)/$C35,0) | J35: =IFERROR(COUNTIFS(Objects!$E$2:$E$1089,$A35,Objects!$R$2:$R$1089,1)/$C35,0) | K35: =IFERROR(COUNTIFS(Objects!$E$2:$E$1089,$A35,Objects!$S$2:$S$1089,1)/$C35,0) | L35: 0 | M35: 0 | N35: 0 | O35: 0 | P35: 0 | Q35: 0 | R35: 0 | S35: 0 | T35: 0 | U35: =SUM(L35:T35) | V35: =IFERROR(MAX(L35:T35)/U35,0) | W35: retaining_wall | X35: label vote | Y35: 0.433
A36: 34 | B36: solid | C36: =COUNTIFS(Objects!$E$2:$E$1089,$A36) | D36: =_xlfn.MINIFS(Objects!$K$2:$K$1089,Objects!$E$2:$E$1089,$A36) | E36: =_xlfn.MAXIFS(Objects!$K$2:$K$1089,Objects!$E$2:$E$1089,$A36) | F36: =_xlfn.MINIFS(Objects!$L$2:$L$1089,Objects!$E$2:$E$1089,$A36) | G36: =_xlfn.MAXIFS(Objects!$L$2:$L$1089,Objects!$E$2:$E$1089,$A36) | H36: =IFERROR(COUNTIFS(Objects!$E$2:$E$1089,$A36,Objects!$P$2:$P$1089,">0")/$C36,0) | I36: =IFERROR(COUNTIFS(Objects!$E$2:$E$1089,$A36,Objects!$Q$2:$Q$1089,1)/$C36,0) | J36: =IFERROR(COUNTIFS(Objects!$E$2:$E$1089,$A36,Objects!$R$2:$R$1089,1)/$C36,0) | K36: =IFERROR(COUNTIFS(Objects!$E$2:$E$1089,$A36,Objects!$S$2:$S$1089,1)/$C36,0) | L36: 0 | M36: 0 | N36: 0 | O36: 0 | P36: 0 | Q36: 1 | R36: 0 | S36: 0 | T36: 1 | U36: =SUM(L36:T36) | V36: =IFERROR(MAX(L36:T36)/U36,0) | W36: unnamed | X36: no label votes | Y36: 0.433
A37: 35 | B37: solid | C37: =COUNTIFS(Objects!$E$2:$E$1089,$A37) | D37: =_xlfn.MINIFS(Objects!$K$2:$K$1089,Objects!$E$2:$E$1089,$A37) | E37: =_xlfn.MAXIFS(Objects!$K$2:$K$1089,Objects!$E$2:$E$1089,$A37) | F37: =_xlfn.MINIFS(Objects!$L$2:$L$1089,Objects!$E$2:$E$1089,$A37) | G37: =_xlfn.MAXIFS(Objects!$L$2:$L$1089,Objects!$E$2:$E$1089,$A37) | H37: =IFERROR(COUNTIFS(Objects!$E$2:$E$1089,$A37,Objects!$P$2:$P$1089,">0")/$C37,0) | I37: =IFERROR(COUNTIFS(Objects!$E$2:$E$1089,$A37,Objects!$Q$2:$Q$1089,1)/$C37,0) | J37: =IFERROR(COUNTIFS(Objects!$E$2:$E$1089,$A37,Objects!$R$2:$R$1089,1)/$C37,0) | K37: =IFERROR(COUNTIFS(Objects!$E$2:$E$1089,$A37,Objects!$S$2:$S$1089,1)/$C37,0) | L37: 0 | M37: 0 | N37: 0 | O37: 0 | P37: 0 | Q37: 0 | R37: 0 | S37: 0 | T37: 11 | U37: =SUM(L37:T37) | V37: =IFERROR(MAX(L37:T37)/U37,0) | W37: shear_wall | X37: label vote | Y37: 0.433
A38: 36 | B38: solid | C38: =COUNTIFS(Objects!$E$2:$E$1089,$A38) | D38: =_xlfn.MINIFS(Objects!$K$2:$K$1089,Objects!$E$2:$E$1089,$A38) | E38: =_xlfn.MAXIFS(Objects!$K$2:$K$1089,Objects!$E$2:$E$1089,$A38) | F38: =_xlfn.MINIFS(Objects!$L$2:$L$1089,Objects!$E$2:$E$1089,$A38) | G38: =_xlfn.MAXIFS(Objects!$L$2:$L$1089,Objects!$E$2:$E$1089,$A38) | H38: =IFERROR(COUNTIFS(Objects!$E$2:$E$1089,$A38,Objects!$P$2:$P$1089,">0")/$C38,0) | I38: =IFERROR(COUNTIFS(Objects!$E$2:$E$1089,$A38,Objects!$Q$2:$Q$1089,1)/$C38,0) | J38: =IFERROR(COUNTIFS(Objects!$E$2:$E$1089,$A38,Objects!$R$2:$R$1089,1)/$C38,0) | K38: =IFERROR(COUNTIFS(Objects!$E$2:$E$1089,$A38,Objects!$S$2:$S$1089,1)/$C38,0) | L38: 0 | M38: 0 | N38: 0 | O38: 0 | P38: 0 | Q38: 0 | R38: 0 | S38: 0 | T38: 21 | U38: =SUM(L38:T38) | V38: =IFERROR(MAX(L38:T38)/U38,0) | W38: shear_wall | X38: label vote | Y38: 0.433
A39: 37 | B39: solid | C39: =COUNTIFS(Objects!$E$2:$E$1089,$A39) | D39: =_xlfn.MINIFS(Objects!$K$2:$K$1089,Objects!$E$2:$E$1089,$A39) | E39: =_xlfn.MAXIFS(Objects!$K$2:$K$1089,Objects!$E$2:$E$1089,$A39) | F39: =_xlfn.MINIFS(Objects!$L$2:$L$1089,Objects!$E$2:$E$1089,$A39) | G39: =_xlfn.MAXIFS(Objects!$L$2:$L$1089,Objects!$E$2:$E$1089,$A39) | H39: =IFERROR(COUNTIFS(Objects!$E$2:$E$1089,$A39,Objects!$P$2:$P$1089,">0")/$C39,0) | I39: =IFERROR(COUNTIFS(Objects!$E$2:$E$1089,$A39,Objects!$Q$2:$Q$1089,1)/$C39,0) | J39: =IFERROR(COUNTIFS(Objects!$E$2:$E$1089,$A39,Objects!$R$2:$R$1089,1)/$C39,0) | K39: =IFERROR(COUNTIFS(Objects!$E$2:$E$1089,$A39,Objects!$S$2:$S$1089,1)/$C39,0) | L39: 0 | M39: 0 | N39: 0 | O39: 0 | P39: 0 | Q39: 0 | R39: 0 | S39: 0 | T39: 14 | U39: =SUM(L39:T39) | V39: =IFERROR(MAX(L39:T39)/U39,0) | W39: shear_wall | X39: label vote | Y39: 0.433
A40: 38 | B40: solid | C40: =COUNTIFS(Objects!$E$2:$E$1089,$A40) | D40: =_xlfn.MINIFS(Objects!$K$2:$K$1089,Objects!$E$2:$E$1089,$A40) | E40: =_xlfn.MAXIFS(Objects!$K$2:$K$1089,Objects!$E$2:$E$1089,$A40) | F40: =_xlfn.MINIFS(Objects!$L$2:$L$1089,Objects!$E$2:$E$1089,$A40) | G40: =_xlfn.MAXIFS(Objects!$L$2:$L$1089,Objects!$E$2:$E$1089,$A40) | H40: =IFERROR(COUNTIFS(Objects!$E$2:$E$1089,$A40,Objects!$P$2:$P$1089,">0")/$C40,0) | I40: =IFERROR(COUNTIFS(Objects!$E$2:$E$1089,$A40,Objects!$Q$2:$Q$1089,1)/$C40,0) | J40: =IFERROR(COUNTIFS(Objects!$E$2:$E$1089,$A40,Objects!$R$2:$R$1089,1)/$C40,0) | K40: =IFERROR(COUNTIFS(Objects!$E$2:$E$1089,$A40,Objects!$S$2:$S$1089,1)/$C40,0) | L40: 0 | M40: 0 | N40: 0 | O40: 0 | P40: 1 | Q40: 0 | R40: 0 | S40: 0 | T40: 0 | U40: =SUM(L40:T40) | V40: =IFERROR(MAX(L40:T40)/U40,0) | W40: unnamed | X40: no label votes | Y40: 0.433
A41: 39 | B41: stamped_region | C41: =COUNTIFS(Objects!$E$2:$E$1089,$A41) | D41: =_xlfn.MINIFS(Objects!$K$2:$K$1089,Objects!$E$2:$E$1089,$A41) | E41: =_xlfn.MAXIFS(Objects!$K$2:$K$1089,Objects!$E$2:$E$1089,$A41) | F41: =_xlfn.MINIFS(Objects!$L$2:$L$1089,Objects!$E$2:$E$1089,$A41) | G41: =_xlfn.MAXIFS(Objects!$L$2:$L$1089,Objects!$E$2:$E$1089,$A41) | H41: =IFERROR(COUNTIFS(Objects!$E$2:$E$1089,$A41,Objects!$P$2:$P$1089,">0")/$C41,0) | I41: =IFERROR(COUNTIFS(Objects!$E$2:$E$1089,$A41,Objects!$Q$2:$Q$1089,1)/$C41,0) | J41: =IFERROR(COUNTIFS(Objects!$E$2:$E$1089,$A41,Objects!$R$2:$R$1089,1)/$C41,0) | K41: =IFERROR(COUNTIFS(Objects!$E$2:$E$1089,$A41,Objects!$S$2:$S$1089,1)/$C41,0) | L41: 0 | M41: 0 | N41: 0 | O41: 0 | P41: 0 | Q41: 13 | R41: 0 | S41: 0 | T41: 0 | U41: =SUM(L41:T41) | V41: =IFERROR(MAX(L41:T41)/U41,0) | W41: raft | X41: label vote
A43: Votes are the first, neutral pass (program output). A 'VP..-SF..' label votes for the strip it sits on and for the wall standing in that strip.

Sheet Objects
A1: ID | B1: Building | C1: Building from | D1: Drawing kind | E1: Cluster | F1: Class | G1: Class named by | H1: Type key | I1: Type source | J1: Label text | K1: Length (cm) | L1: Width (cm) | M1: L/W | N1: Area (m²) | O1: Angle (°) | P1: Touches solids | Q1: Inside an outline | R1: In a strip band | S1: On a stamped region | T1: Solids inside | U1: Dots inside | V1: Beams touching | W1: Net length (m) | X1: Extent | Y1: bbox x0 (px) | Z1: bbox y0 (px) | AA1: bbox x1 (px) | AB1: bbox y1 (px) | AC1: (validation) verified class | AD1: (validation) agrees
A2: 1 | B2: 120 | C2: nearest labels in its region | D2: solid | E2: 31 | F2: column | G2: label vote | H2: (none) | I2: no column type in its building has this size | K2: 47 | L2: 26 | M2: =IF(AND(ISNUMBER(K2),L2>0),K2/L2,"") | N2: 0.122 | O2: 89.9 | P2: 1 | Q2: 0 | R2: 0 | S2: 1 | T2: 0 | U2: 0 | V2: 0 | Y2: 4870.7 | Z2: 760.3 | AA2: 4878.3 | AB2: 774.3 | AD2: =IF(AC2="","",IF(OR(AC2=F2,AND(AC2="crane_footing",F2="isolated_footing")),"yes","no"))
A3: 2 | B3: 120 | C3: own label | D3: solid | E3: 31 | F3: column | G3: label vote | H3: P1/120 | I3: printed label | J3: P1/120/120 | K3: 80 | L3: 25 | M3: =IF(AND(ISNUMBER(K3),L3>0),K3/L3,"") | N3: 0.2 | O3: 0 | P3: 0 | Q3: 0 | R3: 0 | S3: 1 | T3: 0 | U3: 0 | V3: 3 | Y3: 4596.9 | Z3: 792 | AA3: 4620.6 | AB3: 799.4 | AC3: column | AD3: =IF(AC3="","",IF(OR(AC3=F3,AND(AC3="crane_footing",F3="isolated_footing")),"yes","no"))
A4: 3 | B4: 120 | C4: own label | D4: solid | E4: 31 | F4: column | G4: label vote | H4: P1/120 | I4: printed label | J4: P1/120/120 | K4: 80 | L4: 25 | M4: =IF(AND(ISNUMBER(K4),L4>0),K4/L4,"") | N4: 0.2 | O4: 0 | P4: 0 | Q4: 0 | R4: 0 | S4: 1 | T4: 0 | U4: 0 | V4: 5 | Y4: 4704.8 | Z4: 861.4 | AA4: 4728.4 | AB4: 868.8 | AC4: column | AD4: =IF(AC4="","",IF(OR(AC4=F4,AND(AC4="crane_footing",F4="isolated_footing")),"yes","no"))
A5: 4 | B5: 120 | C5: own label | D5: solid | E5: 31 | F5: column | G5: label vote | H5: P1/120 | I5: printed label | J5: P1/120/120 | K5: 80 | L5: 25 | M5: =IF(AND(ISNUMBER(K5),L5>0),K5/L5,"") | N5: 0.2 | O5: 0 | P5: 0 | Q5: 0 | R5: 0 | S5: 1 | T5: 0 | U5: 0 | V5: 3 | Y5: 4596.9 | Z5: 861.4 | AA5: 4620.6 | AB5: 868.8 | AC5: column | AD5: =IF(AC5="","",IF(OR(AC5=F5,AND(AC5="crane_footing",F5="isolated_footing")),"yes","no"))
A6: 5 | B6: 120 | C6: own label | D6: solid | E6: 31 | F6: column | G6: label vote | H6: P1/120 | I6: printed label | J6: P1/120/120 | K6: 80 | L6: 25 | M6: =IF(AND(ISNUMBER(K6),L6>0),K6/L6,"") | N6: 0.2 | O6: 0 | P6: 0 | Q6: 0 | R6: 0 | S6: 1 | T6: 0 | U6: 0 | V6: 4 | Y6: 4704.8 | Z6: 792 | AA6: 4728.4 | AB6: 799.4 | AC6: column | AD6: =IF(AC6="","",IF(OR(AC6=F6,AND(AC6="crane_footing",F6="isolated_footing")),"yes","no"))
A7: 6 | B7: 120 | C7: nearest labels in its region | D7: solid | E7: 32 | F7: shear_wall | G7: label vote | H7: (none) | I7: no shear_wall type in its building has this size | K7: 474 | L7: 25 | M7: =IF(AND(ISNUMBER(K7),L7>0),K7/L7,"") | N7: 1.188 | O7: 180 | P7: 1 | Q7: 0 | R7: 0 | S7: 1 | T7: 0 | U7: 4 | V7: 4 | Y7: 4870.8 | Z7: 861.3 | AA7: 5010.9 | AB7: 868.7 | AD7: =IF(AC7="","",IF(OR(AC7=F7,AND(AC7="crane_footing",F7="isolated_footing")),"yes","no"))
A8: 7 | B8: 120 | C8: nearest labels in its region | D8: solid | E8: 32 | F8: shear_wall | G8: label vote | H8: (none) | I8: no shear_wall type in its building has this size | K8: 270 | L8: 25 | M8: =IF(AND(ISNUMBER(K8),L8>0),K8/L8,"") | N8: 0.684 | O8: 90 | P8: 1 | Q8: 0 | R8: 0 | S8: 1 | T8: 0 | U8: 6 | V8: 2 | Y8: 5011 | Z8: 781.6 | AA8: 5018.5 | AB8: 861.3 | AD8: =IF(AC8="","",IF(OR(AC8=F8,AND(AC8="crane_footing",F8="isolated_footing")),"yes","no"))
A9: 8 | B9: 120 | C9: nearest labels in its region | D9: solid | E9: 30 | F9: shear_wall | G9: label vote | H9: (none) | I9: no shear_wall type in its building has this size | K9: 424 | L9: 25 | M9: =IF(AND(ISNUMBER(K9),L9>0),K9/L9,"") | N9: 1.062 | O9: 180 | P9: 2 | Q9: 0 | R9: 0 | S9: 1 | T9: 0 | U9: 4 | V9: 0 | Y9: 4878.4 | Z9: 774.2 | AA9: 5003.8 | AB9: 781.7 | AD9: =IF(AC9="","",IF(OR(AC9=F9,AND(AC9="crane_footing",F9="isolated_footing")),"yes","no"))
A10: 9 | B10: 120 | C10: nearest labels in its region | D10: solid | E10: 30 | F10: shear_wall | G10: label vote | H10: (none) | I10: no shear_wall type in its building has this size | K10: 287 | L10: 25 | M10: =IF(AND(ISNUMBER(K10),L10>0),K10/L10,"") | N10: 0.722 | O10: 180 | P10: 2 | Q10: 0 | R10: 0 | S10: 1 | T10: 0 | U10: 4 | V10: 0 | Y10: 4771.3 | Z10: 749.2 | AA10: 4856.1 | AB10: 756.6 | AD10: =IF(AC10="","",IF(OR(AC10=F10,AND(AC10="crane_footing",F10="isolated_footing")),"yes","no"))
A11: 10 | B11: 120 | C11: nearest labels in its region | D11: solid | E11: 32 | F11: shear_wall | G11: label vote | H11: (none) | I11: no shear_wall type in its building has this size | K11: 175 | L11: 25 | M11: =IF(AND(ISNUMBER(K11),L11>0),K11/L11,"") | N11: 0.441 | O11: 89.9 | P11: 1 | Q11: 0 | R11: 0 | S11: 1 | T11: 0 | U11: 1 | V11: 2 | Y11: 4763.8 | Z11: 756.6 | AA11: 4771.3 | AB11: 808.2 | AD11: =IF(AC11="","",IF(OR(AC11=F11,AND(AC11="crane_footing",F11="isolated_footing")),"yes","no"))
A12: 11 | B12: 120 | C12: nearest labels in its region | D12: solid | E12: 32 | F12: shear_wall | G12: label vote | H12: (none) | I12: no shear_wall type in its building has this size | K12: 158 | L12: 25 | M12: =IF(AND(ISNUMBER(K12),L12>0),K12/L12,"") | N12: 0.402 | O12: 89.9 | P12: 1 | Q12: 0 | R12: 0 | S12: 1 | T12: 0 | U12: 1 | V12: 2 | Y12: 4870.7 | Z12: 781.7 | AA12: 4878.3 | AB12: 828.2 | AD12: =IF(AC12="","",IF(OR(AC12=F12,AND(AC12="crane_footing",F12="isolated_footing")),"yes","no"))
A13: 12 | B13: 120 | C13: own label | D13: solid | E13: 36 | F13: shear_wall | G13: label vote | H13: V1/120 | I13: printed label | J13: V1/120/120 | K13: 200 | L13: 25 | M13: =IF(AND(ISNUMBER(K13),L13>0),K13/L13,"") | N13: 0.502 | O13: 0 | P13: 0 | Q13: 0 | R13: 0 | S13: 1 | T13: 0 | U13: 2 | V13: 3 | Y13: 4521.3 | Z13: 517.4 | AA13: 4580.3 | AB13: 524.9 | AC13: shear_wall | AD13: =IF(AC13="","",IF(OR(AC13=F13,AND(AC13="crane_footing",F13="isolated_footing")),"yes","no"))
A14: 13 | B14: 120 | C14: own label | D14: solid | E14: 36 | F14: shear_wall | G14: label vote | H14: V1/120 | I14: printed label | J14: V1/120/120 | K14: 200 | L14: 25 | M14: =IF(AND(ISNUMBER(K14),L14>0),K14/L14,"") | N14: 0.5 | O14: 0 | P14: 0 | Q14: 0 | R14: 0 | S14: 1 | T14: 0 | U14: 2 | V14: 2 | Y14: 4516.5 | Z14: 826.7 | AA14: 4575.6 | AB14: 834.2 | AC14: shear_wall | AD14: =IF(AC14="","",IF(OR(AC14=F14,AND(AC14="crane_footing",F14="isolated_footing")),"yes","no"))
A15: 14 | B15: 120 | C15: own label | D15: solid | E15: 36 | F15: shear_wall | G15: label vote | H15: V1/120 | I15: printed label | J15: V1/120/120 | K15: 200 | L15: 25 | M15: =IF(AND(ISNUMBER(K15),L15>0),K15/L15,"") | N15: 0.5 | O15: 0 | P15: 0 | Q15: 1 | R15: 0 | S15: 0 | T15: 0 | U15: 2 | V15: 2 | Y15: 4519.4 | Z15: 681.4 | AA15: 4578.4 | AB15: 688.7 | AC15: shear_wall | AD15: =IF(AC15="","",IF(OR(AC15=F15,AND(AC15="crane_footing",F15="isolated_footing")),"yes","no"))
A16: 15 | B16: 120 | C16: own label | D16: solid | E16: 36 | F16: shear_wall | G16: label vote | H16: V1/120 | I16: printed label | J16: V1/120/120 | K16: 200 | L16: 25 | M16: =IF(AND(ISNUMBER(K16),L16>0),K16/L16,"") | N16: 0.499 | O16: 0 | P16: 0 | Q16: 1 | R16: 0 | S16: 0 | T16: 0 | U16: 2 | V16: 2 | Y16: 4519.5 | Z16: 972.2 | AA16: 4578.5 | AB16: 979.5 | AC16: shear_wall | AD16: =IF(AC16="","",IF(OR(AC16=F16,AND(AC16="crane_footing",F16="isolated_footing")),"yes","no"))
A17: 16 | B17: 120 | C17: own label | D17: solid | E17: 36 | F17: shear_wall | G17: label vote | H17: V2/120 | I17: printed label | J17: V2/120/120 | K17: 125 | L17: 25 | M17: =IF(AND(ISNUMBER(K17),L17>0),K17/L17,"") | N17: 0.313 | O17: 179.7 | P17: 0 | Q17: 1 | R17: 0 | S17: 0 | T17: 0 | U17: 2 | V17: 2 | Y17: 4516.6 | Z17: 1323 | AA17: 4553.6 | AB17: 1330.6 | AC17: shear_wall | AD17: =IF(AC17="","",IF(OR(AC17=F17,AND(AC17="crane_footing",F17="isolated_footing")),"yes","no"))
A18: 17 | B18: 120 | C18: own label (region says 121) | D18: solid | E18: 32 | F18: shear_wall | G18: label vote | H18: V2/120 | I18: printed label | J18: V2/120/120 | K18: 125 | L18: 25 | M18: =IF(AND(ISNUMBER(K18),L18>0),K18/L18,"") | N18: 0.312 | O18: 0 | P18: 1 | Q18: 1 | R18: 0 | S18: 0 | T18: 0 | U18: 0 | V18: 2 | Y18: 4749.1 | Z18: 1323.2 | AA18: 4786.1 | AB18: 1330.5 | AD18: =IF(AC18="","",IF(OR(AC18=F18,AND(AC18="crane_footing",F18="isolated_footing")),"yes","no"))
A19: 18 | B19: 120 | C19: own label | D19: solid | E19: 36 | F19: shear_wall | G19: label vote | H19: V3/120 | I19: printed label | J19: V3/120/120 | K19: 125 | L19: 25 | M19: =IF(AND(ISNUMBER(K19),L19>0),K19/L19,"") | N19: 0.314 | O19: 0 | P19: 0 | Q19: 1 | R19: 0 | S19: 0 | T19: 0 | U19: 2 | V19: 2 | Y19: 4285 | Z19: 864.7 | AA19: 4321.9 | AB19: 872.1 | AC19: shear_wall | AD19: =IF(AC19="","",IF(OR(AC19=F19,AND(AC19="crane_footing",F19="isolated_footing")),"yes","no"))
A20: 19 | B20: 120 | C20: own label | D20: solid | E20: 36 | F20: shear_wall | G20: label vote | H20: V3/120 | I20: printed label | J20: V3/120/120 | K20: 125 | L20: 25 | M20: =IF(AND(ISNUMBER(K20),L20>0),K20/L20,"") | N20: 0.313 | O20: 0.1 | P20: 0 | Q20: 0 | R20: 0 | S20: 1 | T20: 0 | U20: 2 | V20: 2 | Y20: 4253.5 | Z20: 1323.1 | AA20: 4290.5 | AB20: 1330.5 | AC20: shear_wall | AD20: =IF(AC20="","",IF(OR(AC20=F20,AND(AC20="crane_footing",F20="isolated_footing")),"yes","no"))
