Workbook

Sheet README
A1: Geometry-first classification
A3: How each element got its class
A4: 1. Objects were found from geometry only: solid fills (pieces grouped by the order they are drawn in), cross-hatched regions, closed outlines, bands (pairs of parallel lines; the widths come from the drawing itself) and circle stamps with corner rays. No colour, no layer, no text.
A5: 2. Objects of the same drawing kind were clustered on geometric features only: length, width, the ratio of the two (log), the EN 1992-1-1 5.3.1(7) section test (long side <= 4 x short side = column-shaped), whether it touches another solid, lies inside a closed outline, stands in a strip band or on a raft, and the pen of the outline drawn around it (none / thin / thick, relative to the thickest on the sheet). For outlines: length, width, how many solids and stipple dots are inside, how many beams touch it. 'Similar' means close in these features after scaling, not the same dimensions. Deliberately more clusters than classes.
A6: 3. Every label was matched to one object by distance and text alignment, in one global assignment that ignores what the label says; a label may stay unmatched.
A7: 4. A cluster takes the class that most of its matched labels name (>= 5 votes for it, at least 1.5 x the runner-up, with labels on >= 10% of its members, or a small clear vote of 2 or more with labels on 30% of its members). A cluster without enough labels takes the name of the most similar named cluster of the same drawing kind (feature distance <= 1.6), else stays unnamed. Unlabelled members inherit their cluster's class - that is how unlabelled walls became walls.
A8: 5. Labels were matched again, now only to objects of the class they name (or unnamed ones, at a cost), penalising an object whose size differs from the size its type has where a label sits right on its element, or that lies between expansion joints of another building. That gives the type keys (P1/124, V3/120, S7...).
A9: 6. An unlabelled member of a class takes the type of its class (and building, where sizes vary per building) that has its size: '~P1/124' when one type fits, '~V2/123|V4/123' when several share the size (nearest first). When none fits, the type source says so: for a 'column' that is a sign it is not a column.
A10: 7. Buildings: the footprint is cut along the expansion joints (pairs of long lines a few cm apart); a region whose labels agree is one building. Elsewhere the nearest building-numbered labels within the region decide.
A11: 8. A printed label whose element's size differs from the size its type has on at least two other elements is re-typed from the types of the building region the element stands in (then its label's building), else '?'. Two elements of a type that disagree are both flagged 'conflict'.
A12: 9. Unlabelled walls (solid or hatched): along the building edge (close and parallel to the footprint's boundary) or standing on a strip footing they are retaining walls; inside the building, when no V type has their size, core walls. A column-cluster member without a label stays a column unless it is drawn unlike the labelled columns (an outline pen none of them has) or continues a wall of the same thickness; then it is a wall piece.
A14: A label type only votes for its home drawing kind - the one it lands on most in the neutral pass (learned from the drawing: P and V labels land on solids, LG and SF labels on bands, S labels on outlines).
... A28: Scale 1/200.0, from 222 dimension texts (median error 0.24 cm). Formulas recalculate on opening; they were checked with the Python 'formulas' engine.

Sheet Summary by building
A1: Building | B1: Class | C1: Type key | D1: Count | E1: Length min (cm) | F1: Length max (cm) | G1: Width min (cm) | H1: Width max (cm) | I1: Same section? | J1: Total length (m) | K1: Of which typed by inference
A2: 120 | B2: column | C2: P1/120 | D2: =COUNTIFS(Objects!$B$2:$B$947,$A2,Objects!$F$2:$F$947,$B2,Objects!$I$2:$I$947,$C2) | E2: =_xlfn.MINIFS(Objects!$L$2:$L$947,Objects!$B$2:$B$947,$A2,Objects!$F$2:$F$947,$B2,Objects!$I$2:$I$947,$C2) | F2: =_xlfn.MAXIFS(Objects!$L$2:$L$947,Objects!$B$2:$B$947,$A2,Objects!$F$2:$F$947,$B2,Objects!$I$2:$I$947,$C2) | G2: =_xlfn.MINIFS(Objects!$M$2:$M$947,Objects!$B$2:$B$947,$A2,Objects!$F$2:$F$947,$B2,Objects!$I$2:$I$947,$C2) | H2: =_xlfn.MAXIFS(Objects!$M$2:$M$947,Objects!$B$2:$B$947,$A2,Objects!$F$2:$F$947,$B2,Objects!$I$2:$I$947,$C2) | I2: =IF(OR(C2="(none)",B2="raft",B2="sump_pit"),"n/a",IF(OR(B2="column",B2="shear_wall",B2="isolated_footing",B2="combined_footing"),IF(AND(F2-E2<=3,H2-G2<=3),"yes","no"),IF(H2-G2<=3,"yes (thickness)","no (thickness)"))) | J2: =SUMIFS(Objects!$L$2:$L$947,Objects!$B$2:$B$947,$A2,Objects!$F$2:$F$947,$B2,Objects!$I$2:$I$947,$C2)/100 | K2: =COUNTIFS(Objects!$B$2:$B$947,$A2,Objects!$F$2:$F$947,$B2,Objects!$I$2:$I$947,$C2,Objects!$J$2:$J$947,"inferred*")
A3: 120 | B3: shear_wall | C3: V1/120 | D3: =COUNTIFS(Objects!$B$2:$B$947,$A3,Objects!$F$2:$F$947,$B3,Objects!$I$2:$I$947,$C3) | E3: =_xlfn.MINIFS(Objects!$L$2:$L$947,Objects!$B$2:$B$947,$A3,Objects!$F$2:$F$947,$B3,Objects!$I$2:$I$947,$C3) | F3: =_xlfn.MAXIFS(Objects!$L$2:$L$947,Objects!$B$2:$B$947,$A3,Objects!$F$2:$F$947,$B3,Objects!$I$2:$I$947,$C3) | G3: =_xlfn.MINIFS(Objects!$M$2:$M$947,Objects!$B$2:$B$947,$A3,Objects!$F$2:$F$947,$B3,Objects!$I$2:$I$947,$C3) | H3: =_xlfn.MAXIFS(Objects!$M$2:$M$947,Objects!$B$2:$B$947,$A3,Objects!$F$2:$F$947,$B3,Objects!$I$2:$I$947,$C3) | I3: =IF(OR(C3="(none)",B3="raft",B3="sump_pit"),"n/a",IF(OR(B3="column",B3="shear_wall",B3="isolated_footing",B3="combined_footing"),IF(AND(F3-E3<=3,H3-G3<=3),"yes","no"),IF(H3-G3<=3,"yes (thickness)","no (thickness)"))) | J3: =SUMIFS(Objects!$L$2:$L$947,Objects!$B$2:$B$947,$A3,Objects!$F$2:$F$947,$B3,Objects!$I$2:$I$947,$C3)/100 | K3: =COUNTIFS(Objects!$B$2:$B$947,$A3,Objects!$F$2:$F$947,$B3,Objects!$I$2:$I$947,$C3,Objects!$J$2:$J$947,"inferred*")
A4: 120 | B4: shear_wall | C4: V2/120 | D4: =COUNTIFS(Objects!$B$2:$B$947,$A4,Objects!$F$2:$F$947,$B4,Objects!$I$2:$I$947,$C4) | E4: =_xlfn.MINIFS(Objects!$L$2:$L$947,Objects!$B$2:$B$947,$A4,Objects!$F$2:$F$947,$B4,Objects!$I$2:$I$947,$C4) | F4: =_xlfn.MAXIFS(Objects!$L$2:$L$947,Objects!$B$2:$B$947,$A4,Objects!$F$2:$F$947,$B4,Objects!$I$2:$I$947,$C4) | G4: =_xlfn.MINIFS(Objects!$M$2:$M$947,Objects!$B$2:$B$947,$A4,Objects!$F$2:$F$947,$B4,Objects!$I$2:$I$947,$C4) | H4: =_xlfn.MAXIFS(Objects!$M$2:$M$947,Objects!$B$2:$B$947,$A4,Objects!$F$2:$F$947,$B4,Objects!$I$2:$I$947,$C4) | I4: =IF(OR(C4="(none)",B4="raft",B4="sump_pit"),"n/a",IF(OR(B4="column",B4="shear_wall",B4="isolated_footing",B4="combined_footing"),IF(AND(F4-E4<=3,H4-G4<=3),"yes","no"),IF(H4-G4<=3,"yes (thickness)","no (thickness)"))) | J4: =SUMIFS(Objects!$L$2:$L$947,Objects!$B$2:$B$947,$A4,Objects!$F$2:$F$947,$B4,Objects!$I$2:$I$947,$C4)/100 | K4: =COUNTIFS(Objects!$B$2:$B$947,$A4,Objects!$F$2:$F$947,$B4,Objects!$I$2:$I$947,$C4,Objects!$J$2:$J$947,"inferred*")
A5: 120 | B5: shear_wall | C5: V3/120 | D5: =COUNTIFS(Objects!$B$2:$B$947,$A5,Objects!$F$2:$F$947,$B5,Objects!$I$2:$I$947,$C5) | E5: =_xlfn.MINIFS(Objects!$L$2:$L$947,Objects!$B$2:$B$947,$A5,Objects!$F$2:$F$947,$B5,Objects!$I$2:$I$947,$C5) | F5: =_xlfn.MAXIFS(Objects!$L$2:$L$947,Objects!$B$2:$B$947,$A5,Objects!$F$2:$F$947,$B5,Objects!$I$2:$I$947,$C5) | G5: =_xlfn.MINIFS(Objects!$M$2:$M$947,Objects!$B$2:$B$947,$A5,Objects!$F$2:$F$947,$B5,Objects!$I$2:$I$947,$C5) | H5: =_xlfn.MAXIFS(Objects!$M$2:$M$947,Objects!$B$2:$B$947,$A5,Objects!$F$2:$F$947,$B5,Objects!$I$2:$I$947,$C5) | I5: =IF(OR(C5="(none)",B5="raft",B5="sump_pit"),"n/a",IF(OR(B5="column",B5="shear_wall",B5="isolated_footing",B5="combined_footing"),IF(AND(F5-E5<=3,H5-G5<=3),"yes","no"),IF(H5-G5<=3,"yes (thickness)","no (thickness)"))) | J5: =SUMIFS(Objects!$L$2:$L$947,Objects!$B$2:$B$947,$A5,Objects!$F$2:$F$947,$B5,Objects!$I$2:$I$947,$C5)/100 | K5: =COUNTIFS(Objects!$B$2:$B$947,$A5,Objects!$F$2:$F$947,$B5,Objects!$I$2:$I$947,$C5,Objects!$J$2:$J$947,"inferred*")
A6: 120 | B6: shear_wall | C6: V4/120 | D6: =COUNTIFS(Objects!$B$2:$B$947,$A6,Objects!$F$2:$F$947,$B6,Objects!$I$2:$I$947,$C6) | E6: =_xlfn.MINIFS(Objects!$L$2:$L$947,Objects!$B$2:$B$947,$A6,Objects!$F$2:$F$947,$B6,Objects!$I$2:$I$947,$C6) | F6: =_xlfn.MAXIFS(Objects!$L$2:$L$947,Objects!$B$2:$B$947,$A6,Objects!$F$2:$F$947,$B6,Objects!$I$2:$I$947,$C6) | G6: =_xlfn.MINIFS(Objects!$M$2:$M$947,Objects!$B$2:$B$947,$A6,Objects!$F$2:$F$947,$B6,Objects!$I$2:$I$947,$C6) | H6: =_xlfn.MAXIFS(Objects!$M$2:$M$947,Objects!$B$2:$B$947,$A6,Objects!$F$2:$F$947,$B6,Objects!$I$2:$I$947,$C6) | I6: =IF(OR(C6="(none)",B6="raft",B6="sump_pit"),"n/a",IF(OR(B6="column",B6="shear_wall",B6="isolated_footing",B6="combined_footing"),IF(AND(F6-E6<=3,H6-G6<=3),"yes","no"),IF(H6-G6<=3,"yes (thickness)","no (thickness)"))) | J6: =SUMIFS(Objects!$L$2:$L$947,Objects!$B$2:$B$947,$A6,Objects!$F$2:$F$947,$B6,Objects!$I$2:$I$947,$C6)/100 | K6: =COUNTIFS(Objects!$B$2:$B$947,$A6,Objects!$F$2:$F$947,$B6,Objects!$I$2:$I$947,$C6,Objects!$J$2:$J$947,"inferred*")
A7: 120 | B7: shear_wall | C7: V5/120 | D7: =COUNTIFS(Objects!$B$2:$B$947,$A7,Objects!$F$2:$F$947,$B7,Objects!$I$2:$I$947,$C7) | E7: =_xlfn.MINIFS(Objects!$L$2:$L$947,Objects!$B$2:$B$947,$A7,Objects!$F$2:$F$947,$B7,Objects!$I$2:$I$947,$C7) | F7: =_xlfn.MAXIFS(Objects!$L$2:$L$947,Objects!$B$2:$B$947,$A7,Objects!$F$2:$F$947,$B7,Objects!$I$2:$I$947,$C7) | G7: =_xlfn.MINIFS(Objects!$M$2:$M$947,Objects!$B$2:$B$947,$A7,Objects!$F$2:$F$947,$B7,Objects!$I$2:$I$947,$C7) | H7: =_xlfn.MAXIFS(Objects!$M$2:$M$947,Objects!$B$2:$B$947,$A7,Objects!$F$2:$F$947,$B7,Objects!$I$2:$I$947,$C7) | I7: =IF(OR(C7="(none)",B7="raft",B7="sump_pit"),"n/a",IF(OR(B7="column",B7="shear_wall",B7="isolated_footing",B7="combined_footing"),IF(AND(F7-E7<=3,H7-G7<=3),"yes","no"),IF(H7-G7<=3,"yes (thickness)","no (thickness)"))) | J7: =SUMIFS(Objects!$L$2:$L$947,Objects!$B$2:$B$947,$A7,Objects!$F$2:$F$947,$B7,Objects!$I$2:$I$947,$C7)/100 | K7: =COUNTIFS(Objects!$B$2:$B$947,$A7,Objects!$F$2:$F$947,$B7,Objects!$I$2:$I$947,$C7,Objects!$J$2:$J$947,"inferred*")
A8: 120 | B8: shear_wall | C8: V8/120 | D8: =COUNTIFS(Objects!$B$2:$B$947,$A8,Objects!$F$2:$F$947,$B8,Objects!$I$2:$I$947,$C8) | E8: =_xlfn.MINIFS(Objects!$L$2:$L$947,Objects!$B$2:$B$947,$A8,Objects!$F$2:$F$947,$B8,Objects!$I$2:$I$947,$C8) | F8: =_xlfn.MAXIFS(Objects!$L$2:$L$947,Objects!$B$2:$B$947,$A8,Objects!$F$2:$F$947,$B8,Objects!$I$2:$I$947,$C8) | G8: =_xlfn.MINIFS(Objects!$M$2:$M$947,Objects!$B$2:$B$947,$A8,Objects!$F$2:$F$947,$B8,Objects!$I$2:$I$947,$C8) | H8: =_xlfn.MAXIFS(Objects!$M$2:$M$947,Objects!$B$2:$B$947,$A8,Objects!$F$2:$F$947,$B8,Objects!$I$2:$I$947,$C8) | I8: =IF(OR(C8="(none)",B8="raft",B8="sump_pit"),"n/a",IF(OR(B8="column",B8="shear_wall",B8="isolated_footing",B8="combined_footing"),IF(AND(F8-E8<=3,H8-G8<=3),"yes","no"),IF(H8-G8<=3,"yes (thickness)","no (thickness)"))) | J8: =SUMIFS(Objects!$L$2:$L$947,Objects!$B$2:$B$947,$A8,Objects!$F$2:$F$947,$B8,Objects!$I$2:$I$947,$C8)/100 | K8: =COUNTIFS(Objects!$B$2:$B$947,$A8,Objects!$F$2:$F$947,$B8,Objects!$I$2:$I$947,$C8,Objects!$J$2:$J$947,"inferred*")
A9: 120 | B9: shear_wall | C9: V9/120 | D9: =COUNTIFS(Objects!$B$2:$B$947,$A9,Objects!$F$2:$F$947,$B9,Objects!$I$2:$I$947,$C9) | E9: =_xlfn.MINIFS(Objects!$L$2:$L$947,Objects!$B$2:$B$947,$A9,Objects!$F$2:$F$947,$B9,Objects!$I$2:$I$947,$C9) | F9: =_xlfn.MAXIFS(Objects!$L$2:$L$947,Objects!$B$2:$B$947,$A9,Objects!$F$2:$F$947,$B9,Objects!$I$2:$I$947,$C9) | G9: =_xlfn.MINIFS(Objects!$M$2:$M$947,Objects!$B$2:$B$947,$A9,Objects!$F$2:$F$947,$B9,Objects!$I$2:$I$947,$C9) | H9: =_xlfn.MAXIFS(Objects!$M$2:$M$947,Objects!$B$2:$B$947,$A9,Objects!$F$2:$F$947,$B9,Objects!$I$2:$I$947,$C9) | I9: =IF(OR(C9="(none)",B9="raft",B9="sump_pit"),"n/a",IF(OR(B9="column",B9="shear_wall",B9="isolated_footing",B9="combined_footing"),IF(AND(F9-E9<=3,H9-G9<=3),"yes","no"),IF(H9-G9<=3,"yes (thickness)","no (thickness)"))) | J9: =SUMIFS(Objects!$L$2:$L$947,Objects!$B$2:$B$947,$A9,Objects!$F$2:$F$947,$B9,Objects!$I$2:$I$947,$C9)/100 | K9: =COUNTIFS(Objects!$B$2:$B$947,$A9,Objects!$F$2:$F$947,$B9,Objects!$I$2:$I$947,$C9,Objects!$J$2:$J$947,"inferred*")
A10: 120 | B10: core_wall | C10: (none) | D10: =COUNTIFS(Objects!$B$2:$B$947,$A10,Objects!$F$2:$F$947,$B10,Objects!$I$2:$I$947,$C10) | E10: =_xlfn.MINIFS(Objects!$L$2:$L$947,Objects!$B$2:$B$947,$A10,Objects!$F$2:$F$947,$B10,Objects!$I$2:$I$947,$C10) | F10: =_xlfn.MAXIFS(Objects!$L$2:$L$947,Objects!$B$2:$B$947,$A10,Objects!$F$2:$F$947,$B10,Objects!$I$2:$I$947,$C10) | G10: =_xlfn.MINIFS(Objects!$M$2:$M$947,Objects!$B$2:$B$947,$A10,Objects!$F$2:$F$947,$B10,Objects!$I$2:$I$947,$C10) | H10: =_xlfn.MAXIFS(Objects!$M$2:$M$947,Objects!$B$2:$B$947,$A10,Objects!$F$2:$F$947,$B10,Objects!$I$2:$I$947,$C10) | I10: =IF(OR(C10="(none)",B10="raft",B10="sump_pit"),"n/a",IF(OR(B10="column",B10="shear_wall",B10="isolated_footing",B10="combined_footing"),IF(AND(F10-E10<=3,H10-G10<=3),"yes","no"),IF(H10-G10<=3,"yes (thickness)","no (thickness)"))) | J10: =SUMIFS(Objects!$L$2:$L$947,Objects!$B$2:$B$947,$A10,Objects!$F$2:$F$947,$B10,Objects!$I$2:$I$947,$C10)/100 | K10: =COUNTIFS(Objects!$B$2:$B$947,$A10,Objects!$F$2:$F$947,$B10,Objects!$I$2:$I$947,$C10,Objects!$J$2:$J$947,"inferred*")
A11: 120 | B11: retaining_wall | C11: VP20 | D11: =COUNTIFS(Objects!$B$2:$B$947,$A11,Objects!$F$2:$F$947,$B11,Objects!$I$2:$I$947,$C11) | E11: =_xlfn.MINIFS(Objects!$L$2:$L$947,Objects!$B$2:$B$947,$A11,Objects!$F$2:$F$947,$B11,Objects!$I$2:$I$947,$C11) | F11: =_xlfn.MAXIFS(Objects!$L$2:$L$947,Objects!$B$2:$B$947,$A11,Objects!$F$2:$F$947,$B11,Objects!$I$2:$I$947,$C11) | G11: =_xlfn.MINIFS(Objects!$M$2:$M$947,Objects!$B$2:$B$947,$A11,Objects!$F$2:$F$947,$B11,Objects!$I$2:$I$947,$C11) | H11: =_xlfn.MAXIFS(Objects!$M$2:$M$947,Objects!$B$2:$B$947,$A11,Objects!$F$2:$F$947,$B11,Objects!$I$2:$I$947,$C11) | I11: =IF(OR(C11="(none)",B11="raft",B11="sump_pit"),"n/a",IF(OR(B11="column",B11="shear_wall",B11="isolated_footing",B11="combined_footing"),IF(AND(F11-E11<=3,H11-G11<=3),"yes","no"),IF(H11-G11<=3,"yes (thickness)","no (thickness)"))) | J11: =SUMIFS(Objects!$L$2:$L$947,Objects!$B$2:$B$947,$A11,Objects!$F$2:$F$947,$B11,Objects!$I$2:$I$947,$C11)/100 | K11: =COUNTIFS(Objects!$B$2:$B$947,$A11,Objects!$F$2:$F$947,$B11,Objects!$I$2:$I$947,$C11,Objects!$J$2:$J$947,"inferred*")
A12: 120 | B12: retaining_wall | C12: VP25 | D12: =COUNTIFS(Objects!$B$2:$B$947,$A12,Objects!$F$2:$F$947,$B12,Objects!$I$2:$I$947,$C12) | E12: =_xlfn.MINIFS(Objects!$L$2:$L$947,Objects!$B$2:$B$947,$A12,Objects!$F$2:$F$947,$B12,Objects!$I$2:$I$947,$C12) | F12: =_xlfn.MAXIFS(Objects!$L$2:$L$947,Objects!$B$2:$B$947,$A12,Objects!$F$2:$F$947,$B12,Objects!$I$2:$I$947,$C12) | G12: =_xlfn.MINIFS(Objects!$M$2:$M$947,Objects!$B$2:$B$947,$A12,Objects!$F$2:$F$947,$B12,Objects!$I$2:$I$947,$C12) | H12: =_xlfn.MAXIFS(Objects!$M$2:$M$947,Objects!$B$2:$B$947,$A12,Objects!$F$2:$F$947,$B12,Objects!$I$2:$I$947,$C12) | I12: =IF(OR(C12="(none)",B12="raft",B12="sump_pit"),"n/a",IF(OR(B12="column",B12="shear_wall",B12="isolated_footing",B12="combined_footing"),IF(AND(F12-E12<=3,H12-G12<=3),"yes","no"),IF(H12-G12<=3,"yes (thickness)","no (thickness)"))) | J12: =SUMIFS(Objects!$L$2:$L$947,Objects!$B$2:$B$947,$A12,Objects!$F$2:$F$947,$B12,Objects!$I$2:$I$947,$C12)/100 | K12: =COUNTIFS(Objects!$B$2:$B$947,$A12,Objects!$F$2:$F$947,$B12,Objects!$I$2:$I$947,$C12,Objects!$J$2:$J$947,"inferred*")
A13: 120 | B13: isolated_footing | C13: S1 | D13: =COUNTIFS(Objects!$B$2:$B$947,$A13,Objects!$F$2:$F$947,$B13,Objects!$I$2:$I$947,$C13) | E13: =_xlfn.MINIFS(Objects!$L$2:$L$947,Objects!$B$2:$B$947,$A13,Objects!$F$2:$F$947,$B13,Objects!$I$2:$I$947,$C13) | F13: =_xlfn.MAXIFS(Objects!$L$2:$L$947,Objects!$B$2:$B$947,$A13,Objects!$F$2:$F$947,$B13,Objects!$I$2:$I$947,$C13) | G13: =_xlfn.MINIFS(Objects!$M$2:$M$947,Objects!$B$2:$B$947,$A13,Objects!$F$2:$F$947,$B13,Objects!$I$2:$I$947,$C13) | H13: =_xlfn.MAXIFS(Objects!$M$2:$M$947,Objects!$B$2:$B$947,$A13,Objects!$F$2:$F$947,$B13,Objects!$I$2:$I$947,$C13) | I13: =IF(OR(C13="(none)",B13="raft",B13="sump_pit"),"n/a",IF(OR(B13="column",B13="shear_wall",B13="isolated_footing",B13="combined_footing"),IF(AND(F13-E13<=3,H13-G13<=3),"yes","no"),IF(H13-G13<=3,"yes (thickness)","no (thickness)"))) | J13: =SUMIFS(Objects!$L$2:$L$947,Objects!$B$2:$B$947,$A13,Objects!$F$2:$F$947,$B13,Objects!$I$2:$I$947,$C13)/100 | K13: =COUNTIFS(Objects!$B$2:$B$947,$A13,Objects!$F$2:$F$947,$B13,Objects!$I$2:$I$947,$C13,Objects!$J$2:$J$947,"inferred*")
... A235: 130 | B235: sump_pit | C235: Fosse | D235: =COUNTIFS(Objects!$B$2:$B$947,$A235,Objects!$F$2:$F$947,$B235,Objects!$I$2:$I$947,$C235) | E235: =_xlfn.MINIFS(Objects!$L$2:$L$947,Objects!$B$2:$B$947,$A235,Objects!$F$2:$F$947,$B235,Objects!$I$2:$I$947,$C235) | F235: =_xlfn.MAXIFS(Objects!$L$2:$L$947,Objects!$B$2:$B$947,$A235,Objects!$F$2:$F$947,$B235,Objects!$I$2:$I$947,$C235) | G235: =_xlfn.MINIFS(Objects!$M$2:$M$947,Objects!$B$2:$B$947,$A235,Objects!$F$2:$F$947,$B235,Objects!$I$2:$I$947,$C235) | H235: =_xlfn.MAXIFS(Objects!$M$2:$M$947,Objects!$B$2:$B$947,$A235,Objects!$F$2:$F$947,$B235,Objects!$I$2:$I$947,$C235) | I235: =IF(OR(C235="(none)",B235="raft",B235="sump_pit"),"n/a",IF(OR(B235="column",B235="shear_wall",B235="isolated_footing",B235="combined_footing"),IF(AND(F235-E235<=3,H235-G235<=3),"yes","no"),IF(H235-G235<=3,"yes (thickness)","no (thickness)"))) | J235: =SUMIFS(Objects!$L$2:$L$947,Objects!$B$2:$B$947,$A235,Objects!$F$2:$F$947,$B235,Objects!$I$2:$I$947,$C235)/100 | K235: =COUNTIFS(Objects!$B$2:$B$947,$A235,Objects!$F$2:$F$947,$B235,Objects!$I$2:$I$947,$C235,Objects!$J$2:$J$947,"inferred*")
A237: All | D237: =SUM(D2:D235)
A238: Unnamed clusters are not listed here (see 'Clusters'). 'Same section?' allows 3 cm; columns, shear walls and footings compare length and width, walls and bands of varying length compare thickness only.

Sheet Clusters
A1: Cluster | B1: Drawing kind | C1: Members | D1: Length min (cm) | E1: Length max (cm) | F1: Width min (cm) | G1: Width max (cm) | H1: Touch solids | I1: Inside an outline | J1: In a strip band | K1: On a stamped region | L1: Votes: column | M1: Votes: footing:S | N1: Votes: footing:SC | O1: Votes: grade_beam | P1: Votes: pit | Q1: Votes: raft | R1: Votes: retaining_wall+strip_footing | S1: Votes: strip_footing | T1: Votes: wall | U1: Votes total | V1: Top share | W1: Class | X1: Named by | Y1: Silhouette
A2: 0 | B2: band 0.10 m | C2: =COUNTIFS(Objects!$E$2:$E$947,$A2) | D2: =_xlfn.MINIFS(Objects!$L$2:$L$947,Objects!$E$2:$E$947,$A2) | E2: =_xlfn.MAXIFS(Objects!$L$2:$L$947,Objects!$E$2:$E$947,$A2) | F2: =_xlfn.MINIFS(Objects!$M$2:$M$947,Objects!$E$2:$E$947,$A2) | G2: =_xlfn.MAXIFS(Objects!$M$2:$M$947,Objects!$E$2:$E$947,$A2) | H2: =IFERROR(COUNTIFS(Objects!$E$2:$E$947,$A2,Objects!$Q$2:$Q$947,">0")/$C2,0) | I2: =IFERROR(COUNTIFS(Objects!$E$2:$E$947,$A2,Objects!$R$2:$R$947,1)/$C2,0) | J2: =IFERROR(COUNTIFS(Objects!$E$2:$E$947,$A2,Objects!$S$2:$S$947,1)/$C2,0) | K2: =IFERROR(COUNTIFS(Objects!$E$2:$E$947,$A2,Objects!$T$2:$T$947,1)/$C2,0) | L2: 0 | M2: 0 | N2: 0 | O2: 0 | P2: 0 | Q2: 0 | R2: 0 | S2: 0 | T2: 0 | U2: =SUM(L2:T2) | V2: =IFERROR(MAX(L2:T2)/U2,0) | W2: unidentified | X2: no label votes
A3: 1 | B3: band 0.25 m | C3: =COUNTIFS(Objects!$E$2:$E$947,$A3) | D3: =_xlfn.MINIFS(Objects!$L$2:$L$947,Objects!$E$2:$E$947,$A3) | E3: =_xlfn.MAXIFS(Objects!$L$2:$L$947,Objects!$E$2:$E$947,$A3) | F3: =_xlfn.MINIFS(Objects!$M$2:$M$947,Objects!$E$2:$E$947,$A3) | G3: =_xlfn.MAXIFS(Objects!$M$2:$M$947,Objects!$E$2:$E$947,$A3) | H3: =IFERROR(COUNTIFS(Objects!$E$2:$E$947,$A3,Objects!$Q$2:$Q$947,">0")/$C3,0) | I3: =IFERROR(COUNTIFS(Objects!$E$2:$E$947,$A3,Objects!$R$2:$R$947,1)/$C3,0) | J3: =IFERROR(COUNTIFS(Objects!$E$2:$E$947,$A3,Objects!$S$2:$S$947,1)/$C3,0) | K3: =IFERROR(COUNTIFS(Objects!$E$2:$E$947,$A3,Objects!$T$2:$T$947,1)/$C3,0) | L3: 0 | M3: 0 | N3: 0 | O3: 8 | P3: 0 | Q3: 0 | R3: 0 | S3: 0 | T3: 0 | U3: =SUM(L3:T3) | V3: =IFERROR(MAX(L3:T3)/U3,0) | W3: grade_beam | X3: label vote
A4: 2 | B4: band 0.32 m | C4: =COUNTIFS(Objects!$E$2:$E$947,$A4) | D4: =_xlfn.MINIFS(Objects!$L$2:$L$947,Objects!$E$2:$E$947,$A4) | E4: =_xlfn.MAXIFS(Objects!$L$2:$L$947,Objects!$E$2:$E$947,$A4) | F4: =_xlfn.MINIFS(Objects!$M$2:$M$947,Objects!$E$2:$E$947,$A4) | G4: =_xlfn.MAXIFS(Objects!$M$2:$M$947,Objects!$E$2:$E$947,$A4) | H4: =IFERROR(COUNTIFS(Objects!$E$2:$E$947,$A4,Objects!$Q$2:$Q$947,">0")/$C4,0) | I4: =IFERROR(COUNTIFS(Objects!$E$2:$E$947,$A4,Objects!$R$2:$R$947,1)/$C4,0) | J4: =IFERROR(COUNTIFS(Objects!$E$2:$E$947,$A4,Objects!$S$2:$S$947,1)/$C4,0) | K4: =IFERROR(COUNTIFS(Objects!$E$2:$E$947,$A4,Objects!$T$2:$T$947,1)/$C4,0) | L4: 0 | M4: 0 | N4: 0 | O4: 0 | P4: 0 | Q4: 0 | R4: 0 | S4: 0 | T4: 0 | U4: =SUM(L4:T4) | V4: =IFERROR(MAX(L4:T4)/U4,0) | W4: unidentified | X4: no label votes
A5: 3 | B5: band 0.40 m | C5: =COUNTIFS(Objects!$E$2:$E$947,$A5) | D5: =_xlfn.MINIFS(Objects!$L$2:$L$947,Objects!$E$2:$E$947,$A5) | E5: =_xlfn.MAXIFS(Objects!$L$2:$L$947,Objects!$E$2:$E$947,$A5) | F5: =_xlfn.MINIFS(Objects!$M$2:$M$947,Objects!$E$2:$E$947,$A5) | G5: =_xlfn.MAXIFS(Objects!$M$2:$M$947,Objects!$E$2:$E$947,$A5) | H5: =IFERROR(COUNTIFS(Objects!$E$2:$E$947,$A5,Objects!$Q$2:$Q$947,">0")/$C5,0) | I5: =IFERROR(COUNTIFS(Objects!$E$2:$E$947,$A5,Objects!$R$2:$R$947,1)/$C5,0) | J5: =IFERROR(COUNTIFS(Objects!$E$2:$E$947,$A5,Objects!$S$2:$S$947,1)/$C5,0) | K5: =IFERROR(COUNTIFS(Objects!$E$2:$E$947,$A5,Objects!$T$2:$T$947,1)/$C5,0) | L5: 0 | M5: 0 | N5: 0 | O5: 191 | P5: 0 | Q5: 0 | R5: 0 | S5: 0 | T5: 0 | U5: =SUM(L5:T5) | V5: =IFERROR(MAX(L5:T5)/U5,0) | W5: grade_beam | X5: label vote
A6: 4 | B6: band 0.48 m | C6: =COUNTIFS(Objects!$E$2:$E$947,$A6) | D6: =_xlfn.MINIFS(Objects!$L$2:$L$947,Objects!$E$2:$E$947,$A6) | E6: =_xlfn.MAXIFS(Objects!$L$2:$L$947,Objects!$E$2:$E$947,$A6) | F6: =_xlfn.MINIFS(Objects!$M$2:$M$947,Objects!$E$2:$E$947,$A6) | G6: =_xlfn.MAXIFS(Objects!$M$2:$M$947,Objects!$E$2:$E$947,$A6) | H6: =IFERROR(COUNTIFS(Objects!$E$2:$E$947,$A6,Objects!$Q$2:$Q$947,">0")/$C6,0) | I6: =IFERROR(COUNTIFS(Objects!$E$2:$E$947,$A6,Objects!$R$2:$R$947,1)/$C6,0) | J6: =IFERROR(COUNTIFS(Objects!$E$2:$E$947,$A6,Objects!$S$2:$S$947,1)/$C6,0) | K6: =IFERROR(COUNTIFS(Objects!$E$2:$E$947,$A6,Objects!$T$2:$T$947,1)/$C6,0) | L6: 0 | M6: 0 | N6: 0 | O6: 0 | P6: 0 | Q6: 0 | R6: 0 | S6: 0 | T6: 0 | U6: =SUM(L6:T6) | V6: =IFERROR(MAX(L6:T6)/U6,0) | W6: unidentified | X6: no label votes
A7: 5 | B7: band 0.80 m | C7: =COUNTIFS(Objects!$E$2:$E$947,$A7) | D7: =_xlfn.MINIFS(Objects!$L$2:$L$947,Objects!$E$2:$E$947,$A7) | E7: =_xlfn.MAXIFS(Objects!$L$2:$L$947,Objects!$E$2:$E$947,$A7) | F7: =_xlfn.MINIFS(Objects!$M$2:$M$947,Objects!$E$2:$E$947,$A7) | G7: =_xlfn.MAXIFS(Objects!$M$2:$M$947,Objects!$E$2:$E$947,$A7) | H7: =IFERROR(COUNTIFS(Objects!$E$2:$E$947,$A7,Objects!$Q$2:$Q$947,">0")/$C7,0) | I7: =IFERROR(COUNTIFS(Objects!$E$2:$E$947,$A7,Objects!$R$2:$R$947,1)/$C7,0) | J7: =IFERROR(COUNTIFS(Objects!$E$2:$E$947,$A7,Objects!$S$2:$S$947,1)/$C7,0) | K7: =IFERROR(COUNTIFS(Objects!$E$2:$E$947,$A7,Objects!$T$2:$T$947,1)/$C7,0) | L7: 0 | M7: 0 | N7: 0 | O7: 0 | P7: 0 | Q7: 0 | R7: 0 | S7: 60 | T7: 0 | U7: =SUM(L7:T7) | V7: =IFERROR(MAX(L7:T7)/U7,0) | W7: strip_footing | X7: label vote
A8: 6 | B8: band 0.83 m | C8: =COUNTIFS(Objects!$E$2:$E$947,$A8) | D8: =_xlfn.MINIFS(Objects!$L$2:$L$947,Objects!$E$2:$E$947,$A8) | E8: =_xlfn.MAXIFS(Objects!$L$2:$L$947,Objects!$E$2:$E$947,$A8) | F8: =_xlfn.MINIFS(Objects!$M$2:$M$947,Objects!$E$2:$E$947,$A8) | G8: =_xlfn.MAXIFS(Objects!$M$2:$M$947,Objects!$E$2:$E$947,$A8) | H8: =IFERROR(COUNTIFS(Objects!$E$2:$E$947,$A8,Objects!$Q$2:$Q$947,">0")/$C8,0) | I8: =IFERROR(COUNTIFS(Objects!$E$2:$E$947,$A8,Objects!$R$2:$R$947,1)/$C8,0) | J8: =IFERROR(COUNTIFS(Objects!$E$2:$E$947,$A8,Objects!$S$2:$S$947,1)/$C8,0) | K8: =IFERROR(COUNTIFS(Objects!$E$2:$E$947,$A8,Objects!$T$2:$T$947,1)/$C8,0) | L8: 0 | M8: 0 | N8: 0 | O8: 0 | P8: 0 | Q8: 0 | R8: 0 | S8: 0 | T8: 0 | U8: =SUM(L8:T8) | V8: =IFERROR(MAX(L8:T8)/U8,0) | W8: unidentified | X8: no label votes
A9: 7 | B9: band 0.95 m | C9: =COUNTIFS(Objects!$E$2:$E$947,$A9) | D9: =_xlfn.MINIFS(Objects!$L$2:$L$947,Objects!$E$2:$E$947,$A9) | E9: =_xlfn.MAXIFS(Objects!$L$2:$L$947,Objects!$E$2:$E$947,$A9) | F9: =_xlfn.MINIFS(Objects!$M$2:$M$947,Objects!$E$2:$E$947,$A9) | G9: =_xlfn.MAXIFS(Objects!$M$2:$M$947,Objects!$E$2:$E$947,$A9) | H9: =IFERROR(COUNTIFS(Objects!$E$2:$E$947,$A9,Objects!$Q$2:$Q$947,">0")/$C9,0) | I9: =IFERROR(COUNTIFS(Objects!$E$2:$E$947,$A9,Objects!$R$2:$R$947,1)/$C9,0) | J9: =IFERROR(COUNTIFS(Objects!$E$2:$E$947,$A9,Objects!$S$2:$S$947,1)/$C9,0) | K9: =IFERROR(COUNTIFS(Objects!$E$2:$E$947,$A9,Objects!$T$2:$T$947,1)/$C9,0) | L9: 0 | M9: 0 | N9: 0 | O9: 0 | P9: 0 | Q9: 0 | R9: 0 | S9: 0 | T9: 0 | U9: =SUM(L9:T9) | V9: =IFERROR(MAX(L9:T9)/U9,0) | W9: unidentified | X9: no label votes
A10: 8 | B10: band 1.00 m | C10: =COUNTIFS(Objects!$E$2:$E$947,$A10) | D10: =_xlfn.MINIFS(Objects!$L$2:$L$947,Objects!$E$2:$E$947,$A10) | E10: =_xlfn.MAXIFS(Objects!$L$2:$L$947,Objects!$E$2:$E$947,$A10) | F10: =_xlfn.MINIFS(Objects!$M$2:$M$947,Objects!$E$2:$E$947,$A10) | G10: =_xlfn.MAXIFS(Objects!$M$2:$M$947,Objects!$E$2:$E$947,$A10) | H10: =IFERROR(COUNTIFS(Objects!$E$2:$E$947,$A10,Objects!$Q$2:$Q$947,">0")/$C10,0) | I10: =IFERROR(COUNTIFS(Objects!$E$2:$E$947,$A10,Objects!$R$2:$R$947,1)/$C10,0) | J10: =IFERROR(COUNTIFS(Objects!$E$2:$E$947,$A10,Objects!$S$2:$S$947,1)/$C10,0) | K10: =IFERROR(COUNTIFS(Objects!$E$2:$E$947,$A10,Objects!$T$2:$T$947,1)/$C10,0) | L10: 0 | M10: 0 | N10: 0 | O10: 0 | P10: 0 | Q10: 0 | R10: 0 | S10: 0 | T10: 0 | U10: =SUM(L10:T10) | V10: =IFERROR(MAX(L10:T10)/U10,0) | W10: unidentified | X10: no label votes
A11: 9 | B11: band 1.22 m | C11: =COUNTIFS(Objects!$E$2:$E$947,$A11) | D11: =_xlfn.MINIFS(Objects!$L$2:$L$947,Objects!$E$2:$E$947,$A11) | E11: =_xlfn.MAXIFS(Objects!$L$2:$L$947,Objects!$E$2:$E$947,$A11) | F11: =_xlfn.MINIFS(Objects!$M$2:$M$947,Objects!$E$2:$E$947,$A11) | G11: =_xlfn.MAXIFS(Objects!$M$2:$M$947,Objects!$E$2:$E$947,$A11) | H11: =IFERROR(COUNTIFS(Objects!$E$2:$E$947,$A11,Objects!$Q$2:$Q$947,">0")/$C11,0) | I11: =IFERROR(COUNTIFS(Objects!$E$2:$E$947,$A11,Objects!$R$2:$R$947,1)/$C11,0) | J11: =IFERROR(COUNTIFS(Objects!$E$2:$E$947,$A11,Objects!$S$2:$S$947,1)/$C11,0) | K11: =IFERROR(COUNTIFS(Objects!$E$2:$E$947,$A11,Objects!$T$2:$T$947,1)/$C11,0) | L11: 0 | M11: 0 | N11: 0 | O11: 0 | P11: 0 | Q11: 0 | R11: 0 | S11: 0 | T11: 0 | U11: =SUM(L11:T11) | V11: =IFERROR(MAX(L11:T11)/U11,0) | W11: unidentified | X11: no label votes
A12: 10 | B12: cross_hatch | C12: =COUNTIFS(Objects!$E$2:$E$947,$A12) | D12: =_xlfn.MINIFS(Objects!$L$2:$L$947,Objects!$E$2:$E$947,$A12) | E12: =_xlfn.MAXIFS(Objects!$L$2:$L$947,Objects!$E$2:$E$947,$A12) | F12: =_xlfn.MINIFS(Objects!$M$2:$M$947,Objects!$E$2:$E$947,$A12) | G12: =_xlfn.MAXIFS(Objects!$M$2:$M$947,Objects!$E$2:$E$947,$A12) | H12: =IFERROR(COUNTIFS(Objects!$E$2:$E$947,$A12,Objects!$Q$2:$Q$947,">0")/$C12,0) | I12: =IFERROR(COUNTIFS(Objects!$E$2:$E$947,$A12,Objects!$R$2:$R$947,1)/$C12,0) | J12: =IFERROR(COUNTIFS(Objects!$E$2:$E$947,$A12,Objects!$S$2:$S$947,1)/$C12,0) | K12: =IFERROR(COUNTIFS(Objects!$E$2:$E$947,$A12,Objects!$T$2:$T$947,1)/$C12,0) | L12: 0 | M12: 0 | N12: 0 | O12: 0 | P12: 0 | Q12: 0 | R12: 0 | S12: 0 | T12: 0 | U12: =SUM(L12:T12) | V12: =IFERROR(MAX(L12:T12)/U12,0) | W12: unidentified | X12: no label votes
A13: 11 | B13: outline | C13: =COUNTIFS(Objects!$E$2:$E$947,$A13) | D13: =_xlfn.MINIFS(Objects!$L$2:$L$947,Objects!$E$2:$E$947,$A13) | E13: =_xlfn.MAXIFS(Objects!$L$2:$L$947,Objects!$E$2:$E$947,$A13) | F13: =_xlfn.MINIFS(Objects!$M$2:$M$947,Objects!$E$2:$E$947,$A13) | G13: =_xlfn.MAXIFS(Objects!$M$2:$M$947,Objects!$E$2:$E$947,$A13) | H13: =IFERROR(COUNTIFS(Objects!$E$2:$E$947,$A13,Objects!$Q$2:$Q$947,">0")/$C13,0) | I13: =IFERROR(COUNTIFS(Objects!$E$2:$E$947,$A13,Objects!$R$2:$R$947,1)/$C13,0) | J13: =IFERROR(COUNTIFS(Objects!$E$2:$E$947,$A13,Objects!$S$2:$S$947,1)/$C13,0) | K13: =IFERROR(COUNTIFS(Objects!$E$2:$E$947,$A13,Objects!$T$2:$T$947,1)/$C13,0) | L13: 0 | M13: 0 | N13: 0 | O13: 0 | P13: 2 | Q13: 0 | R13: 0 | S13: 0 | T13: 0 | U13: =SUM(L13:T13) | V13: =IFERROR(MAX(L13:T13)/U13,0) | W13: sump_pit | X13: label vote | Y13: 0.66
A14: 12 | B14: outline | C14: =COUNTIFS(Objects!$E$2:$E$947,$A14) | D14: =_xlfn.MINIFS(Objects!$L$2:$L$947,Objects!$E$2:$E$947,$A14) | E14: =_xlfn.MAXIFS(Objects!$L$2:$L$947,Objects!$E$2:$E$947,$A14) | F14: =_xlfn.MINIFS(Objects!$M$2:$M$947,Objects!$E$2:$E$947,$A14) | G14: =_xlfn.MAXIFS(Objects!$M$2:$M$947,Objects!$E$2:$E$947,$A14) | H14: =IFERROR(COUNTIFS(Objects!$E$2:$E$947,$A14,Objects!$Q$2:$Q$947,">0")/$C14,0) | I14: =IFERROR(COUNTIFS(Objects!$E$2:$E$947,$A14,Objects!$R$2:$R$947,1)/$C14,0) | J14: =IFERROR(COUNTIFS(Objects!$E$2:$E$947,$A14,Objects!$S$2:$S$947,1)/$C14,0) | K14: =IFERROR(COUNTIFS(Objects!$E$2:$E$947,$A14,Objects!$T$2:$T$947,1)/$C14,0) | L14: 0 | M14: 22 | N14: 0 | O14: 0 | P14: 0 | Q14: 0 | R14: 0 | S14: 0 | T14: 0 | U14: =SUM(L14:T14) | V14: =IFERROR(MAX(L14:T14)/U14,0) | W14: isolated_footing | X14: label vote | Y14: 0.66
A15: 13 | B15: outline | C15: =COUNTIFS(Objects!$E$2:$E$947,$A15) | D15: =_xlfn.MINIFS(Objects!$L$2:$L$947,Objects!$E$2:$E$947,$A15) | E15: =_xlfn.MAXIFS(Objects!$L$2:$L$947,Objects!$E$2:$E$947,$A15) | F15: =_xlfn.MINIFS(Objects!$M$2:$M$947,Objects!$E$2:$E$947,$A15) | G15: =_xlfn.MAXIFS(Objects!$M$2:$M$947,Objects!$E$2:$E$947,$A15) | H15: =IFERROR(COUNTIFS(Objects!$E$2:$E$947,$A15,Objects!$Q$2:$Q$947,">0")/$C15,0) | I15: =IFERROR(COUNTIFS(Objects!$E$2:$E$947,$A15,Objects!$R$2:$R$947,1)/$C15,0) | J15: =IFERROR(COUNTIFS(Objects!$E$2:$E$947,$A15,Objects!$S$2:$S$947,1)/$C15,0) | K15: =IFERROR(COUNTIFS(Objects!$E$2:$E$947,$A15,Objects!$T$2:$T$947,1)/$C15,0) | L15: 0 | M15: 42 | N15: 0 | O15: 0 | P15: 0 | Q15: 0 | R15: 0 | S15: 0 | T15: 0 | U15: =SUM(L15:T15) | V15: =IFERROR(MAX(L15:T15)/U15,0) | W15: isolated_footing | X15: label vote | Y15: 0.66
A16: 14 | B16: outline | C16: =COUNTIFS(Objects!$E$2:$E$947,$A16) | D16: =_xlfn.MINIFS(Objects!$L$2:$L$947,Objects!$E$2:$E$947,$A16) | E16: =_xlfn.MAXIFS(Objects!$L$2:$L$947,Objects!$E$2:$E$947,$A16) | F16: =_xlfn.MINIFS(Objects!$M$2:$M$947,Objects!$E$2:$E$947,$A16) | G16: =_xlfn.MAXIFS(Objects!$M$2:$M$947,Objects!$E$2:$E$947,$A16) | H16: =IFERROR(COUNTIFS(Objects!$E$2:$E$947,$A16,Objects!$Q$2:$Q$947,">0")/$C16,0) | I16: =IFERROR(COUNTIFS(Objects!$E$2:$E$947,$A16,Objects!$R$2:$R$947,1)/$C16,0) | J16: =IFERROR(COUNTIFS(Objects!$E$2:$E$947,$A16,Objects!$S$2:$S$947,1)/$C16,0) | K16: =IFERROR(COUNTIFS(Objects!$E$2:$E$947,$A16,Objects!$T$2:$T$947,1)/$C16,0) | L16: 0 | M16: 1 | N16: 21 | O16: 0 | P16: 0 | Q16: 0 | R16: 0 | S16: 0 | T16: 0 | U16: =SUM(L16:T16) | V16: =IFERROR(MAX(L16:T16)/U16,0) | W16: combined_footing | X16: label vote | Y16: 0.66
A17: 15 | B17: outline | C17: =COUNTIFS(Objects!$E$2:$E$947,$A17) | D17: =_xlfn.MINIFS(Objects!$L$2:$L$947,Objects!$E$2:$E$947,$A17) | E17: =_xlfn.MAXIFS(Objects!$L$2:$L$947,Objects!$E$2:$E$947,$A17) | F17: =_xlfn.MINIFS(Objects!$M$2:$M$947,Objects!$E$2:$E$947,$A17) | G17: =_xlfn.MAXIFS(Objects!$M$2:$M$947,Objects!$E$2:$E$947,$A17) | H17: =IFERROR(COUNTIFS(Objects!$E$2:$E$947,$A17,Objects!$Q$2:$Q$947,">0")/$C17,0) | I17: =IFERROR(COUNTIFS(Objects!$E$2:$E$947,$A17,Objects!$R$2:$R$947,1)/$C17,0) | J17: =IFERROR(COUNTIFS(Objects!$E$2:$E$947,$A17,Objects!$S$2:$S$947,1)/$C17,0) | K17: =IFERROR(COUNTIFS(Objects!$E$2:$E$947,$A17,Objects!$T$2:$T$947,1)/$C17,0) | L17: 0 | M17: 0 | N17: 3 | O17: 0 | P17: 0 | Q17: 0 | R17: 0 | S17: 0 | T17: 0 | U17: =SUM(L17:T17) | V17: =IFERROR(MAX(L17:T17)/U17,0) | W17: combined_footing | X17: label vote | Y17: 0.66
A18: 16 | B18: outline | C18: =COUNTIFS(Objects!$E$2:$E$947,$A18) | D18: =_xlfn.MINIFS(Objects!$L$2:$L$947,Objects!$E$2:$E$947,$A18) | E18: =_xlfn.MAXIFS(Objects!$L$2:$L$947,Objects!$E$2:$E$947,$A18) | F18: =_xlfn.MINIFS(Objects!$M$2:$M$947,Objects!$E$2:$E$947,$A18) | G18: =_xlfn.MAXIFS(Objects!$M$2:$M$947,Objects!$E$2:$E$947,$A18) | H18: =IFERROR(COUNTIFS(Objects!$E$2:$E$947,$A18,Objects!$Q$2:$Q$947,">0")/$C18,0) | I18: =IFERROR(COUNTIFS(Objects!$E$2:$E$947,$A18,Objects!$R$2:$R$947,1)/$C18,0) | J18: =IFERROR(COUNTIFS(Objects!$E$2:$E$947,$A18,Objects!$S$2:$S$947,1)/$C18,0) | K18: =IFERROR(COUNTIFS(Objects!$E$2:$E$947,$A18,Objects!$T$2:$T$947,1)/$C18,0) | L18: 0 | M18: 1 | N18: 0 | O18: 0 | P18: 0 | Q18: 0 | R18: 0 | S18: 0 | T18: 0 | U18: =SUM(L18:T18) | V18: =IFERROR(MAX(L18:T18)/U18,0) | W18: isolated_footing | X18: similar to cluster 12 (distance 1.23) | Y18: 0.66
A19: 17 | B19: outline | C19: =COUNTIFS(Objects!$E$2:$E$947,$A19) | D19: =_xlfn.MINIFS(Objects!$L$2:$L$947,Objects!$E$2:$E$947,$A19) | E19: =_xlfn.MAXIFS(Objects!$L$2:$L$947,Objects!$E$2:$E$947,$A19) | F19: =_xlfn.MINIFS(Objects!$M$2:$M$947,Objects!$E$2:$E$947,$A19) | G19: =_xlfn.MAXIFS(Objects!$M$2:$M$947,Objects!$E$2:$E$947,$A19) | H19: =IFERROR(COUNTIFS(Objects!$E$2:$E$947,$A19,Objects!$Q$2:$Q$947,">0")/$C19,0) | I19: =IFERROR(COUNTIFS(Objects!$E$2:$E$947,$A19,Objects!$R$2:$R$947,1)/$C19,0) | J19: =IFERROR(COUNTIFS(Objects!$E$2:$E$947,$A19,Objects!$S$2:$S$947,1)/$C19,0) | K19: =IFERROR(COUNTIFS(Objects!$E$2:$E$947,$A19,Objects!$T$2:$T$947,1)/$C19,0) | L19: 0 | M19: 0 | N19: 0 | O19: 0 | P19: 0 | Q19: 0 | R19: 0 | S19: 0 | T19: 0 | U19: =SUM(L19:T19) | V19: =IFERROR(MAX(L19:T19)/U19,0) | W19: unidentified | X19: no label votes | Y19: 0.66
A20: 18 | B20: outline | C20: =COUNTIFS(Objects!$E$2:$E$947,$A20) | D20: =_xlfn.MINIFS(Objects!$L$2:$L$947,Objects!$E$2:$E$947,$A20) | E20: =_xlfn.MAXIFS(Objects!$L$2:$L$947,Objects!$E$2:$E$947,$A20) | F20: =_xlfn.MINIFS(Objects!$M$2:$M$947,Objects!$E$2:$E$947,$A20) | G20: =_xlfn.MAXIFS(Objects!$M$2:$M$947,Objects!$E$2:$E$947,$A20) | H20: =IFERROR(COUNTIFS(Objects!$E$2:$E$947,$A20,Objects!$Q$2:$Q$947,">0")/$C20,0) | I20: =IFERROR(COUNTIFS(Objects!$E$2:$E$947,$A20,Objects!$R$2:$R$947,1)/$C20,0) | J20: =IFERROR(COUNTIFS(Objects!$E$2:$E$947,$A20,Objects!$S$2:$S$947,1)/$C20,0) | K20: =IFERROR(COUNTIFS(Objects!$E$2:$E$947,$A20,Objects!$T$2:$T$947,1)/$C20,0) | L20: 0 | M20: 0 | N20: 0 | O20: 0 | P20: 0 | Q20: 0 | R20: 0 | S20: 0 | T20: 0 | U20: =SUM(L20:T20) | V20: =IFERROR(MAX(L20:T20)/U20,0) | W20: unidentified | X20: no label votes | Y20: 0.66
A21: 19 | B21: outline | C21: =COUNTIFS(Objects!$E$2:$E$947,$A21) | D21: =_xlfn.MINIFS(Objects!$L$2:$L$947,Objects!$E$2:$E$947,$A21) | E21: =_xlfn.MAXIFS(Objects!$L$2:$L$947,Objects!$E$2:$E$947,$A21) | F21: =_xlfn.MINIFS(Objects!$M$2:$M$947,Objects!$E$2:$E$947,$A21) | G21: =_xlfn.MAXIFS(Objects!$M$2:$M$947,Objects!$E$2:$E$947,$A21) | H21: =IFERROR(COUNTIFS(Objects!$E$2:$E$947,$A21,Objects!$Q$2:$Q$947,">0")/$C21,0) | I21: =IFERROR(COUNTIFS(Objects!$E$2:$E$947,$A21,Objects!$R$2:$R$947,1)/$C21,0) | J21: =IFERROR(COUNTIFS(Objects!$E$2:$E$947,$A21,Objects!$S$2:$S$947,1)/$C21,0) | K21: =IFERROR(COUNTIFS(Objects!$E$2:$E$947,$A21,Objects!$T$2:$T$947,1)/$C21,0) | L21: 0 | M21: 3 | N21: 0 | O21: 0 | P21: 0 | Q21: 0 | R21: 0 | S21: 0 | T21: 0 | U21: =SUM(L21:T21) | V21: =IFERROR(MAX(L21:T21)/U21,0) | W21: isolated_footing | X21: label vote | Y21: 0.66
A22: 20 | B22: outline | C22: =COUNTIFS(Objects!$E$2:$E$947,$A22) | D22: =_xlfn.MINIFS(Objects!$L$2:$L$947,Objects!$E$2:$E$947,$A22) | E22: =_xlfn.MAXIFS(Objects!$L$2:$L$947,Objects!$E$2:$E$947,$A22) | F22: =_xlfn.MINIFS(Objects!$M$2:$M$947,Objects!$E$2:$E$947,$A22) | G22: =_xlfn.MAXIFS(Objects!$M$2:$M$947,Objects!$E$2:$E$947,$A22) | H22: =IFERROR(COUNTIFS(Objects!$E$2:$E$947,$A22,Objects!$Q$2:$Q$947,">0")/$C22,0) | I22: =IFERROR(COUNTIFS(Objects!$E$2:$E$947,$A22,Objects!$R$2:$R$947,1)/$C22,0) | J22: =IFERROR(COUNTIFS(Objects!$E$2:$E$947,$A22,Objects!$S$2:$S$947,1)/$C22,0) | K22: =IFERROR(COUNTIFS(Objects!$E$2:$E$947,$A22,Objects!$T$2:$T$947,1)/$C22,0) | L22: 0 | M22: 0 | N22: 0 | O22: 0 | P22: 0 | Q22: 0 | R22: 0 | S22: 0 | T22: 0 | U22: =SUM(L22:T22) | V22: =IFERROR(MAX(L22:T22)/U22,0) | W22: unidentified | X22: no label votes | Y22: 0.66
A23: 21 | B23: outline | C23: =COUNTIFS(Objects!$E$2:$E$947,$A23) | D23: =_xlfn.MINIFS(Objects!$L$2:$L$947,Objects!$E$2:$E$947,$A23) | E23: =_xlfn.MAXIFS(Objects!$L$2:$L$947,Objects!$E$2:$E$947,$A23) | F23: =_xlfn.MINIFS(Objects!$M$2:$M$947,Objects!$E$2:$E$947,$A23) | G23: =_xlfn.MAXIFS(Objects!$M$2:$M$947,Objects!$E$2:$E$947,$A23) | H23: =IFERROR(COUNTIFS(Objects!$E$2:$E$947,$A23,Objects!$Q$2:$Q$947,">0")/$C23,0) | I23: =IFERROR(COUNTIFS(Objects!$E$2:$E$947,$A23,Objects!$R$2:$R$947,1)/$C23,0) | J23: =IFERROR(COUNTIFS(Objects!$E$2:$E$947,$A23,Objects!$S$2:$S$947,1)/$C23,0) | K23: =IFERROR(COUNTIFS(Objects!$E$2:$E$947,$A23,Objects!$T$2:$T$947,1)/$C23,0) | L23: 0 | M23: 0 | N23: 0 | O23: 0 | P23: 0 | Q23: 0 | R23: 0 | S23: 0 | T23: 0 | U23: =SUM(L23:T23) | V23: =IFERROR(MAX(L23:T23)/U23,0) | W23: unidentified | X23: no label votes | Y23: 0.66
A24: 22 | B24: outline | C24: =COUNTIFS(Objects!$E$2:$E$947,$A24) | D24: =_xlfn.MINIFS(Objects!$L$2:$L$947,Objects!$E$2:$E$947,$A24) | E24: =_xlfn.MAXIFS(Objects!$L$2:$L$947,Objects!$E$2:$E$947,$A24) | F24: =_xlfn.MINIFS(Objects!$M$2:$M$947,Objects!$E$2:$E$947,$A24) | G24: =_xlfn.MAXIFS(Objects!$M$2:$M$947,Objects!$E$2:$E$947,$A24) | H24: =IFERROR(COUNTIFS(Objects!$E$2:$E$947,$A24,Objects!$Q$2:$Q$947,">0")/$C24,0) | I24: =IFERROR(COUNTIFS(Objects!$E$2:$E$947,$A24,Objects!$R$2:$R$947,1)/$C24,0) | J24: =IFERROR(COUNTIFS(Objects!$E$2:$E$947,$A24,Objects!$S$2:$S$947,1)/$C24,0) | K24: =IFERROR(COUNTIFS(Objects!$E$2:$E$947,$A24,Objects!$T$2:$T$947,1)/$C24,0) | L24: 0 | M24: 0 | N24: 0 | O24: 0 | P24: 2 | Q24: 0 | R24: 0 | S24: 0 | T24: 0 | U24: =SUM(L24:T24) | V24: =IFERROR(MAX(L24:T24)/U24,0) | W24: sump_pit | X24: label vote | Y24: 0.66
A25: 23 | B25: outline | C25: =COUNTIFS(Objects!$E$2:$E$947,$A25) | D25: =_xlfn.MINIFS(Objects!$L$2:$L$947,Objects!$E$2:$E$947,$A25) | E25: =_xlfn.MAXIFS(Objects!$L$2:$L$947,Objects!$E$2:$E$947,$A25) | F25: =_xlfn.MINIFS(Objects!$M$2:$M$947,Objects!$E$2:$E$947,$A25) | G25: =_xlfn.MAXIFS(Objects!$M$2:$M$947,Objects!$E$2:$E$947,$A25) | H25: =IFERROR(COUNTIFS(Objects!$E$2:$E$947,$A25,Objects!$Q$2:$Q$947,">0")/$C25,0) | I25: =IFERROR(COUNTIFS(Objects!$E$2:$E$947,$A25,Objects!$R$2:$R$947,1)/$C25,0) | J25: =IFERROR(COUNTIFS(Objects!$E$2:$E$947,$A25,Objects!$S$2:$S$947,1)/$C25,0) | K25: =IFERROR(COUNTIFS(Objects!$E$2:$E$947,$A25,Objects!$T$2:$T$947,1)/$C25,0) | L25: 0 | M25: 0 | N25: 2 | O25: 0 | P25: 0 | Q25: 0 | R25: 0 | S25: 0 | T25: 0 | U25: =SUM(L25:T25) | V25: =IFERROR(MAX(L25:T25)/U25,0) | W25: combined_footing | X25: label vote | Y25: 0.66
A26: 24 | B26: single_hatch | C26: =COUNTIFS(Objects!$E$2:$E$947,$A26) | D26: =_xlfn.MINIFS(Objects!$L$2:$L$947,Objects!$E$2:$E$947,$A26) | E26: =_xlfn.MAXIFS(Objects!$L$2:$L$947,Objects!$E$2:$E$947,$A26) | F26: =_xlfn.MINIFS(Objects!$M$2:$M$947,Objects!$E$2:$E$947,$A26) | G26: =_xlfn.MAXIFS(Objects!$M$2:$M$947,Objects!$E$2:$E$947,$A26) | H26: =IFERROR(COUNTIFS(Objects!$E$2:$E$947,$A26,Objects!$Q$2:$Q$947,">0")/$C26,0) | I26: =IFERROR(COUNTIFS(Objects!$E$2:$E$947,$A26,Objects!$R$2:$R$947,1)/$C26,0) | J26: =IFERROR(COUNTIFS(Objects!$E$2:$E$947,$A26,Objects!$S$2:$S$947,1)/$C26,0) | K26: =IFERROR(COUNTIFS(Objects!$E$2:$E$947,$A26,Objects!$T$2:$T$947,1)/$C26,0) | L26: 0 | M26: 0 | N26: 0 | O26: 0 | P26: 0 | Q26: 0 | R26: 0 | S26: 0 | T26: 0 | U26: =SUM(L26:T26) | V26: =IFERROR(MAX(L26:T26)/U26,0) | W26: unidentified | X26: no label votes
A27: 25 | B27: solid | C27: =COUNTIFS(Objects!$E$2:$E$947,$A27) | D27: =_xlfn.MINIFS(Objects!$L$2:$L$947,Objects!$E$2:$E$947,$A27) | E27: =_xlfn.MAXIFS(Objects!$L$2:$L$947,Objects!$E$2:$E$947,$A27) | F27: =_xlfn.MINIFS(Objects!$M$2:$M$947,Objects!$E$2:$E$947,$A27) | G27: =_xlfn.MAXIFS(Objects!$M$2:$M$947,Objects!$E$2:$E$947,$A27) | H27: =IFERROR(COUNTIFS(Objects!$E$2:$E$947,$A27,Objects!$Q$2:$Q$947,">0")/$C27,0) | I27: =IFERROR(COUNTIFS(Objects!$E$2:$E$947,$A27,Objects!$R$2:$R$947,1)/$C27,0) | J27: =IFERROR(COUNTIFS(Objects!$E$2:$E$947,$A27,Objects!$S$2:$S$947,1)/$C27,0) | K27: =IFERROR(COUNTIFS(Objects!$E$2:$E$947,$A27,Objects!$T$2:$T$947,1)/$C27,0) | L27: 27 | M27: 0 | N27: 0 | O27: 0 | P27: 0 | Q27: 0 | R27: 0 | S27: 0 | T27: 0 | U27: =SUM(L27:T27) | V27: =IFERROR(MAX(L27:T27)/U27,0) | W27: column | X27: label vote | Y27: 0.408
A28: 26 | B28: solid | C28: =COUNTIFS(Objects!$E$2:$E$947,$A28) | D28: =_xlfn.MINIFS(Objects!$L$2:$L$947,Objects!$E$2:$E$947,$A28) | E28: =_xlfn.MAXIFS(Objects!$L$2:$L$947,Objects!$E$2:$E$947,$A28) | F28: =_xlfn.MINIFS(Objects!$M$2:$M$947,Objects!$E$2:$E$947,$A28) | G28: =_xlfn.MAXIFS(Objects!$M$2:$M$947,Objects!$E$2:$E$947,$A28) | H28: =IFERROR(COUNTIFS(Objects!$E$2:$E$947,$A28,Objects!$Q$2:$Q$947,">0")/$C28,0) | I28: =IFERROR(COUNTIFS(Objects!$E$2:$E$947,$A28,Objects!$R$2:$R$947,1)/$C28,0) | J28: =IFERROR(COUNTIFS(Objects!$E$2:$E$947,$A28,Objects!$S$2:$S$947,1)/$C28,0) | K28: =IFERROR(COUNTIFS(Objects!$E$2:$E$947,$A28,Objects!$T$2:$T$947,1)/$C28,0) | L28: 0 | M28: 0 | N28: 0 | O28: 0 | P28: 0 | Q28: 0 | R28: 0 | S28: 0 | T28: 1 | U28: =SUM(L28:T28) | V28: =IFERROR(MAX(L28:T28)/U28,0) | W28: unidentified | X28: no label votes | Y28: 0.408
A29: 27 | B29: solid | C29: =COUNTIFS(Objects!$E$2:$E$947,$A29) | D29: =_xlfn.MINIFS(Objects!$L$2:$L$947,Objects!$E$2:$E$947,$A29) | E29: =_xlfn.MAXIFS(Objects!$L$2:$L$947,Objects!$E$2:$E$947,$A29) | F29: =_xlfn.MINIFS(Objects!$M$2:$M$947,Objects!$E$2:$E$947,$A29) | G29: =_xlfn.MAXIFS(Objects!$M$2:$M$947,Objects!$E$2:$E$947,$A29) | H29: =IFERROR(COUNTIFS(Objects!$E$2:$E$947,$A29,Objects!$Q$2:$Q$947,">0")/$C29,0) | I29: =IFERROR(COUNTIFS(Objects!$E$2:$E$947,$A29,Objects!$R$2:$R$947,1)/$C29,0) | J29: =IFERROR(COUNTIFS(Objects!$E$2:$E$947,$A29,Objects!$S$2:$S$947,1)/$C29,0) | K29: =IFERROR(COUNTIFS(Objects!$E$2:$E$947,$A29,Objects!$T$2:$T$947,1)/$C29,0) | L29: 0 | M29: 0 | N29: 0 | O29: 0 | P29: 0 | Q29: 0 | R29: 0 | S29: 0 | T29: 2 | U29: =SUM(L29:T29) | V29: =IFERROR(MAX(L29:T29)/U29,0) | W29: shear_wall | X29: similar to cluster 29 (distance 2.85) | Y29: 0.408
A30: 28 | B30: solid | C30: =COUNTIFS(Objects!$E$2:$E$947,$A30) | D30: =_xlfn.MINIFS(Objects!$L$2:$L$947,Objects!$E$2:$E$947,$A30) | E30: =_xlfn.MAXIFS(Objects!$L$2:$L$947,Objects!$E$2:$E$947,$A30) | F30: =_xlfn.MINIFS(Objects!$M$2:$M$947,Objects!$E$2:$E$947,$A30) | G30: =_xlfn.MAXIFS(Objects!$M$2:$M$947,Objects!$E$2:$E$947,$A30) | H30: =IFERROR(COUNTIFS(Objects!$E$2:$E$947,$A30,Objects!$Q$2:$Q$947,">0")/$C30,0) | I30: =IFERROR(COUNTIFS(Objects!$E$2:$E$947,$A30,Objects!$R$2:$R$947,1)/$C30,0) | J30: =IFERROR(COUNTIFS(Objects!$E$2:$E$947,$A30,Objects!$S$2:$S$947,1)/$C30,0) | K30: =IFERROR(COUNTIFS(Objects!$E$2:$E$947,$A30,Objects!$T$2:$T$947,1)/$C30,0) | L30: 0 | M30: 0 | N30: 0 | O30: 0 | P30: 0 | Q30: 0 | R30: 0 | S30: 0 | T30: 1 | U30: =SUM(L30:T30) | V30: =IFERROR(MAX(L30:T30)/U30,0) | W30: shear_wall | X30: similar to cluster 33 (distance 3.55) | Y30: 0.408
A31: 29 | B31: solid | C31: =COUNTIFS(Objects!$E$2:$E$947,$A31) | D31: =_xlfn.MINIFS(Objects!$L$2:$L$947,Objects!$E$2:$E$947,$A31) | E31: =_xlfn.MAXIFS(Objects!$L$2:$L$947,Objects!$E$2:$E$947,$A31) | F31: =_xlfn.MINIFS(Objects!$M$2:$M$947,Objects!$E$2:$E$947,$A31) | G31: =_xlfn.MAXIFS(Objects!$M$2:$M$947,Objects!$E$2:$E$947,$A31) | H31: =IFERROR(COUNTIFS(Objects!$E$2:$E$947,$A31,Objects!$Q$2:$Q$947,">0")/$C31,0) | I31: =IFERROR(COUNTIFS(Objects!$E$2:$E$947,$A31,Objects!$R$2:$R$947,1)/$C31,0) | J31: =IFERROR(COUNTIFS(Objects!$E$2:$E$947,$A31,Objects!$S$2:$S$947,1)/$C31,0) | K31: =IFERROR(COUNTIFS(Objects!$E$2:$E$947,$A31,Objects!$T$2:$T$947,1)/$C31,0) | L31: 0 | M31: 0 | N31: 0 | O31: 0 | P31: 0 | Q31: 0 | R31: 0 | S31: 0 | T31: 10 | U31: =SUM(L31:T31) | V31: =IFERROR(MAX(L31:T31)/U31,0) | W31: shear_wall | X31: label vote | Y31: 0.408
A32: 30 | B32: solid | C32: =COUNTIFS(Objects!$E$2:$E$947,$A32) | D32: =_xlfn.MINIFS(Objects!$L$2:$L$947,Objects!$E$2:$E$947,$A32) | E32: =_xlfn.MAXIFS(Objects!$L$2:$L$947,Objects!$E$2:$E$947,$A32) | F32: =_xlfn.MINIFS(Objects!$M$2:$M$947,Objects!$E$2:$E$947,$A32) | G32: =_xlfn.MAXIFS(Objects!$M$2:$M$947,Objects!$E$2:$E$947,$A32) | H32: =IFERROR(COUNTIFS(Objects!$E$2:$E$947,$A32,Objects!$Q$2:$Q$947,">0")/$C32,0) | I32: =IFERROR(COUNTIFS(Objects!$E$2:$E$947,$A32,Objects!$R$2:$R$947,1)/$C32,0) | J32: =IFERROR(COUNTIFS(Objects!$E$2:$E$947,$A32,Objects!$S$2:$S$947,1)/$C32,0) | K32: =IFERROR(COUNTIFS(Objects!$E$2:$E$947,$A32,Objects!$T$2:$T$947,1)/$C32,0) | L32: 1 | M32: 0 | N32: 0 | O32: 0 | P32: 0 | Q32: 0 | R32: 0 | S32: 0 | T32: 3 | U32: =SUM(L32:T32) | V32: =IFERROR(MAX(L32:T32)/U32,0) | W32: unidentified | X32: no label votes | Y32: 0.408
A33: 31 | B33: solid | C33: =COUNTIFS(Objects!$E$2:$E$947,$A33) | D33: =_xlfn.MINIFS(Objects!$L$2:$L$947,Objects!$E$2:$E$947,$A33) | E33: =_xlfn.MAXIFS(Objects!$L$2:$L$947,Objects!$E$2:$E$947,$A33) | F33: =_xlfn.MINIFS(Objects!$M$2:$M$947,Objects!$E$2:$E$947,$A33) | G33: =_xlfn.MAXIFS(Objects!$M$2:$M$947,Objects!$E$2:$E$947,$A33) | H33: =IFERROR(COUNTIFS(Objects!$E$2:$E$947,$A33,Objects!$Q$2:$Q$947,">0")/$C33,0) | I33: =IFERROR(COUNTIFS(Objects!$E$2:$E$947,$A33,Objects!$R$2:$R$947,1)/$C33,0) | J33: =IFERROR(COUNTIFS(Objects!$E$2:$E$947,$A33,Objects!$S$2:$S$947,1)/$C33,0) | K33: =IFERROR(COUNTIFS(Objects!$E$2:$E$947,$A33,Objects!$T$2:$T$947,1)/$C33,0) | L33: 0 | M33: 0 | N33: 0 | O33: 0 | P33: 0 | Q33: 0 | R33: 0 | S33: 0 | T33: 21 | U33: =SUM(L33:T33) | V33: =IFERROR(MAX(L33:T33)/U33,0) | W33: shear_wall | X33: label vote | Y33: 0.408
A34: 32 | B34: solid | C34: =COUNTIFS(Objects!$E$2:$E$947,$A34) | D34: =_xlfn.MINIFS(Objects!$L$2:$L$947,Objects!$E$2:$E$947,$A34) | E34: =_xlfn.MAXIFS(Objects!$L$2:$L$947,Objects!$E$2:$E$947,$A34) | F34: =_xlfn.MINIFS(Objects!$M$2:$M$947,Objects!$E$2:$E$947,$A34) | G34: =_xlfn.MAXIFS(Objects!$M$2:$M$947,Objects!$E$2:$E$947,$A34) | H34: =IFERROR(COUNTIFS(Objects!$E$2:$E$947,$A34,Objects!$Q$2:$Q$947,">0")/$C34,0) | I34: =IFERROR(COUNTIFS(Objects!$E$2:$E$947,$A34,Objects!$R$2:$R$947,1)/$C34,0) | J34: =IFERROR(COUNTIFS(Objects!$E$2:$E$947,$A34,Objects!$S$2:$S$947,1)/$C34,0) | K34: =IFERROR(COUNTIFS(Objects!$E$2:$E$947,$A34,Objects!$T$2:$T$947,1)/$C34,0) | L34: 0 | M34: 0 | N34: 0 | O34: 0 | P34: 0 | Q34: 0 | R34: 0 | S34: 0 | T34: 0 | U34: =SUM(L34:T34) | V34: =IFERROR(MAX(L34:T34)/U34,0) | W34: retaining_wall | X34: label vote | Y34: 0.408
A35: 33 | B35: solid | C35: =COUNTIFS(Objects!$E$2:$E$947,$A35) | D35: =_xlfn.MINIFS(Objects!$L$2:$L$947,Objects!$E$2:$E$947,$A35) | E35: =_xlfn.MAXIFS(Objects!$L$2:$L$947,Objects!$E$2:$E$947,$A35) | F35: =_xlfn.MINIFS(Objects!$M$2:$M$947,Objects!$E$2:$E$947,$A35) | G35: =_xlfn.MAXIFS(Objects!$M$2:$M$947,Objects!$E$2:$E$947,$A35) | H35: =IFERROR(COUNTIFS(Objects!$E$2:$E$947,$A35,Objects!$Q$2:$Q$947,">0")/$C35,0) | I35: =IFERROR(COUNTIFS(Objects!$E$2:$E$947,$A35,Objects!$R$2:$R$947,1)/$C35,0) | J35: =IFERROR(COUNTIFS(Objects!$E$2:$E$947,$A35,Objects!$S$2:$S$947,1)/$C35,0) | K35: =IFERROR(COUNTIFS(Objects!$E$2:$E$947,$A35,Objects!$T$2:$T$947,1)/$C35,0) | L35: 0 | M35: 0 | N35: 0 | O35: 0 | P35: 0 | Q35: 0 | R35: 0 | S35: 0 | T35: 15 | U35: =SUM(L35:T35) | V35: =IFERROR(MAX(L35:T35)/U35,0) | W35: shear_wall | X35: label vote | Y35: 0.408
A36: 34 | B36: solid | C36: =COUNTIFS(Objects!$E$2:$E$947,$A36) | D36: =_xlfn.MINIFS(Objects!$L$2:$L$947,Objects!$E$2:$E$947,$A36) | E36: =_xlfn.MAXIFS(Objects!$L$2:$L$947,Objects!$E$2:$E$947,$A36) | F36: =_xlfn.MINIFS(Objects!$M$2:$M$947,Objects!$E$2:$E$947,$A36) | G36: =_xlfn.MAXIFS(Objects!$M$2:$M$947,Objects!$E$2:$E$947,$A36) | H36: =IFERROR(COUNTIFS(Objects!$E$2:$E$947,$A36,Objects!$Q$2:$Q$947,">0")/$C36,0) | I36: =IFERROR(COUNTIFS(Objects!$E$2:$E$947,$A36,Objects!$R$2:$R$947,1)/$C36,0) | J36: =IFERROR(COUNTIFS(Objects!$E$2:$E$947,$A36,Objects!$S$2:$S$947,1)/$C36,0) | K36: =IFERROR(COUNTIFS(Objects!$E$2:$E$947,$A36,Objects!$T$2:$T$947,1)/$C36,0) | L36: 0 | M36: 0 | N36: 0 | O36: 0 | P36: 0 | Q36: 0 | R36: 0 | S36: 0 | T36: 1 | U36: =SUM(L36:T36) | V36: =IFERROR(MAX(L36:T36)/U36,0) | W36: shear_wall | X36: similar to cluster 29 (distance 3.13) | Y36: 0.408
A37: 35 | B37: solid | C37: =COUNTIFS(Objects!$E$2:$E$947,$A37) | D37: =_xlfn.MINIFS(Objects!$L$2:$L$947,Objects!$E$2:$E$947,$A37) | E37: =_xlfn.MAXIFS(Objects!$L$2:$L$947,Objects!$E$2:$E$947,$A37) | F37: =_xlfn.MINIFS(Objects!$M$2:$M$947,Objects!$E$2:$E$947,$A37) | G37: =_xlfn.MAXIFS(Objects!$M$2:$M$947,Objects!$E$2:$E$947,$A37) | H37: =IFERROR(COUNTIFS(Objects!$E$2:$E$947,$A37,Objects!$Q$2:$Q$947,">0")/$C37,0) | I37: =IFERROR(COUNTIFS(Objects!$E$2:$E$947,$A37,Objects!$R$2:$R$947,1)/$C37,0) | J37: =IFERROR(COUNTIFS(Objects!$E$2:$E$947,$A37,Objects!$S$2:$S$947,1)/$C37,0) | K37: =IFERROR(COUNTIFS(Objects!$E$2:$E$947,$A37,Objects!$T$2:$T$947,1)/$C37,0) | L37: 0 | M37: 0 | N37: 0 | O37: 0 | P37: 0 | Q37: 0 | R37: 0 | S37: 0 | T37: 3 | U37: =SUM(L37:T37) | V37: =IFERROR(MAX(L37:T37)/U37,0) | W37: shear_wall | X37: similar to cluster 31 (distance 2.05) | Y37: 0.408
A38: 36 | B38: solid | C38: =COUNTIFS(Objects!$E$2:$E$947,$A38) | D38: =_xlfn.MINIFS(Objects!$L$2:$L$947,Objects!$E$2:$E$947,$A38) | E38: =_xlfn.MAXIFS(Objects!$L$2:$L$947,Objects!$E$2:$E$947,$A38) | F38: =_xlfn.MINIFS(Objects!$M$2:$M$947,Objects!$E$2:$E$947,$A38) | G38: =_xlfn.MAXIFS(Objects!$M$2:$M$947,Objects!$E$2:$E$947,$A38) | H38: =IFERROR(COUNTIFS(Objects!$E$2:$E$947,$A38,Objects!$Q$2:$Q$947,">0")/$C38,0) | I38: =IFERROR(COUNTIFS(Objects!$E$2:$E$947,$A38,Objects!$R$2:$R$947,1)/$C38,0) | J38: =IFERROR(COUNTIFS(Objects!$E$2:$E$947,$A38,Objects!$S$2:$S$947,1)/$C38,0) | K38: =IFERROR(COUNTIFS(Objects!$E$2:$E$947,$A38,Objects!$T$2:$T$947,1)/$C38,0) | L38: 2 | M38: 0 | N38: 0 | O38: 0 | P38: 0 | Q38: 0 | R38: 0 | S38: 0 | T38: 0 | U38: =SUM(L38:T38) | V38: =IFERROR(MAX(L38:T38)/U38,0) | W38: column | X38: label vote | Y38: 0.408
... A40: 38 | B40: solid | C40: =COUNTIFS(Objects!$E$2:$E$947,$A40) | D40: =_xlfn.MINIFS(Objects!$L$2:$L$947,Objects!$E$2:$E$947,$A40) | E40: =_xlfn.MAXIFS(Objects!$L$2:$L$947,Objects!$E$2:$E$947,$A40) | F40: =_xlfn.MINIFS(Objects!$M$2:$M$947,Objects!$E$2:$E$947,$A40) | G40: =_xlfn.MAXIFS(Objects!$M$2:$M$947,Objects!$E$2:$E$947,$A40) | H40: =IFERROR(COUNTIFS(Objects!$E$2:$E$947,$A40,Objects!$Q$2:$Q$947,">0")/$C40,0) | I40: =IFERROR(COUNTIFS(Objects!$E$2:$E$947,$A40,Objects!$R$2:$R$947,1)/$C40,0) | J40: =IFERROR(COUNTIFS(Objects!$E$2:$E$947,$A40,Objects!$S$2:$S$947,1)/$C40,0) | K40: =IFERROR(COUNTIFS(Objects!$E$2:$E$947,$A40,Objects!$T$2:$T$947,1)/$C40,0) | L40: 0 | M40: 0 | N40: 0 | O40: 0 | P40: 0 | Q40: 0 | R40: 0 | S40: 0 | T40: 13 | U40: =SUM(L40:T40) | V40: =IFERROR(MAX(L40:T40)/U40,0) | W40: shear_wall | X40: label vote | Y40: 0.408
A41: 39 | B41: stamped_region | C41: =COUNTIFS(Objects!$E$2:$E$947,$A41) | D41: =_xlfn.MINIFS(Objects!$L$2:$L$947,Objects!$E$2:$E$947,$A41) | E41: =_xlfn.MAXIFS(Objects!$L$2:$L$947,Objects!$E$2:$E$947,$A41) | F41: =_xlfn.MINIFS(Objects!$M$2:$M$947,Objects!$E$2:$E$947,$A41) | G41: =_xlfn.MAXIFS(Objects!$M$2:$M$947,Objects!$E$2:$E$947,$A41) | H41: =IFERROR(COUNTIFS(Objects!$E$2:$E$947,$A41,Objects!$Q$2:$Q$947,">0")/$C41,0) | I41: =IFERROR(COUNTIFS(Objects!$E$2:$E$947,$A41,Objects!$R$2:$R$947,1)/$C41,0) | J41: =IFERROR(COUNTIFS(Objects!$E$2:$E$947,$A41,Objects!$S$2:$S$947,1)/$C41,0) | K41: =IFERROR(COUNTIFS(Objects!$E$2:$E$947,$A41,Objects!$T$2:$T$947,1)/$C41,0) | L41: 0 | M41: 0 | N41: 0 | O41: 0 | P41: 0 | Q41: 14 | R41: 0 | S41: 0 | T41: 0 | U41: =SUM(L41:T41) | V41: =IFERROR(MAX(L41:T41)/U41,0) | W41: raft | X41: label vote
...

Sheet Objects
A1: ID | B1: Building | C1: Building from | D1: Drawing kind | E1: Cluster | F1: Class | G1: Label shown | H1: Class named by | I1: Type key | J1: Type source | K1: Label text | L1: Length (cm) | M1: Width (cm) | N1: L/W | O1: Area (m²) | P1: Angle (°) | Q1: Touches solids | R1: Inside an outline | S1: In a strip band | T1: On a stamped region | U1: On the building edge | V1: Solids inside | W1: Dots inside | X1: Beams touching | Y1: Net length (m) | Z1: Extent | AA1: bbox x0 (px) | AB1: bbox y0 (px) | AC1: bbox x1 (px) | AD1: bbox y1 (px) | AE1: (validation) verified class | AF1: (validation) agrees
A2: 1 | B2: 120 | C2: own label | D2: solid | E2: 25 | F2: column | G2: Column P1/120 0.80 × 0.25 m | H2: label vote | I2: P1/120 | J2: printed label | K2: P1/120/120 | L2: 80 | M2: 25 | N2: =IF(AND(ISNUMBER(L2),M2>0),L2/M2,"") | O2: 0.2 | P2: 0 | Q2: 0 | R2: 0 | S2: 0 | T2: 1 | U2: 0 | V2: 0 | W2: 0 | X2: 0 | AA2: 4596.9 | AB2: 792 | AC2: 4620.6 | AD2: 799.4 | AE2: column | AF2: =IF(AE2="","",IF(OR(AE2=F2,AND(AE2="crane_footing",F2="isolated_footing")),"yes","no"))
A3: 2 | B3: 120 | C3: own label | D3: solid | E3: 25 | F3: column | G3: Column P1/120 0.80 × 0.25 m | H3: label vote | I3: P1/120 | J3: printed label | K3: P1/120/120 | L3: 80 | M3: 25 | N3: =IF(AND(ISNUMBER(L3),M3>0),L3/M3,"") | O3: 0.2 | P3: 0 | Q3: 0 | R3: 0 | S3: 0 | T3: 1 | U3: 0 | V3: 0 | W3: 0 | X3: 0 | AA3: 4704.8 | AB3: 861.4 | AC3: 4728.4 | AD3: 868.8 | AE3: column | AF3: =IF(AE3="","",IF(OR(AE3=F3,AND(AE3="crane_footing",F3="isolated_footing")),"yes","no"))
A4: 3 | B4: 120 | C4: own label | D4: solid | E4: 25 | F4: column | G4: Column P1/120 0.80 × 0.25 m | H4: label vote | I4: P1/120 | J4: printed label | K4: P1/120/120 | L4: 80 | M4: 25 | N4: =IF(AND(ISNUMBER(L4),M4>0),L4/M4,"") | O4: 0.2 | P4: 0 | Q4: 0 | R4: 0 | S4: 0 | T4: 1 | U4: 0 | V4: 0 | W4: 0 | X4: 0 | AA4: 4596.9 | AB4: 861.4 | AC4: 4620.6 | AD4: 868.8 | AE4: column | AF4: =IF(AE4="","",IF(OR(AE4=F4,AND(AE4="crane_footing",F4="isolated_footing")),"yes","no"))
A5: 4 | B5: 120 | C5: own label | D5: solid | E5: 25 | F5: column | G5: Column P1/120 0.80 × 0.25 m | H5: label vote | I5: P1/120 | J5: printed label | K5: P1/120/120 | L5: 80 | M5: 25 | N5: =IF(AND(ISNUMBER(L5),M5>0),L5/M5,"") | O5: 0.2 | P5: 0 | Q5: 0 | R5: 0 | S5: 0 | T5: 1 | U5: 0 | V5: 0 | W5: 0 | X5: 0 | AA5: 4704.8 | AB5: 792 | AC5: 4728.4 | AD5: 799.4 | AE5: column | AF5: =IF(AE5="","",IF(OR(AE5=F5,AND(AE5="crane_footing",F5="isolated_footing")),"yes","no"))
A6: 5 | B6: 120 | C6: own label | D6: solid | E6: 31 | F6: shear_wall | G6: Shear wall V1/120 2.00 × 0.25 m | H6: label vote | I6: V1/120 | J6: printed label | K6: V1/120/120 | L6: 200 | M6: 25 | N6: =IF(AND(ISNUMBER(L6),M6>0),L6/M6,"") | O6: 0.502 | P6: 0 | Q6: 0 | R6: 0 | S6: 0 | T6: 1 | U6: 0 | V6: 0 | W6: 2 | X6: 2 | AA6: 4521.3 | AB6: 517.4 | AC6: 4580.3 | AD6: 524.9 | AE6: shear_wall | AF6: =IF(AE6="","",IF(OR(AE6=F6,AND(AE6="crane_footing",F6="isolated_footing")),"yes","no"))
A7: 6 | B7: 120 | C7: own label | D7: solid | E7: 31 | F7: shear_wall | G7: Shear wall V1/120 2.00 × 0.25 m | H7: label vote | I7: V1/120 | J7: printed label | K7: V1/120/120 | L7: 200 | M7: 25 | N7: =IF(AND(ISNUMBER(L7),M7>0),L7/M7,"") | O7: 0.5 | P7: 0 | Q7: 0 | R7: 0 | S7: 0 | T7: 1 | U7: 0 | V7: 0 | W7: 2 | X7: 2 | AA7: 4516.5 | AB7: 826.7 | AC7: 4575.6 | AD7: 834.2 | AE7: shear_wall | AF7: =IF(AE7="","",IF(OR(AE7=F7,AND(AE7="crane_footing",F7="isolated_footing")),"yes","no"))
A8: 7 | B8: 120 | C8: own label | D8: solid | E8: 31 | F8: shear_wall | G8: Shear wall V1/120 2.00 × 0.25 m | H8: label vote | I8: V1/120 | J8: printed label | K8: V1/120/120 | L8: 200 | M8: 25 | N8: =IF(AND(ISNUMBER(L8),M8>0),L8/M8,"") | O8: 0.5 | P8: 0 | Q8: 0 | R8: 1 | S8: 0 | T8: 0 | U8: 0 | V8: 0 | W8: 2 | X8: 2 | AA8: 4519.4 | AB8: 681.4 | AC8: 4578.4 | AD8: 688.7 | AE8: shear_wall | AF8: =IF(AE8="","",IF(OR(AE8=F8,AND(AE8="crane_footing",F8="isolated_footing")),"yes","no"))
A9: 8 | B9: 120 | C9: own label | D9: solid | E9: 31 | F9: shear_wall | G9: Shear wall V1/120 2.00 × 0.25 m | H9: label vote | I9: V1/120 | J9: printed label | K9: V1/120/120 | L9: 200 | M9: 25 | N9: =IF(AND(ISNUMBER(L9),M9>0),L9/M9,"") | O9: 0.499 | P9: 0 | Q9: 0 | R9: 1 | S9: 0 | T9: 0 | U9: 0 | V9: 0 | W9: 2 | X9: 2 | AA9: 4519.5 | AB9: 972.2 | AC9: 4578.5 | AD9: 979.5 | AE9: shear_wall | AF9: =IF(AE9="","",IF(OR(AE9=F9,AND(AE9="crane_footing",F9="isolated_footing")),"yes","no"))
A10: 9 | B10: 120 | C10: own label | D10: solid | E10: 31 | F10: shear_wall | G10: Shear wall V2/120 1.25 × 0.25 m | H10: label vote | I10: V2/120 | J10: printed label | K10: V2/120/120 | L10: 125 | M10: 25 | N10: =IF(AND(ISNUMBER(L10),M10>0),L10/M10,"") | O10: 0.313 | P10: 179.7 | Q10: 0 | R10: 1 | S10: 0 | T10: 0 | U10: 0 | V10: 0 | W10: 2 | X10: 2 | AA10: 4516.6 | AB10: 1323 | AC10: 4553.6 | AD10: 1330.6 | AE10: shear_wall | AF10: =IF(AE10="","",IF(OR(AE10=F10,AND(AE10="crane_footing",F10="isolated_footing")),"yes","no"))
A11: 10 | B11: 120 | C11: own label | D11: solid | E11: 33 | F11: shear_wall | G11: Shear wall V2/120 1.25 × 0.25 m | H11: label vote | I11: V2/120 | J11: printed label | K11: V2/120/120 | L11: 125 | M11: 25 | N11: =IF(AND(ISNUMBER(L11),M11>0),L11/M11,"") | O11: 0.312 | P11: 0 | Q11: 1 | R11: 1 | S11: 0 | T11: 0 | U11: 0 | V11: 0 | W11: 0 | X11: 2 | AA11: 4749.1 | AB11: 1323.2 | AC11: 4786.1 | AD11: 1330.5 | AF11: =IF(AE11="","",IF(OR(AE11=F11,AND(AE11="crane_footing",F11="isolated_footing")),"yes","no"))
A12: 11 | B12: 120 | C12: own label | D12: solid | E12: 31 | F12: shear_wall | G12: Shear wall V3/120 1.25 × 0.25 m | H12: label vote | I12: V3/120 | J12: printed label | K12: V3/120/120 | L12: 125 | M12: 25 | N12: =IF(AND(ISNUMBER(L12),M12>0),L12/M12,"") | O12: 0.314 | P12: 0 | Q12: 0 | R12: 1 | S12: 0 | T12: 0 | U12: 0 | V12: 0 | W12: 2 | X12: 2 | AA12: 4285 | AB12: 864.7 | AC12: 4321.9 | AD12: 872.1 | AE12: shear_wall | AF12: =IF(AE12="","",IF(OR(AE12=F12,AND(AE12="crane_footing",F12="isolated_footing")),"yes","no"))
A13: 12 | B13: 120 | C13: own label | D13: solid | E13: 31 | F13: shear_wall | G13: Shear wall V3/120 1.25 × 0.25 m | H13: label vote | I13: V3/120 | J13: printed label | K13: V3/120/120 | L13: 125 | M13: 25 | N13: =IF(AND(ISNUMBER(L13),M13>0),L13/M13,"") | O13: 0.313 | P13: 0.1 | Q13: 0 | R13: 0 | S13: 0 | T13: 1 | U13: 0 | V13: 0 | W13: 2 | X13: 2 | AA13: 4253.5 | AB13: 1323.1 | AC13: 4290.5 | AD13: 1330.5 | AE13: shear_wall | AF13: =IF(AE13="","",IF(OR(AE13=F13,AND(AE13="crane_footing",F13="isolated_footing")),"yes","no"))
A14: 13 | B14: 120 | C14: own label | D14: solid | E14: 31 | F14: shear_wall | G14: Shear wall V3/120 1.25 × 0.25 m | H14: label vote | I14: V3/120 | J14: printed label | K14: V3/120/120 | L14: 125 | M14: 25 | N14: =IF(AND(ISNUMBER(L14),M14>0),L14/M14,"") | O14: 0.313 | P14: 0.1 | Q14: 0 | R14: 1 | S14: 0 | T14: 0 | U14: 0 | V14: 0 | W14: 0 | X14: 2 | AA14: 4284.8 | AB14: 1094.2 | AC14: 4321.7 | AD14: 1101.6 | AE14: shear_wall | AF14: =IF(AE14="","",IF(OR(AE14=F14,AND(AE14="crane_footing",F14="isolated_footing")),"yes","no"))
A15: 14 | B15: 120 | C15: own label | D15: solid | E15: 31 | F15: shear_wall | G15: Shear wall V3/120 1.25 × 0.25 m | H15: label vote | I15: V3/120 | J15: printed label | K15: V3/120120 | L15: 125 | M15: 25 | N15: =IF(AND(ISNUMBER(L15),M15>0),L15/M15,"") | O15: 0.313 | P15: 0.1 | Q15: 0 | R15: 1 | S15: 0 | T15: 0 | U15: 0 | V15: 0 | W15: 3 | X15: 2 | AA15: 4285.2 | AB15: 635.6 | AC15: 4322.1 | AD15: 643 | AE15: shear_wall | AF15: =IF(AE15="","",IF(OR(AE15=F15,AND(AE15="crane_footing",F15="isolated_footing")),"yes","no"))
A16: 15 | B16: 120 | C16: own label | D16: solid | E16: 29 | F16: shear_wall | G16: Shear wall V4/120 2.00 × 0.25 m | H16: label vote | I16: V4/120 | J16: printed label | K16: V4/120/120 | L16: 200 | M16: 25 | N16: =IF(AND(ISNUMBER(L16),M16>0),L16/M16,"") | O16: 0.5 | P16: 90.1 | Q16: 1 | R16: 1 | S16: 0 | T16: 0 | U16: 1 | V16: 0 | W16: 1 | X16: 0 | AA16: 4763.6 | AB16: 416.7 | AC16: 4771.1 | AD16: 475.8 | AF16: =IF(AE16="","",IF(OR(AE16=F16,AND(AE16="crane_footing",F16="isolated_footing")),"yes","no"))
A17: 16 | B17: 120 | C17: own label | D17: solid | E17: 31 | F17: shear_wall | G17: Shear wall V4/120 2.00 × 0.25 m | H17: label vote | I17: V4/120 | J17: printed label | K17: V4/120/120 | L17: 200 | M17: 25 | N17: =IF(AND(ISNUMBER(L17),M17>0),L17/M17,"") | O17: 0.5 | P17: 90 | Q17: 0 | R17: 0 | S17: 0 | T17: 1 | U17: 0 | V17: 0 | W17: 2 | X17: 0 | AA17: 4644.1 | AB17: 425.8 | AC17: 4651.4 | AD17: 484.9 | AE17: shear_wall | AF17: =IF(AE17="","",IF(OR(AE17=F17,AND(AE17="crane_footing",F17="isolated_footing")),"yes","no"))
